2025-08-26 16:34:02,261 - httpx - INFO - HTTP Request: POST https://api.anthropic.com/v1/messages "HTTP/1.1 200 OK"
2025-08-26 16:34:07,320 - httpx - INFO - HTTP Request: POST https://api.anthropic.com/v1/messages "HTTP/1.1 200 OK"
2025-08-26 16:34:17,578 - httpx - INFO - HTTP Request: POST https://api.anthropic.com/v1/messages "HTTP/1.1 200 OK"
2025-08-26 16:38:24,397 - httpx - INFO - HTTP Request: POST https://api.anthropic.com/v1/messages "HTTP/1.1 200 OK"
2025-08-26 19:17:45,885 - BroadAxis - ERROR - Error occurred: {'error_type': 'WebSocketDisconnect', 'message': "(1001, '')", 'context': {'session_id': 'ws_1778749663104_1756246085', 'operation': 'websocket_message_handling'}, 'traceback': 'Traceback (most recent call last):\n  File "C:\\Users\\rohka\\OneDrive\\Desktop\\ba-rfpapp\\backend\\websocket_api.py", line 52, in websocket_chat\n    data = await asyncio.wait_for(websocket.receive_text(), timeout=300.0)  # 5 min timeout\n           ^^^^^^^^^^^^^^^^^^^^^^^^^^^^^^^^^^^^^^^^^^^^^^^^^^^^^^^^^^^^^^^\n  File "C:\\Users\\rohka\\AppData\\Local\\Programs\\Python\\Python313\\Lib\\asyncio\\tasks.py", line 507, in wait_for\n    return await fut\n           ^^^^^^^^^\n  File "C:\\Users\\rohka\\OneDrive\\Desktop\\ba-rfpapp\\venv\\Lib\\site-packages\\starlette\\websockets.py", line 120, in receive_text\n    self._raise_on_disconnect(message)\n    ~~~~~~~~~~~~~~~~~~~~~~~~~^^^^^^^^^\n  File "C:\\Users\\rohka\\OneDrive\\Desktop\\ba-rfpapp\\venv\\Lib\\site-packages\\starlette\\websockets.py", line 114, in _raise_on_disconnect\n    raise WebSocketDisconnect(message["code"], message.get("reason"))\nstarlette.websockets.WebSocketDisconnect: (1001, \'\')\n'}
2025-08-26 19:18:01,898 - httpx - INFO - HTTP Request: POST https://api.anthropic.com/v1/messages "HTTP/1.1 200 OK"
2025-08-26 19:18:03,910 - BroadAxis - ERROR - Error occurred: {'error_type': 'WebSocketDisconnect', 'message': '', 'context': {'operation': 'websocket_send_message'}, 'traceback': 'Traceback (most recent call last):\n  File "C:\\Users\\rohka\\OneDrive\\Desktop\\ba-rfpapp\\venv\\Lib\\site-packages\\websockets\\legacy\\protocol.py", line 1279, in close_connection\n    await self.transfer_data_task\n  File "C:\\Users\\rohka\\AppData\\Local\\Programs\\Python\\Python313\\Lib\\asyncio\\futures.py", line 286, in __await__\n    yield self  # This tells Task to wait for completion.\n    ^^^^^^^^^^\n  File "C:\\Users\\rohka\\AppData\\Local\\Programs\\Python\\Python313\\Lib\\asyncio\\tasks.py", line 375, in __wakeup\n    future.result()\n    ~~~~~~~~~~~~~^^\n  File "C:\\Users\\rohka\\AppData\\Local\\Programs\\Python\\Python313\\Lib\\asyncio\\futures.py", line 194, in result\n    raise self._make_cancelled_error()\n  File "C:\\Users\\rohka\\AppData\\Local\\Programs\\Python\\Python313\\Lib\\asyncio\\tasks.py", line 306, in __step_run_and_handle_result\n    result = coro.throw(exc)\n  File "C:\\Users\\rohka\\OneDrive\\Desktop\\ba-rfpapp\\venv\\Lib\\site-packages\\websockets\\legacy\\protocol.py", line 956, in transfer_data\n    await asyncio.shield(self._put_message_waiter)\n  File "C:\\Users\\rohka\\AppData\\Local\\Programs\\Python\\Python313\\Lib\\asyncio\\futures.py", line 286, in __await__\n    yield self  # This tells Task to wait for completion.\n    ^^^^^^^^^^\n  File "C:\\Users\\rohka\\AppData\\Local\\Programs\\Python\\Python313\\Lib\\asyncio\\tasks.py", line 375, in __wakeup\n    future.result()\n    ~~~~~~~~~~~~~^^\n  File "C:\\Users\\rohka\\AppData\\Local\\Programs\\Python\\Python313\\Lib\\asyncio\\futures.py", line 194, in result\n    raise self._make_cancelled_error()\nasyncio.exceptions.CancelledError\n\nThe above exception was the direct cause of the following exception:\n\nTraceback (most recent call last):\n  File "C:\\Users\\rohka\\OneDrive\\Desktop\\ba-rfpapp\\venv\\Lib\\site-packages\\uvicorn\\protocols\\websockets\\websockets_impl.py", line 332, in asgi_send\n    await self.send(data)  # type: ignore[arg-type]\n    ^^^^^^^^^^^^^^^^^^^^^\n  File "C:\\Users\\rohka\\OneDrive\\Desktop\\ba-rfpapp\\venv\\Lib\\site-packages\\websockets\\legacy\\protocol.py", line 620, in send\n    await self.ensure_open()\n  File "C:\\Users\\rohka\\OneDrive\\Desktop\\ba-rfpapp\\venv\\Lib\\site-packages\\websockets\\legacy\\protocol.py", line 921, in ensure_open\n    raise self.connection_closed_exc()\nwebsockets.exceptions.ConnectionClosedError: sent 1011 (internal error) keepalive ping timeout; no close frame received\n\nThe above exception was the direct cause of the following exception:\n\nTraceback (most recent call last):\n  File "C:\\Users\\rohka\\OneDrive\\Desktop\\ba-rfpapp\\venv\\Lib\\site-packages\\starlette\\websockets.py", line 86, in send\n    await self._send(message)\n  File "C:\\Users\\rohka\\OneDrive\\Desktop\\ba-rfpapp\\venv\\Lib\\site-packages\\starlette\\_exception_handler.py", line 39, in sender\n    await send(message)\n  File "C:\\Users\\rohka\\OneDrive\\Desktop\\ba-rfpapp\\venv\\Lib\\site-packages\\uvicorn\\protocols\\websockets\\websockets_impl.py", line 345, in asgi_send\n    raise ClientDisconnected from exc\nuvicorn.protocols.utils.ClientDisconnected\n\nDuring handling of the above exception, another exception occurred:\n\nTraceback (most recent call last):\n  File "C:\\Users\\rohka\\OneDrive\\Desktop\\ba-rfpapp\\backend\\websocket_api.py", line 30, in send_personal_message\n    await websocket.send_text(message)\n  File "C:\\Users\\rohka\\OneDrive\\Desktop\\ba-rfpapp\\venv\\Lib\\site-packages\\starlette\\websockets.py", line 166, in send_text\n    await self.send({"type": "websocket.send", "text": data})\n  File "C:\\Users\\rohka\\OneDrive\\Desktop\\ba-rfpapp\\venv\\Lib\\site-packages\\starlette\\websockets.py", line 89, in send\n    raise WebSocketDisconnect(code=1006)\nstarlette.websockets.WebSocketDisconnect\n'}
2025-08-26 19:18:03,917 - BroadAxis - ERROR - Error occurred: {'error_type': 'WebSocketDisconnect', 'message': '', 'context': {'operation': 'websocket_progress_update'}, 'traceback': 'Traceback (most recent call last):\n  File "C:\\Users\\rohka\\OneDrive\\Desktop\\ba-rfpapp\\venv\\Lib\\site-packages\\websockets\\legacy\\protocol.py", line 1279, in close_connection\n    await self.transfer_data_task\n  File "C:\\Users\\rohka\\AppData\\Local\\Programs\\Python\\Python313\\Lib\\asyncio\\futures.py", line 286, in __await__\n    yield self  # This tells Task to wait for completion.\n    ^^^^^^^^^^\n  File "C:\\Users\\rohka\\AppData\\Local\\Programs\\Python\\Python313\\Lib\\asyncio\\tasks.py", line 375, in __wakeup\n    future.result()\n    ~~~~~~~~~~~~~^^\n  File "C:\\Users\\rohka\\AppData\\Local\\Programs\\Python\\Python313\\Lib\\asyncio\\futures.py", line 194, in result\n    raise self._make_cancelled_error()\n  File "C:\\Users\\rohka\\AppData\\Local\\Programs\\Python\\Python313\\Lib\\asyncio\\tasks.py", line 306, in __step_run_and_handle_result\n    result = coro.throw(exc)\n  File "C:\\Users\\rohka\\OneDrive\\Desktop\\ba-rfpapp\\venv\\Lib\\site-packages\\websockets\\legacy\\protocol.py", line 956, in transfer_data\n    await asyncio.shield(self._put_message_waiter)\n  File "C:\\Users\\rohka\\AppData\\Local\\Programs\\Python\\Python313\\Lib\\asyncio\\futures.py", line 286, in __await__\n    yield self  # This tells Task to wait for completion.\n    ^^^^^^^^^^\n  File "C:\\Users\\rohka\\AppData\\Local\\Programs\\Python\\Python313\\Lib\\asyncio\\tasks.py", line 375, in __wakeup\n    future.result()\n    ~~~~~~~~~~~~~^^\n  File "C:\\Users\\rohka\\AppData\\Local\\Programs\\Python\\Python313\\Lib\\asyncio\\futures.py", line 194, in result\n    raise self._make_cancelled_error()\nasyncio.exceptions.CancelledError\n\nThe above exception was the direct cause of the following exception:\n\nTraceback (most recent call last):\n  File "C:\\Users\\rohka\\OneDrive\\Desktop\\ba-rfpapp\\venv\\Lib\\site-packages\\uvicorn\\protocols\\websockets\\websockets_impl.py", line 332, in asgi_send\n    await self.send(data)  # type: ignore[arg-type]\n    ^^^^^^^^^^^^^^^^^^^^^\n  File "C:\\Users\\rohka\\OneDrive\\Desktop\\ba-rfpapp\\venv\\Lib\\site-packages\\websockets\\legacy\\protocol.py", line 620, in send\n    await self.ensure_open()\n  File "C:\\Users\\rohka\\OneDrive\\Desktop\\ba-rfpapp\\venv\\Lib\\site-packages\\websockets\\legacy\\protocol.py", line 921, in ensure_open\n    raise self.connection_closed_exc()\nwebsockets.exceptions.ConnectionClosedError: sent 1011 (internal error) keepalive ping timeout; no close frame received\n\nThe above exception was the direct cause of the following exception:\n\nTraceback (most recent call last):\n  File "C:\\Users\\rohka\\OneDrive\\Desktop\\ba-rfpapp\\venv\\Lib\\site-packages\\starlette\\websockets.py", line 86, in send\n    await self._send(message)\n  File "C:\\Users\\rohka\\OneDrive\\Desktop\\ba-rfpapp\\venv\\Lib\\site-packages\\starlette\\_exception_handler.py", line 39, in sender\n    await send(message)\n  File "C:\\Users\\rohka\\OneDrive\\Desktop\\ba-rfpapp\\venv\\Lib\\site-packages\\uvicorn\\protocols\\websockets\\websockets_impl.py", line 345, in asgi_send\n    raise ClientDisconnected from exc\nuvicorn.protocols.utils.ClientDisconnected\n\nDuring handling of the above exception, another exception occurred:\n\nTraceback (most recent call last):\n  File "C:\\Users\\rohka\\OneDrive\\Desktop\\ba-rfpapp\\backend\\mcp_interface.py", line 285, in execute_tool_with_progress\n    await send_message_callback(\n    ...<9 lines>...\n    )\n  File "C:\\Users\\rohka\\OneDrive\\Desktop\\ba-rfpapp\\backend\\websocket_api.py", line 30, in send_personal_message\n    await websocket.send_text(message)\n  File "C:\\Users\\rohka\\OneDrive\\Desktop\\ba-rfpapp\\venv\\Lib\\site-packages\\starlette\\websockets.py", line 166, in send_text\n    await self.send({"type": "websocket.send", "text": data})\n  File "C:\\Users\\rohka\\OneDrive\\Desktop\\ba-rfpapp\\venv\\Lib\\site-packages\\starlette\\websockets.py", line 89, in send\n    raise WebSocketDisconnect(code=1006)\nstarlette.websockets.WebSocketDisconnect\n'}
2025-08-26 19:18:03,919 - BroadAxis - ERROR - Error occurred: {'error_type': 'RuntimeError', 'message': 'Cannot call "send" once a close message has been sent.', 'context': {'operation': 'websocket_send_message'}, 'traceback': 'Traceback (most recent call last):\n  File "C:\\Users\\rohka\\OneDrive\\Desktop\\ba-rfpapp\\backend\\websocket_api.py", line 30, in send_personal_message\n    await websocket.send_text(message)\n  File "C:\\Users\\rohka\\OneDrive\\Desktop\\ba-rfpapp\\venv\\Lib\\site-packages\\starlette\\websockets.py", line 166, in send_text\n    await self.send({"type": "websocket.send", "text": data})\n  File "C:\\Users\\rohka\\OneDrive\\Desktop\\ba-rfpapp\\venv\\Lib\\site-packages\\starlette\\websockets.py", line 98, in send\n    raise RuntimeError(\'Cannot call "send" once a close message has been sent.\')\nRuntimeError: Cannot call "send" once a close message has been sent.\n'}
2025-08-26 19:18:03,921 - BroadAxis - ERROR - Error occurred: {'error_type': 'RuntimeError', 'message': 'Cannot call "send" once a close message has been sent.', 'context': {'operation': 'websocket_generation_update'}, 'traceback': 'Traceback (most recent call last):\n  File "C:\\Users\\rohka\\OneDrive\\Desktop\\ba-rfpapp\\backend\\mcp_interface.py", line 320, in process_query_with_anthropic\n    await send_message_callback(\n    ...<9 lines>...\n    )\n  File "C:\\Users\\rohka\\OneDrive\\Desktop\\ba-rfpapp\\backend\\websocket_api.py", line 30, in send_personal_message\n    await websocket.send_text(message)\n  File "C:\\Users\\rohka\\OneDrive\\Desktop\\ba-rfpapp\\venv\\Lib\\site-packages\\starlette\\websockets.py", line 166, in send_text\n    await self.send({"type": "websocket.send", "text": data})\n  File "C:\\Users\\rohka\\OneDrive\\Desktop\\ba-rfpapp\\venv\\Lib\\site-packages\\starlette\\websockets.py", line 98, in send\n    raise RuntimeError(\'Cannot call "send" once a close message has been sent.\')\nRuntimeError: Cannot call "send" once a close message has been sent.\n'}
2025-08-26 19:18:11,436 - httpx - INFO - HTTP Request: POST https://api.anthropic.com/v1/messages "HTTP/1.1 200 OK"
2025-08-26 19:18:11,439 - BroadAxis - ERROR - Error occurred: {'error_type': 'RuntimeError', 'message': 'Cannot call "send" once a close message has been sent.', 'context': {'operation': 'websocket_send_message'}, 'traceback': 'Traceback (most recent call last):\n  File "C:\\Users\\rohka\\OneDrive\\Desktop\\ba-rfpapp\\backend\\websocket_api.py", line 30, in send_personal_message\n    await websocket.send_text(message)\n  File "C:\\Users\\rohka\\OneDrive\\Desktop\\ba-rfpapp\\venv\\Lib\\site-packages\\starlette\\websockets.py", line 166, in send_text\n    await self.send({"type": "websocket.send", "text": data})\n  File "C:\\Users\\rohka\\OneDrive\\Desktop\\ba-rfpapp\\venv\\Lib\\site-packages\\starlette\\websockets.py", line 98, in send\n    raise RuntimeError(\'Cannot call "send" once a close message has been sent.\')\nRuntimeError: Cannot call "send" once a close message has been sent.\n'}
2025-08-26 19:18:11,441 - BroadAxis - ERROR - Error occurred: {'error_type': 'RuntimeError', 'message': 'Cannot call "send" once a close message has been sent.', 'context': {'session_id': 'ws_1778749769040_1756244282', 'query_length': 23}, 'traceback': 'Traceback (most recent call last):\n  File "C:\\Users\\rohka\\OneDrive\\Desktop\\ba-rfpapp\\backend\\websocket_api.py", line 161, in websocket_chat\n    await manager.send_personal_message(\n    ...<7 lines>...\n    )\n  File "C:\\Users\\rohka\\OneDrive\\Desktop\\ba-rfpapp\\backend\\websocket_api.py", line 30, in send_personal_message\n    await websocket.send_text(message)\n  File "C:\\Users\\rohka\\OneDrive\\Desktop\\ba-rfpapp\\venv\\Lib\\site-packages\\starlette\\websockets.py", line 166, in send_text\n    await self.send({"type": "websocket.send", "text": data})\n  File "C:\\Users\\rohka\\OneDrive\\Desktop\\ba-rfpapp\\venv\\Lib\\site-packages\\starlette\\websockets.py", line 98, in send\n    raise RuntimeError(\'Cannot call "send" once a close message has been sent.\')\nRuntimeError: Cannot call "send" once a close message has been sent.\n'}
2025-08-26 19:18:11,442 - BroadAxis - ERROR - Error occurred: {'error_type': 'RuntimeError', 'message': 'Cannot call "send" once a close message has been sent.', 'context': {'operation': 'websocket_send_message'}, 'traceback': 'Traceback (most recent call last):\n  File "C:\\Users\\rohka\\OneDrive\\Desktop\\ba-rfpapp\\backend\\websocket_api.py", line 161, in websocket_chat\n    await manager.send_personal_message(\n    ...<7 lines>...\n    )\n  File "C:\\Users\\rohka\\OneDrive\\Desktop\\ba-rfpapp\\backend\\websocket_api.py", line 30, in send_personal_message\n    await websocket.send_text(message)\n  File "C:\\Users\\rohka\\OneDrive\\Desktop\\ba-rfpapp\\venv\\Lib\\site-packages\\starlette\\websockets.py", line 166, in send_text\n    await self.send({"type": "websocket.send", "text": data})\n  File "C:\\Users\\rohka\\OneDrive\\Desktop\\ba-rfpapp\\venv\\Lib\\site-packages\\starlette\\websockets.py", line 98, in send\n    raise RuntimeError(\'Cannot call "send" once a close message has been sent.\')\nRuntimeError: Cannot call "send" once a close message has been sent.\n\nDuring handling of the above exception, another exception occurred:\n\nTraceback (most recent call last):\n  File "C:\\Users\\rohka\\OneDrive\\Desktop\\ba-rfpapp\\backend\\websocket_api.py", line 30, in send_personal_message\n    await websocket.send_text(message)\n  File "C:\\Users\\rohka\\OneDrive\\Desktop\\ba-rfpapp\\venv\\Lib\\site-packages\\starlette\\websockets.py", line 166, in send_text\n    await self.send({"type": "websocket.send", "text": data})\n  File "C:\\Users\\rohka\\OneDrive\\Desktop\\ba-rfpapp\\venv\\Lib\\site-packages\\starlette\\websockets.py", line 98, in send\n    raise RuntimeError(\'Cannot call "send" once a close message has been sent.\')\nRuntimeError: Cannot call "send" once a close message has been sent.\n'}
2025-08-26 19:18:11,444 - BroadAxis - ERROR - Error occurred: {'error_type': 'RuntimeError', 'message': 'Cannot call "send" once a close message has been sent.', 'context': {'session_id': 'ws_1778749769040_1756244282', 'operation': 'websocket_message_handling'}, 'traceback': 'Traceback (most recent call last):\n  File "C:\\Users\\rohka\\OneDrive\\Desktop\\ba-rfpapp\\backend\\websocket_api.py", line 161, in websocket_chat\n    await manager.send_personal_message(\n    ...<7 lines>...\n    )\n  File "C:\\Users\\rohka\\OneDrive\\Desktop\\ba-rfpapp\\backend\\websocket_api.py", line 30, in send_personal_message\n    await websocket.send_text(message)\n  File "C:\\Users\\rohka\\OneDrive\\Desktop\\ba-rfpapp\\venv\\Lib\\site-packages\\starlette\\websockets.py", line 166, in send_text\n    await self.send({"type": "websocket.send", "text": data})\n  File "C:\\Users\\rohka\\OneDrive\\Desktop\\ba-rfpapp\\venv\\Lib\\site-packages\\starlette\\websockets.py", line 98, in send\n    raise RuntimeError(\'Cannot call "send" once a close message has been sent.\')\nRuntimeError: Cannot call "send" once a close message has been sent.\n\nDuring handling of the above exception, another exception occurred:\n\nTraceback (most recent call last):\n  File "C:\\Users\\rohka\\OneDrive\\Desktop\\ba-rfpapp\\backend\\websocket_api.py", line 195, in websocket_chat\n    await manager.send_personal_message(\n    ...<6 lines>...\n    )\n  File "C:\\Users\\rohka\\OneDrive\\Desktop\\ba-rfpapp\\backend\\websocket_api.py", line 30, in send_personal_message\n    await websocket.send_text(message)\n  File "C:\\Users\\rohka\\OneDrive\\Desktop\\ba-rfpapp\\venv\\Lib\\site-packages\\starlette\\websockets.py", line 166, in send_text\n    await self.send({"type": "websocket.send", "text": data})\n  File "C:\\Users\\rohka\\OneDrive\\Desktop\\ba-rfpapp\\venv\\Lib\\site-packages\\starlette\\websockets.py", line 98, in send\n    raise RuntimeError(\'Cannot call "send" once a close message has been sent.\')\nRuntimeError: Cannot call "send" once a close message has been sent.\n'}
2025-08-26 19:18:11,819 - httpx - INFO - HTTP Request: POST https://api.anthropic.com/v1/messages "HTTP/1.1 200 OK"
2025-08-26 19:18:33,287 - httpx - INFO - HTTP Request: POST https://api.anthropic.com/v1/messages "HTTP/1.1 200 OK"
2025-08-26 19:18:36,816 - httpx - INFO - HTTP Request: POST https://api.anthropic.com/v1/messages "HTTP/1.1 200 OK"
2025-08-26 19:20:02,700 - BroadAxis - ERROR - Error occurred: {'error_type': 'WebSocketDisconnect', 'message': '(1012, None)', 'context': {'session_id': 'ws_1778750529776_1756253866', 'operation': 'websocket_message_handling'}, 'traceback': 'Traceback (most recent call last):\n  File "C:\\Users\\rohka\\OneDrive\\Desktop\\ba-rfpapp\\backend\\websocket_api.py", line 52, in websocket_chat\n    data = await asyncio.wait_for(websocket.receive_text(), timeout=300.0)  # 5 min timeout\n           ^^^^^^^^^^^^^^^^^^^^^^^^^^^^^^^^^^^^^^^^^^^^^^^^^^^^^^^^^^^^^^^\n  File "C:\\Users\\rohka\\AppData\\Local\\Programs\\Python\\Python313\\Lib\\asyncio\\tasks.py", line 507, in wait_for\n    return await fut\n           ^^^^^^^^^\n  File "C:\\Users\\rohka\\OneDrive\\Desktop\\ba-rfpapp\\venv\\Lib\\site-packages\\starlette\\websockets.py", line 120, in receive_text\n    self._raise_on_disconnect(message)\n    ~~~~~~~~~~~~~~~~~~~~~~~~~^^^^^^^^^\n  File "C:\\Users\\rohka\\OneDrive\\Desktop\\ba-rfpapp\\venv\\Lib\\site-packages\\starlette\\websockets.py", line 114, in _raise_on_disconnect\n    raise WebSocketDisconnect(message["code"], message.get("reason"))\nstarlette.websockets.WebSocketDisconnect: (1012, None)\n'}
2025-08-26 19:20:03,340 - asyncio - ERROR - an error occurred during closing of asynchronous generator <async_generator object stdio_client at 0x0000019E25B230D0>
asyncgen: <async_generator object stdio_client at 0x0000019E25B230D0>
  + Exception Group Traceback (most recent call last):
  |   File "C:\Users\rohka\OneDrive\Desktop\ba-rfpapp\venv\Lib\site-packages\anyio\_backends\_asyncio.py", line 772, in __aexit__
  |     raise BaseExceptionGroup(
  |         "unhandled errors in a TaskGroup", self._exceptions
  |     ) from None
  | BaseExceptionGroup: unhandled errors in a TaskGroup (1 sub-exception)
  +-+---------------- 1 ----------------
    | Traceback (most recent call last):
    |   File "C:\Users\rohka\OneDrive\Desktop\ba-rfpapp\venv\Lib\site-packages\mcp\client\stdio\__init__.py", line 187, in stdio_client
    |     yield read_stream, write_stream
    | GeneratorExit
    +------------------------------------

During handling of the above exception, another exception occurred:

Traceback (most recent call last):
  File "C:\Users\rohka\AppData\Local\Programs\Python\Python313\Lib\asyncio\tasks.py", line 304, in __step_run_and_handle_result
    result = coro.send(None)
  File "C:\Users\rohka\OneDrive\Desktop\ba-rfpapp\venv\Lib\site-packages\mcp\client\stdio\__init__.py", line 181, in stdio_client
    anyio.create_task_group() as tg,
    ~~~~~~~~~~~~~~~~~~~~~~~^^
  File "C:\Users\rohka\OneDrive\Desktop\ba-rfpapp\venv\Lib\site-packages\anyio\_backends\_asyncio.py", line 778, in __aexit__
    if self.cancel_scope.__exit__(type(exc), exc, exc.__traceback__):
       ~~~~~~~~~~~~~~~~~~~~~~~~~~^^^^^^^^^^^^^^^^^^^^^^^^^^^^^^^^^^^
  File "C:\Users\rohka\OneDrive\Desktop\ba-rfpapp\venv\Lib\site-packages\anyio\_backends\_asyncio.py", line 457, in __exit__
    raise RuntimeError(
    ...<2 lines>...
    )
RuntimeError: Attempted to exit cancel scope in a different task than it was entered in
2025-08-26 19:22:09,969 - httpx - INFO - HTTP Request: POST https://api.anthropic.com/v1/messages "HTTP/1.1 200 OK"
2025-08-26 19:29:46,852 - httpx - INFO - HTTP Request: POST https://api.anthropic.com/v1/messages "HTTP/1.1 200 OK"
2025-08-26 19:37:09,747 - BroadAxis - INFO - WebSocket disconnected gracefully: ws_2556640719760_1756255029
2025-08-26 19:37:47,550 - BroadAxis - INFO - WebSocket disconnected gracefully: ws_2556639624720_1756255067
2025-08-26 19:38:26,125 - httpx - INFO - HTTP Request: POST https://api.anthropic.com/v1/messages "HTTP/1.1 200 OK"
2025-08-26 19:38:26,165 - BroadAxis - INFO - WebSocket disconnected during message send
2025-08-26 19:38:26,165 - BroadAxis - WARNING - Attempted to send message to disconnected WebSocket
2025-08-26 20:26:50,275 - httpx - INFO - HTTP Request: POST https://api.anthropic.com/v1/messages "HTTP/1.1 200 OK"
2025-08-26 20:33:05,239 - httpx - INFO - HTTP Request: POST https://api.anthropic.com/v1/messages "HTTP/1.1 200 OK"
2025-08-26 20:35:11,982 - asyncio - ERROR - an error occurred during closing of asynchronous generator <async_generator object stdio_client at 0x000001EEFA27D690>
asyncgen: <async_generator object stdio_client at 0x000001EEFA27D690>
  + Exception Group Traceback (most recent call last):
  |   File "C:\Users\rohka\AppData\Local\Programs\Python\Python313\Lib\site-packages\anyio\_backends\_asyncio.py", line 772, in __aexit__
  |     raise BaseExceptionGroup(
  |         "unhandled errors in a TaskGroup", self._exceptions
  |     ) from None
  | BaseExceptionGroup: unhandled errors in a TaskGroup (1 sub-exception)
  +-+---------------- 1 ----------------
    | Traceback (most recent call last):
    |   File "C:\Users\rohka\AppData\Local\Programs\Python\Python313\Lib\site-packages\mcp\client\stdio\__init__.py", line 187, in stdio_client
    |     yield read_stream, write_stream
    | GeneratorExit
    +------------------------------------

During handling of the above exception, another exception occurred:

Traceback (most recent call last):
  File "C:\Users\rohka\AppData\Local\Programs\Python\Python313\Lib\site-packages\mcp\client\stdio\__init__.py", line 181, in stdio_client
    anyio.create_task_group() as tg,
    ~~~~~~~~~~~~~~~~~~~~~~~^^
  File "C:\Users\rohka\AppData\Local\Programs\Python\Python313\Lib\site-packages\anyio\_backends\_asyncio.py", line 778, in __aexit__
    if self.cancel_scope.__exit__(type(exc), exc, exc.__traceback__):
       ~~~~~~~~~~~~~~~~~~~~~~~~~~^^^^^^^^^^^^^^^^^^^^^^^^^^^^^^^^^^^
  File "C:\Users\rohka\AppData\Local\Programs\Python\Python313\Lib\site-packages\anyio\_backends\_asyncio.py", line 457, in __exit__
    raise RuntimeError(
    ...<2 lines>...
    )
RuntimeError: Attempted to exit cancel scope in a different task than it was entered in
2025-08-26 20:36:01,630 - httpx - INFO - HTTP Request: POST https://api.anthropic.com/v1/messages "HTTP/1.1 200 OK"
2025-08-26 20:36:03,989 - httpx - INFO - HTTP Request: POST https://api.anthropic.com/v1/messages "HTTP/1.1 200 OK"
2025-08-26 20:49:13,766 - asyncio - ERROR - an error occurred during closing of asynchronous generator <async_generator object stdio_client at 0x0000017E965D57E0>
asyncgen: <async_generator object stdio_client at 0x0000017E965D57E0>
  + Exception Group Traceback (most recent call last):
  |   File "C:\Users\rohka\AppData\Local\Programs\Python\Python313\Lib\site-packages\anyio\_backends\_asyncio.py", line 772, in __aexit__
  |     raise BaseExceptionGroup(
  |         "unhandled errors in a TaskGroup", self._exceptions
  |     ) from None
  | BaseExceptionGroup: unhandled errors in a TaskGroup (1 sub-exception)
  +-+---------------- 1 ----------------
    | Traceback (most recent call last):
    |   File "C:\Users\rohka\AppData\Local\Programs\Python\Python313\Lib\site-packages\mcp\client\stdio\__init__.py", line 187, in stdio_client
    |     yield read_stream, write_stream
    | GeneratorExit
    +------------------------------------

During handling of the above exception, another exception occurred:

Traceback (most recent call last):
  File "C:\Users\rohka\AppData\Local\Programs\Python\Python313\Lib\site-packages\mcp\client\stdio\__init__.py", line 181, in stdio_client
    anyio.create_task_group() as tg,
    ~~~~~~~~~~~~~~~~~~~~~~~^^
  File "C:\Users\rohka\AppData\Local\Programs\Python\Python313\Lib\site-packages\anyio\_backends\_asyncio.py", line 778, in __aexit__
    if self.cancel_scope.__exit__(type(exc), exc, exc.__traceback__):
       ~~~~~~~~~~~~~~~~~~~~~~~~~~^^^^^^^^^^^^^^^^^^^^^^^^^^^^^^^^^^^
  File "C:\Users\rohka\AppData\Local\Programs\Python\Python313\Lib\site-packages\anyio\_backends\_asyncio.py", line 457, in __exit__
    raise RuntimeError(
    ...<2 lines>...
    )
RuntimeError: Attempted to exit cancel scope in a different task than it was entered in
2025-08-26 20:51:43,894 - asyncio - ERROR - an error occurred during closing of asynchronous generator <async_generator object stdio_client at 0x00000201761E57E0>
asyncgen: <async_generator object stdio_client at 0x00000201761E57E0>
  + Exception Group Traceback (most recent call last):
  |   File "C:\Users\rohka\AppData\Local\Programs\Python\Python313\Lib\site-packages\anyio\_backends\_asyncio.py", line 772, in __aexit__
  |     raise BaseExceptionGroup(
  |         "unhandled errors in a TaskGroup", self._exceptions
  |     ) from None
  | BaseExceptionGroup: unhandled errors in a TaskGroup (1 sub-exception)
  +-+---------------- 1 ----------------
    | Traceback (most recent call last):
    |   File "C:\Users\rohka\AppData\Local\Programs\Python\Python313\Lib\site-packages\mcp\client\stdio\__init__.py", line 187, in stdio_client
    |     yield read_stream, write_stream
    | GeneratorExit
    +------------------------------------

During handling of the above exception, another exception occurred:

Traceback (most recent call last):
  File "C:\Users\rohka\AppData\Local\Programs\Python\Python313\Lib\site-packages\mcp\client\stdio\__init__.py", line 181, in stdio_client
    anyio.create_task_group() as tg,
    ~~~~~~~~~~~~~~~~~~~~~~~^^
  File "C:\Users\rohka\AppData\Local\Programs\Python\Python313\Lib\site-packages\anyio\_backends\_asyncio.py", line 778, in __aexit__
    if self.cancel_scope.__exit__(type(exc), exc, exc.__traceback__):
       ~~~~~~~~~~~~~~~~~~~~~~~~~~^^^^^^^^^^^^^^^^^^^^^^^^^^^^^^^^^^^
  File "C:\Users\rohka\AppData\Local\Programs\Python\Python313\Lib\site-packages\anyio\_backends\_asyncio.py", line 457, in __exit__
    raise RuntimeError(
    ...<2 lines>...
    )
RuntimeError: Attempted to exit cancel scope in a different task than it was entered in
2025-08-26 20:59:09,498 - asyncio - ERROR - an error occurred during closing of asynchronous generator <async_generator object stdio_client at 0x000002690E651690>
asyncgen: <async_generator object stdio_client at 0x000002690E651690>
  + Exception Group Traceback (most recent call last):
  |   File "C:\Users\rohka\AppData\Local\Programs\Python\Python313\Lib\site-packages\anyio\_backends\_asyncio.py", line 772, in __aexit__
  |     raise BaseExceptionGroup(
  |         "unhandled errors in a TaskGroup", self._exceptions
  |     ) from None
  | BaseExceptionGroup: unhandled errors in a TaskGroup (1 sub-exception)
  +-+---------------- 1 ----------------
    | Traceback (most recent call last):
    |   File "C:\Users\rohka\AppData\Local\Programs\Python\Python313\Lib\site-packages\mcp\client\stdio\__init__.py", line 187, in stdio_client
    |     yield read_stream, write_stream
    | GeneratorExit
    +------------------------------------

During handling of the above exception, another exception occurred:

Traceback (most recent call last):
  File "C:\Users\rohka\AppData\Local\Programs\Python\Python313\Lib\site-packages\mcp\client\stdio\__init__.py", line 181, in stdio_client
    anyio.create_task_group() as tg,
    ~~~~~~~~~~~~~~~~~~~~~~~^^
  File "C:\Users\rohka\AppData\Local\Programs\Python\Python313\Lib\site-packages\anyio\_backends\_asyncio.py", line 778, in __aexit__
    if self.cancel_scope.__exit__(type(exc), exc, exc.__traceback__):
       ~~~~~~~~~~~~~~~~~~~~~~~~~~^^^^^^^^^^^^^^^^^^^^^^^^^^^^^^^^^^^
  File "C:\Users\rohka\AppData\Local\Programs\Python\Python313\Lib\site-packages\anyio\_backends\_asyncio.py", line 457, in __exit__
    raise RuntimeError(
    ...<2 lines>...
    )
RuntimeError: Attempted to exit cancel scope in a different task than it was entered in
2025-08-26 20:59:33,135 - asyncio - ERROR - an error occurred during closing of asynchronous generator <async_generator object stdio_client at 0x0000024EE23D30D0>
asyncgen: <async_generator object stdio_client at 0x0000024EE23D30D0>
  + Exception Group Traceback (most recent call last):
  |   File "C:\Users\rohka\OneDrive\Desktop\ba-rfpapp\venv\Lib\site-packages\anyio\_backends\_asyncio.py", line 772, in __aexit__
  |     raise BaseExceptionGroup(
  |         "unhandled errors in a TaskGroup", self._exceptions
  |     ) from None
  | BaseExceptionGroup: unhandled errors in a TaskGroup (1 sub-exception)
  +-+---------------- 1 ----------------
    | Traceback (most recent call last):
    |   File "C:\Users\rohka\OneDrive\Desktop\ba-rfpapp\venv\Lib\site-packages\mcp\client\stdio\__init__.py", line 187, in stdio_client
    |     yield read_stream, write_stream
    | GeneratorExit
    +------------------------------------

During handling of the above exception, another exception occurred:

Traceback (most recent call last):
  File "C:\Users\rohka\AppData\Local\Programs\Python\Python313\Lib\asyncio\tasks.py", line 304, in __step_run_and_handle_result
    result = coro.send(None)
  File "C:\Users\rohka\OneDrive\Desktop\ba-rfpapp\venv\Lib\site-packages\mcp\client\stdio\__init__.py", line 181, in stdio_client
    anyio.create_task_group() as tg,
    ~~~~~~~~~~~~~~~~~~~~~~~^^
  File "C:\Users\rohka\OneDrive\Desktop\ba-rfpapp\venv\Lib\site-packages\anyio\_backends\_asyncio.py", line 778, in __aexit__
    if self.cancel_scope.__exit__(type(exc), exc, exc.__traceback__):
       ~~~~~~~~~~~~~~~~~~~~~~~~~~^^^^^^^^^^^^^^^^^^^^^^^^^^^^^^^^^^^
  File "C:\Users\rohka\OneDrive\Desktop\ba-rfpapp\venv\Lib\site-packages\anyio\_backends\_asyncio.py", line 457, in __exit__
    raise RuntimeError(
    ...<2 lines>...
    )
RuntimeError: Attempted to exit cancel scope in a different task than it was entered in
2025-08-26 21:00:18,037 - httpx - INFO - HTTP Request: POST https://api.anthropic.com/v1/messages "HTTP/1.1 200 OK"
2025-08-26 21:11:48,013 - BroadAxis - ERROR - Error occurred: {'error_type': 'WebSocketDisconnect', 'message': "(1001, '')", 'context': {'session_id': 'ws_2282835347008_1756260703', 'operation': 'websocket_message_handling'}, 'traceback': 'Traceback (most recent call last):\n  File "C:\\Users\\rohka\\OneDrive\\Desktop\\ba-rfpapp\\backend\\websocket_api.py", line 52, in websocket_chat\n    data = await asyncio.wait_for(websocket.receive_text(), timeout=300.0)  # 5 min timeout\n           ^^^^^^^^^^^^^^^^^^^^^^^^^^^^^^^^^^^^^^^^^^^^^^^^^^^^^^^^^^^^^^^\n  File "C:\\Users\\rohka\\AppData\\Local\\Programs\\Python\\Python313\\Lib\\asyncio\\tasks.py", line 507, in wait_for\n    return await fut\n           ^^^^^^^^^\n  File "C:\\Users\\rohka\\OneDrive\\Desktop\\ba-rfpapp\\venv\\Lib\\site-packages\\starlette\\websockets.py", line 120, in receive_text\n    self._raise_on_disconnect(message)\n    ~~~~~~~~~~~~~~~~~~~~~~~~~^^^^^^^^^\n  File "C:\\Users\\rohka\\OneDrive\\Desktop\\ba-rfpapp\\venv\\Lib\\site-packages\\starlette\\websockets.py", line 114, in _raise_on_disconnect\n    raise WebSocketDisconnect(message["code"], message.get("reason"))\nstarlette.websockets.WebSocketDisconnect: (1001, \'\')\n'}
2025-08-26 21:12:09,863 - httpx - INFO - HTTP Request: POST https://api.anthropic.com/v1/messages "HTTP/1.1 200 OK"
2025-08-26 21:12:17,777 - httpx - INFO - HTTP Request: POST https://api.anthropic.com/v1/messages "HTTP/1.1 200 OK"
2025-08-26 21:12:36,204 - httpx - INFO - HTTP Request: POST https://api.anthropic.com/v1/messages "HTTP/1.1 200 OK"
2025-08-26 21:12:46,003 - httpx - INFO - HTTP Request: POST https://api.anthropic.com/v1/messages "HTTP/1.1 200 OK"
2025-08-26 21:13:09,069 - httpx - INFO - HTTP Request: POST https://api.anthropic.com/v1/messages "HTTP/1.1 200 OK"
2025-08-26 21:13:17,768 - httpx - INFO - HTTP Request: POST https://api.anthropic.com/v1/messages "HTTP/1.1 200 OK"
2025-08-26 21:13:43,041 - httpx - INFO - HTTP Request: POST https://api.anthropic.com/v1/messages "HTTP/1.1 200 OK"
2025-08-26 21:13:49,628 - httpx - INFO - HTTP Request: POST https://api.anthropic.com/v1/messages "HTTP/1.1 200 OK"
2025-08-26 21:15:22,249 - httpx - INFO - HTTP Request: POST https://api.anthropic.com/v1/messages "HTTP/1.1 200 OK"
2025-08-26 21:15:26,312 - httpx - INFO - HTTP Request: POST https://api.anthropic.com/v1/messages "HTTP/1.1 200 OK"
2025-08-26 21:22:47,655 - BroadAxis - ERROR - Error occurred: {'error_type': 'WebSocketDisconnect', 'message': "(1001, '')", 'context': {'session_id': 'ws_2282834920784_1756260703', 'operation': 'websocket_message_handling'}, 'traceback': 'Traceback (most recent call last):\n  File "C:\\Users\\rohka\\OneDrive\\Desktop\\ba-rfpapp\\backend\\websocket_api.py", line 52, in websocket_chat\n    data = await asyncio.wait_for(websocket.receive_text(), timeout=300.0)  # 5 min timeout\n           ^^^^^^^^^^^^^^^^^^^^^^^^^^^^^^^^^^^^^^^^^^^^^^^^^^^^^^^^^^^^^^^\n  File "C:\\Users\\rohka\\AppData\\Local\\Programs\\Python\\Python313\\Lib\\asyncio\\tasks.py", line 507, in wait_for\n    return await fut\n           ^^^^^^^^^\n  File "C:\\Users\\rohka\\OneDrive\\Desktop\\ba-rfpapp\\venv\\Lib\\site-packages\\starlette\\websockets.py", line 120, in receive_text\n    self._raise_on_disconnect(message)\n    ~~~~~~~~~~~~~~~~~~~~~~~~~^^^^^^^^^\n  File "C:\\Users\\rohka\\OneDrive\\Desktop\\ba-rfpapp\\venv\\Lib\\site-packages\\starlette\\websockets.py", line 114, in _raise_on_disconnect\n    raise WebSocketDisconnect(message["code"], message.get("reason"))\nstarlette.websockets.WebSocketDisconnect: (1001, \'\')\n'}
2025-08-26 21:22:55,820 - BroadAxis - ERROR - Error occurred: {'error_type': 'WebSocketDisconnect', 'message': "(1001, '')", 'context': {'session_id': 'ws_2282835097744_1756261368', 'operation': 'websocket_message_handling'}, 'traceback': 'Traceback (most recent call last):\n  File "C:\\Users\\rohka\\OneDrive\\Desktop\\ba-rfpapp\\backend\\websocket_api.py", line 52, in websocket_chat\n    data = await asyncio.wait_for(websocket.receive_text(), timeout=300.0)  # 5 min timeout\n           ^^^^^^^^^^^^^^^^^^^^^^^^^^^^^^^^^^^^^^^^^^^^^^^^^^^^^^^^^^^^^^^\n  File "C:\\Users\\rohka\\AppData\\Local\\Programs\\Python\\Python313\\Lib\\asyncio\\tasks.py", line 507, in wait_for\n    return await fut\n           ^^^^^^^^^\n  File "C:\\Users\\rohka\\OneDrive\\Desktop\\ba-rfpapp\\venv\\Lib\\site-packages\\starlette\\websockets.py", line 120, in receive_text\n    self._raise_on_disconnect(message)\n    ~~~~~~~~~~~~~~~~~~~~~~~~~^^^^^^^^^\n  File "C:\\Users\\rohka\\OneDrive\\Desktop\\ba-rfpapp\\venv\\Lib\\site-packages\\starlette\\websockets.py", line 114, in _raise_on_disconnect\n    raise WebSocketDisconnect(message["code"], message.get("reason"))\nstarlette.websockets.WebSocketDisconnect: (1001, \'\')\n'}
2025-08-26 21:23:16,598 - httpx - INFO - HTTP Request: POST https://api.anthropic.com/v1/messages "HTTP/1.1 200 OK"
2025-08-26 21:23:26,236 - httpx - INFO - HTTP Request: POST https://api.anthropic.com/v1/messages "HTTP/1.1 200 OK"
2025-08-26 21:23:40,733 - httpx - INFO - HTTP Request: POST https://api.anthropic.com/v1/messages "HTTP/1.1 200 OK"
2025-08-26 21:23:43,783 - httpx - INFO - HTTP Request: POST https://api.anthropic.com/v1/messages "HTTP/1.1 200 OK"
2025-08-26 21:23:47,299 - httpx - INFO - HTTP Request: POST https://api.anthropic.com/v1/messages "HTTP/1.1 200 OK"
2025-08-26 21:23:53,024 - httpx - INFO - HTTP Request: POST https://api.anthropic.com/v1/messages "HTTP/1.1 200 OK"
2025-08-26 21:23:58,135 - httpx - INFO - HTTP Request: POST https://api.anthropic.com/v1/messages "HTTP/1.1 200 OK"
2025-08-26 21:24:05,102 - httpx - INFO - HTTP Request: POST https://api.anthropic.com/v1/messages "HTTP/1.1 200 OK"
2025-08-26 21:24:06,293 - httpx - INFO - HTTP Request: POST https://api.anthropic.com/v1/messages "HTTP/1.1 429 Too Many Requests"
2025-08-26 21:24:06,294 - anthropic._base_client - INFO - Retrying request to /v1/messages in 6.000000 seconds
2025-08-26 21:24:14,636 - httpx - INFO - HTTP Request: POST https://api.anthropic.com/v1/messages "HTTP/1.1 200 OK"
2025-08-26 21:24:15,547 - httpx - INFO - HTTP Request: POST https://api.anthropic.com/v1/messages "HTTP/1.1 429 Too Many Requests"
2025-08-26 21:24:15,549 - anthropic._base_client - INFO - Retrying request to /v1/messages in 18.000000 seconds
2025-08-26 21:24:29,333 - asyncio - ERROR - an error occurred during closing of asynchronous generator <async_generator object stdio_client at 0x00000213838E1BD0>
asyncgen: <async_generator object stdio_client at 0x00000213838E1BD0>
  + Exception Group Traceback (most recent call last):
  |   File "C:\Users\rohka\OneDrive\Desktop\ba-rfpapp\venv\Lib\site-packages\anyio\_backends\_asyncio.py", line 772, in __aexit__
  |     raise BaseExceptionGroup(
  |         "unhandled errors in a TaskGroup", self._exceptions
  |     ) from None
  | BaseExceptionGroup: unhandled errors in a TaskGroup (1 sub-exception)
  +-+---------------- 1 ----------------
    | Traceback (most recent call last):
    |   File "C:\Users\rohka\OneDrive\Desktop\ba-rfpapp\venv\Lib\site-packages\mcp\client\stdio\__init__.py", line 187, in stdio_client
    |     yield read_stream, write_stream
    | GeneratorExit
    +------------------------------------

During handling of the above exception, another exception occurred:

Traceback (most recent call last):
  File "C:\Users\rohka\AppData\Local\Programs\Python\Python313\Lib\asyncio\tasks.py", line 304, in __step_run_and_handle_result
    result = coro.send(None)
  File "C:\Users\rohka\OneDrive\Desktop\ba-rfpapp\venv\Lib\site-packages\mcp\client\stdio\__init__.py", line 181, in stdio_client
    anyio.create_task_group() as tg,
    ~~~~~~~~~~~~~~~~~~~~~~~^^
  File "C:\Users\rohka\OneDrive\Desktop\ba-rfpapp\venv\Lib\site-packages\anyio\_backends\_asyncio.py", line 778, in __aexit__
    if self.cancel_scope.__exit__(type(exc), exc, exc.__traceback__):
       ~~~~~~~~~~~~~~~~~~~~~~~~~~^^^^^^^^^^^^^^^^^^^^^^^^^^^^^^^^^^^
  File "C:\Users\rohka\OneDrive\Desktop\ba-rfpapp\venv\Lib\site-packages\anyio\_backends\_asyncio.py", line 457, in __exit__
    raise RuntimeError(
    ...<2 lines>...
    )
RuntimeError: Attempted to exit cancel scope in a different task than it was entered in
2025-08-26 21:29:48,635 - BroadAxis - ERROR - Error occurred: {'error_type': 'WebSocketDisconnect', 'message': "(1001, '')", 'context': {'session_id': 'ws_2660106976656_1756261474', 'operation': 'websocket_message_handling'}, 'traceback': 'Traceback (most recent call last):\n  File "C:\\Users\\rohka\\OneDrive\\Desktop\\ba-rfpapp\\backend\\websocket_api.py", line 52, in websocket_chat\n    data = await asyncio.wait_for(websocket.receive_text(), timeout=300.0)  # 5 min timeout\n           ^^^^^^^^^^^^^^^^^^^^^^^^^^^^^^^^^^^^^^^^^^^^^^^^^^^^^^^^^^^^^^^\n  File "C:\\Users\\rohka\\AppData\\Local\\Programs\\Python\\Python313\\Lib\\asyncio\\tasks.py", line 507, in wait_for\n    return await fut\n           ^^^^^^^^^\n  File "C:\\Users\\rohka\\OneDrive\\Desktop\\ba-rfpapp\\venv\\Lib\\site-packages\\starlette\\websockets.py", line 120, in receive_text\n    self._raise_on_disconnect(message)\n    ~~~~~~~~~~~~~~~~~~~~~~~~~^^^^^^^^^\n  File "C:\\Users\\rohka\\OneDrive\\Desktop\\ba-rfpapp\\venv\\Lib\\site-packages\\starlette\\websockets.py", line 114, in _raise_on_disconnect\n    raise WebSocketDisconnect(message["code"], message.get("reason"))\nstarlette.websockets.WebSocketDisconnect: (1001, \'\')\n'}
2025-08-26 21:30:23,489 - httpx - INFO - HTTP Request: POST https://api.anthropic.com/v1/messages "HTTP/1.1 200 OK"
2025-08-26 21:30:26,788 - httpx - INFO - HTTP Request: POST https://api.anthropic.com/v1/messages "HTTP/1.1 200 OK"
2025-08-26 21:30:29,541 - httpx - INFO - HTTP Request: POST https://api.anthropic.com/v1/messages "HTTP/1.1 400 Bad Request"
2025-08-26 21:37:29,590 - BroadAxis - ERROR - Error occurred: {'error_type': 'WebSocketDisconnect', 'message': "(1001, '')", 'context': {'session_id': 'ws_2660106448240_1756261790', 'operation': 'websocket_message_handling'}, 'traceback': 'Traceback (most recent call last):\n  File "C:\\Users\\rohka\\OneDrive\\Desktop\\ba-rfpapp\\backend\\websocket_api.py", line 52, in websocket_chat\n    data = await asyncio.wait_for(websocket.receive_text(), timeout=300.0)  # 5 min timeout\n           ^^^^^^^^^^^^^^^^^^^^^^^^^^^^^^^^^^^^^^^^^^^^^^^^^^^^^^^^^^^^^^^\n  File "C:\\Users\\rohka\\AppData\\Local\\Programs\\Python\\Python313\\Lib\\asyncio\\tasks.py", line 507, in wait_for\n    return await fut\n           ^^^^^^^^^\n  File "C:\\Users\\rohka\\OneDrive\\Desktop\\ba-rfpapp\\venv\\Lib\\site-packages\\starlette\\websockets.py", line 120, in receive_text\n    self._raise_on_disconnect(message)\n    ~~~~~~~~~~~~~~~~~~~~~~~~~^^^^^^^^^\n  File "C:\\Users\\rohka\\OneDrive\\Desktop\\ba-rfpapp\\venv\\Lib\\site-packages\\starlette\\websockets.py", line 114, in _raise_on_disconnect\n    raise WebSocketDisconnect(message["code"], message.get("reason"))\nstarlette.websockets.WebSocketDisconnect: (1001, \'\')\n'}
2025-08-26 21:37:48,732 - httpx - INFO - HTTP Request: POST https://api.anthropic.com/v1/messages "HTTP/1.1 200 OK"
2025-08-26 21:37:51,417 - httpx - INFO - HTTP Request: POST https://api.anthropic.com/v1/messages "HTTP/1.1 200 OK"
2025-08-26 21:37:55,973 - httpx - INFO - HTTP Request: POST https://api.anthropic.com/v1/messages "HTTP/1.1 200 OK"
2025-08-26 21:37:57,886 - httpx - INFO - HTTP Request: POST https://api.anthropic.com/v1/messages "HTTP/1.1 200 OK"
2025-08-26 21:38:00,321 - httpx - INFO - HTTP Request: POST https://api.anthropic.com/v1/messages "HTTP/1.1 200 OK"
2025-08-26 21:38:01,385 - httpx - INFO - HTTP Request: POST https://api.anthropic.com/v1/messages "HTTP/1.1 429 Too Many Requests"
2025-08-26 21:38:01,387 - anthropic._base_client - INFO - Retrying request to /v1/messages in 13.000000 seconds
2025-08-26 21:38:16,231 - httpx - INFO - HTTP Request: POST https://api.anthropic.com/v1/messages "HTTP/1.1 200 OK"
2025-08-26 21:38:17,268 - httpx - INFO - HTTP Request: POST https://api.anthropic.com/v1/messages "HTTP/1.1 429 Too Many Requests"
2025-08-26 21:38:17,269 - anthropic._base_client - INFO - Retrying request to /v1/messages in 21.000000 seconds
2025-08-26 21:38:40,225 - httpx - INFO - HTTP Request: POST https://api.anthropic.com/v1/messages "HTTP/1.1 200 OK"
2025-08-26 21:38:41,125 - httpx - INFO - HTTP Request: POST https://api.anthropic.com/v1/messages "HTTP/1.1 429 Too Many Requests"
2025-08-26 21:38:41,128 - anthropic._base_client - INFO - Retrying request to /v1/messages in 21.000000 seconds
2025-08-26 21:39:05,186 - httpx - INFO - HTTP Request: POST https://api.anthropic.com/v1/messages "HTTP/1.1 200 OK"
2025-08-26 21:39:07,323 - httpx - INFO - HTTP Request: POST https://api.anthropic.com/v1/messages "HTTP/1.1 429 Too Many Requests"
2025-08-26 21:39:07,325 - anthropic._base_client - INFO - Retrying request to /v1/messages in 22.000000 seconds
2025-08-26 21:39:40,334 - httpx - INFO - HTTP Request: POST https://api.anthropic.com/v1/messages "HTTP/1.1 200 OK"
2025-08-26 21:45:35,534 - BroadAxis - ERROR - Error occurred: {'error_type': 'WebSocketDisconnect', 'message': "(1001, '')", 'context': {'session_id': 'ws_2660106665520_1756262250', 'operation': 'websocket_message_handling'}, 'traceback': 'Traceback (most recent call last):\n  File "C:\\Users\\rohka\\OneDrive\\Desktop\\ba-rfpapp\\backend\\websocket_api.py", line 52, in websocket_chat\n    data = await asyncio.wait_for(websocket.receive_text(), timeout=300.0)  # 5 min timeout\n           ^^^^^^^^^^^^^^^^^^^^^^^^^^^^^^^^^^^^^^^^^^^^^^^^^^^^^^^^^^^^^^^\n  File "C:\\Users\\rohka\\AppData\\Local\\Programs\\Python\\Python313\\Lib\\asyncio\\tasks.py", line 507, in wait_for\n    return await fut\n           ^^^^^^^^^\n  File "C:\\Users\\rohka\\OneDrive\\Desktop\\ba-rfpapp\\venv\\Lib\\site-packages\\starlette\\websockets.py", line 120, in receive_text\n    self._raise_on_disconnect(message)\n    ~~~~~~~~~~~~~~~~~~~~~~~~~^^^^^^^^^\n  File "C:\\Users\\rohka\\OneDrive\\Desktop\\ba-rfpapp\\venv\\Lib\\site-packages\\starlette\\websockets.py", line 114, in _raise_on_disconnect\n    raise WebSocketDisconnect(message["code"], message.get("reason"))\nstarlette.websockets.WebSocketDisconnect: (1001, \'\')\n'}
2025-08-26 21:46:00,660 - httpx - INFO - HTTP Request: POST https://api.anthropic.com/v1/messages "HTTP/1.1 200 OK"
2025-08-26 21:46:09,292 - httpx - INFO - HTTP Request: POST https://api.anthropic.com/v1/messages "HTTP/1.1 200 OK"
2025-08-26 21:46:37,955 - httpx - INFO - HTTP Request: POST https://api.anthropic.com/v1/messages "HTTP/1.1 200 OK"
2025-08-26 21:46:48,671 - httpx - INFO - HTTP Request: POST https://api.anthropic.com/v1/messages "HTTP/1.1 200 OK"
2025-08-27 09:42:12,464 - BroadAxis - ERROR - Error occurred: {'error_type': 'WebSocketDisconnect', 'message': "(1001, '')", 'context': {'session_id': 'ws_2824775283600_1756305717', 'operation': 'websocket_message_handling'}, 'traceback': 'Traceback (most recent call last):\n  File "C:\\Users\\rohka\\OneDrive\\Desktop\\ba-rfpapp\\backend\\websocket_api.py", line 52, in websocket_chat\n    data = await asyncio.wait_for(websocket.receive_text(), timeout=300.0)  # 5 min timeout\n           ^^^^^^^^^^^^^^^^^^^^^^^^^^^^^^^^^^^^^^^^^^^^^^^^^^^^^^^^^^^^^^^\n  File "C:\\Users\\rohka\\AppData\\Local\\Programs\\Python\\Python313\\Lib\\asyncio\\tasks.py", line 507, in wait_for\n    return await fut\n           ^^^^^^^^^\n  File "C:\\Users\\rohka\\OneDrive\\Desktop\\ba-rfpapp\\venv\\Lib\\site-packages\\starlette\\websockets.py", line 120, in receive_text\n    self._raise_on_disconnect(message)\n    ~~~~~~~~~~~~~~~~~~~~~~~~~^^^^^^^^^\n  File "C:\\Users\\rohka\\OneDrive\\Desktop\\ba-rfpapp\\venv\\Lib\\site-packages\\starlette\\websockets.py", line 114, in _raise_on_disconnect\n    raise WebSocketDisconnect(message["code"], message.get("reason"))\nstarlette.websockets.WebSocketDisconnect: (1001, \'\')\n'}
2025-08-27 10:00:59,793 - BroadAxis - ERROR - Error occurred: {'error_type': 'WebSocketDisconnect', 'message': '(1012, None)', 'context': {'session_id': 'ws_2802271142928_1756306436', 'operation': 'websocket_message_handling'}, 'traceback': 'Traceback (most recent call last):\n  File "C:\\Users\\rohka\\OneDrive\\Desktop\\ba-rfpapp\\backend\\websocket_api.py", line 52, in websocket_chat\n    data = await asyncio.wait_for(websocket.receive_text(), timeout=300.0)  # 5 min timeout\n           ^^^^^^^^^^^^^^^^^^^^^^^^^^^^^^^^^^^^^^^^^^^^^^^^^^^^^^^^^^^^^^^\n  File "C:\\Users\\rohka\\AppData\\Local\\Programs\\Python\\Python313\\Lib\\asyncio\\tasks.py", line 507, in wait_for\n    return await fut\n           ^^^^^^^^^\n  File "C:\\Users\\rohka\\OneDrive\\Desktop\\ba-rfpapp\\venv\\Lib\\site-packages\\starlette\\websockets.py", line 120, in receive_text\n    self._raise_on_disconnect(message)\n    ~~~~~~~~~~~~~~~~~~~~~~~~~^^^^^^^^^\n  File "C:\\Users\\rohka\\OneDrive\\Desktop\\ba-rfpapp\\venv\\Lib\\site-packages\\starlette\\websockets.py", line 114, in _raise_on_disconnect\n    raise WebSocketDisconnect(message["code"], message.get("reason"))\nstarlette.websockets.WebSocketDisconnect: (1012, None)\n'}
2025-08-27 10:01:00,654 - asyncio - ERROR - an error occurred during closing of asynchronous generator <async_generator object stdio_client at 0x0000028C745E1000>
asyncgen: <async_generator object stdio_client at 0x0000028C745E1000>
  + Exception Group Traceback (most recent call last):
  |   File "C:\Users\rohka\OneDrive\Desktop\ba-rfpapp\venv\Lib\site-packages\anyio\_backends\_asyncio.py", line 772, in __aexit__
  |     raise BaseExceptionGroup(
  |         "unhandled errors in a TaskGroup", self._exceptions
  |     ) from None
  | BaseExceptionGroup: unhandled errors in a TaskGroup (1 sub-exception)
  +-+---------------- 1 ----------------
    | Traceback (most recent call last):
    |   File "C:\Users\rohka\OneDrive\Desktop\ba-rfpapp\venv\Lib\site-packages\mcp\client\stdio\__init__.py", line 187, in stdio_client
    |     yield read_stream, write_stream
    | GeneratorExit
    +------------------------------------

During handling of the above exception, another exception occurred:

Traceback (most recent call last):
  File "C:\Users\rohka\AppData\Local\Programs\Python\Python313\Lib\asyncio\tasks.py", line 304, in __step_run_and_handle_result
    result = coro.send(None)
  File "C:\Users\rohka\OneDrive\Desktop\ba-rfpapp\venv\Lib\site-packages\mcp\client\stdio\__init__.py", line 181, in stdio_client
    anyio.create_task_group() as tg,
    ~~~~~~~~~~~~~~~~~~~~~~~^^
  File "C:\Users\rohka\OneDrive\Desktop\ba-rfpapp\venv\Lib\site-packages\anyio\_backends\_asyncio.py", line 778, in __aexit__
    if self.cancel_scope.__exit__(type(exc), exc, exc.__traceback__):
       ~~~~~~~~~~~~~~~~~~~~~~~~~~^^^^^^^^^^^^^^^^^^^^^^^^^^^^^^^^^^^
  File "C:\Users\rohka\OneDrive\Desktop\ba-rfpapp\venv\Lib\site-packages\anyio\_backends\_asyncio.py", line 457, in __exit__
    raise RuntimeError(
    ...<2 lines>...
    )
RuntimeError: Attempted to exit cancel scope in a different task than it was entered in
2025-08-27 10:02:59,370 - httpx - INFO - HTTP Request: POST https://api.anthropic.com/v1/messages "HTTP/1.1 200 OK"
2025-08-27 10:03:02,594 - httpx - INFO - HTTP Request: POST https://api.anthropic.com/v1/messages "HTTP/1.1 200 OK"
2025-08-27 10:03:18,231 - httpx - INFO - HTTP Request: POST https://api.anthropic.com/v1/messages "HTTP/1.1 200 OK"
2025-08-27 10:34:45,560 - httpx - INFO - HTTP Request: POST https://api.anthropic.com/v1/messages "HTTP/1.1 200 OK"
2025-08-27 10:51:03,591 - BroadAxis - ERROR - Error occurred: {'error_type': 'WebSocketDisconnect', 'message': '(1012, None)', 'context': {'session_id': 'ws_1721460667600_1756306864', 'operation': 'websocket_message_handling'}, 'traceback': 'Traceback (most recent call last):\n  File "C:\\Users\\rohka\\OneDrive\\Desktop\\ba-rfpapp\\backend\\websocket_api.py", line 52, in websocket_chat\n    data = await asyncio.wait_for(websocket.receive_text(), timeout=300.0)  # 5 min timeout\n           ^^^^^^^^^^^^^^^^^^^^^^^^^^^^^^^^^^^^^^^^^^^^^^^^^^^^^^^^^^^^^^^\n  File "C:\\Users\\rohka\\AppData\\Local\\Programs\\Python\\Python313\\Lib\\asyncio\\tasks.py", line 507, in wait_for\n    return await fut\n           ^^^^^^^^^\n  File "C:\\Users\\rohka\\OneDrive\\Desktop\\ba-rfpapp\\venv\\Lib\\site-packages\\starlette\\websockets.py", line 120, in receive_text\n    self._raise_on_disconnect(message)\n    ~~~~~~~~~~~~~~~~~~~~~~~~~^^^^^^^^^\n  File "C:\\Users\\rohka\\OneDrive\\Desktop\\ba-rfpapp\\venv\\Lib\\site-packages\\starlette\\websockets.py", line 114, in _raise_on_disconnect\n    raise WebSocketDisconnect(message["code"], message.get("reason"))\nstarlette.websockets.WebSocketDisconnect: (1012, None)\n'}
2025-08-27 10:51:04,964 - asyncio - ERROR - an error occurred during closing of asynchronous generator <async_generator object stdio_client at 0x00000190CEEE23B0>
asyncgen: <async_generator object stdio_client at 0x00000190CEEE23B0>
  + Exception Group Traceback (most recent call last):
  |   File "C:\Users\rohka\OneDrive\Desktop\ba-rfpapp\venv\Lib\site-packages\anyio\_backends\_asyncio.py", line 772, in __aexit__
  |     raise BaseExceptionGroup(
  |         "unhandled errors in a TaskGroup", self._exceptions
  |     ) from None
  | BaseExceptionGroup: unhandled errors in a TaskGroup (1 sub-exception)
  +-+---------------- 1 ----------------
    | Traceback (most recent call last):
    |   File "C:\Users\rohka\OneDrive\Desktop\ba-rfpapp\venv\Lib\site-packages\mcp\client\stdio\__init__.py", line 187, in stdio_client
    |     yield read_stream, write_stream
    | GeneratorExit
    +------------------------------------

During handling of the above exception, another exception occurred:

Traceback (most recent call last):
  File "C:\Users\rohka\AppData\Local\Programs\Python\Python313\Lib\asyncio\tasks.py", line 304, in __step_run_and_handle_result
    result = coro.send(None)
  File "C:\Users\rohka\OneDrive\Desktop\ba-rfpapp\venv\Lib\site-packages\mcp\client\stdio\__init__.py", line 181, in stdio_client
    anyio.create_task_group() as tg,
    ~~~~~~~~~~~~~~~~~~~~~~~^^
  File "C:\Users\rohka\OneDrive\Desktop\ba-rfpapp\venv\Lib\site-packages\anyio\_backends\_asyncio.py", line 778, in __aexit__
    if self.cancel_scope.__exit__(type(exc), exc, exc.__traceback__):
       ~~~~~~~~~~~~~~~~~~~~~~~~~~^^^^^^^^^^^^^^^^^^^^^^^^^^^^^^^^^^^
  File "C:\Users\rohka\OneDrive\Desktop\ba-rfpapp\venv\Lib\site-packages\anyio\_backends\_asyncio.py", line 457, in __exit__
    raise RuntimeError(
    ...<2 lines>...
    )
RuntimeError: Attempted to exit cancel scope in a different task than it was entered in
2025-08-27 11:01:22,376 - httpx - INFO - HTTP Request: POST https://api.anthropic.com/v1/messages "HTTP/1.1 529 "
2025-08-27 11:01:22,379 - anthropic._base_client - INFO - Retrying request to /v1/messages in 0.420703 seconds
2025-08-27 11:01:26,677 - httpx - INFO - HTTP Request: POST https://api.anthropic.com/v1/messages "HTTP/1.1 200 OK"
2025-08-27 11:01:30,958 - httpx - INFO - HTTP Request: POST https://api.anthropic.com/v1/messages "HTTP/1.1 200 OK"
2025-08-27 11:01:48,632 - httpx - INFO - HTTP Request: POST https://api.anthropic.com/v1/messages "HTTP/1.1 200 OK"
2025-08-27 11:02:30,348 - httpx - INFO - HTTP Request: POST https://api.anthropic.com/v1/messages "HTTP/1.1 200 OK"
2025-08-27 11:03:09,340 - BroadAxis - ERROR - Error occurred: {'error_type': 'WebSocketDisconnect', 'message': '(1012, None)', 'context': {'session_id': '1756310422252', 'operation': 'websocket_message_handling'}, 'traceback': 'Traceback (most recent call last):\n  File "C:\\Users\\rohka\\OneDrive\\Desktop\\ba-rfpapp\\backend\\websocket_api.py", line 61, in websocket_chat\n    data = await asyncio.wait_for(websocket.receive_text(), timeout=300.0)  # 5 min timeout\n           ^^^^^^^^^^^^^^^^^^^^^^^^^^^^^^^^^^^^^^^^^^^^^^^^^^^^^^^^^^^^^^^\n  File "C:\\Users\\rohka\\AppData\\Local\\Programs\\Python\\Python313\\Lib\\asyncio\\tasks.py", line 507, in wait_for\n    return await fut\n           ^^^^^^^^^\n  File "C:\\Users\\rohka\\OneDrive\\Desktop\\ba-rfpapp\\venv\\Lib\\site-packages\\starlette\\websockets.py", line 120, in receive_text\n    self._raise_on_disconnect(message)\n    ~~~~~~~~~~~~~~~~~~~~~~~~~^^^^^^^^^\n  File "C:\\Users\\rohka\\OneDrive\\Desktop\\ba-rfpapp\\venv\\Lib\\site-packages\\starlette\\websockets.py", line 114, in _raise_on_disconnect\n    raise WebSocketDisconnect(message["code"], message.get("reason"))\nstarlette.websockets.WebSocketDisconnect: (1012, None)\n'}
2025-08-27 11:03:10,301 - asyncio - ERROR - an error occurred during closing of asynchronous generator <async_generator object stdio_client at 0x000001FA0D741BD0>
asyncgen: <async_generator object stdio_client at 0x000001FA0D741BD0>
  + Exception Group Traceback (most recent call last):
  |   File "C:\Users\rohka\OneDrive\Desktop\ba-rfpapp\venv\Lib\site-packages\anyio\_backends\_asyncio.py", line 772, in __aexit__
  |     raise BaseExceptionGroup(
  |         "unhandled errors in a TaskGroup", self._exceptions
  |     ) from None
  | BaseExceptionGroup: unhandled errors in a TaskGroup (1 sub-exception)
  +-+---------------- 1 ----------------
    | Traceback (most recent call last):
    |   File "C:\Users\rohka\OneDrive\Desktop\ba-rfpapp\venv\Lib\site-packages\mcp\client\stdio\__init__.py", line 187, in stdio_client
    |     yield read_stream, write_stream
    | GeneratorExit
    +------------------------------------

During handling of the above exception, another exception occurred:

Traceback (most recent call last):
  File "C:\Users\rohka\AppData\Local\Programs\Python\Python313\Lib\asyncio\tasks.py", line 304, in __step_run_and_handle_result
    result = coro.send(None)
  File "C:\Users\rohka\OneDrive\Desktop\ba-rfpapp\venv\Lib\site-packages\mcp\client\stdio\__init__.py", line 181, in stdio_client
    anyio.create_task_group() as tg,
    ~~~~~~~~~~~~~~~~~~~~~~~^^
  File "C:\Users\rohka\OneDrive\Desktop\ba-rfpapp\venv\Lib\site-packages\anyio\_backends\_asyncio.py", line 778, in __aexit__
    if self.cancel_scope.__exit__(type(exc), exc, exc.__traceback__):
       ~~~~~~~~~~~~~~~~~~~~~~~~~~^^^^^^^^^^^^^^^^^^^^^^^^^^^^^^^^^^^
  File "C:\Users\rohka\OneDrive\Desktop\ba-rfpapp\venv\Lib\site-packages\anyio\_backends\_asyncio.py", line 457, in __exit__
    raise RuntimeError(
    ...<2 lines>...
    )
RuntimeError: Attempted to exit cancel scope in a different task than it was entered in
2025-08-27 11:06:08,946 - BroadAxis - ERROR - Error occurred: {'error_type': 'WebSocketDisconnect', 'message': "(1001, '')", 'context': {'session_id': None, 'operation': 'websocket_message_handling'}, 'traceback': 'Traceback (most recent call last):\n  File "C:\\Users\\rohka\\OneDrive\\Desktop\\ba-rfpapp\\backend\\websocket_api.py", line 61, in websocket_chat\n    data = await asyncio.wait_for(websocket.receive_text(), timeout=300.0)  # 5 min timeout\n           ^^^^^^^^^^^^^^^^^^^^^^^^^^^^^^^^^^^^^^^^^^^^^^^^^^^^^^^^^^^^^^^\n  File "C:\\Users\\rohka\\AppData\\Local\\Programs\\Python\\Python313\\Lib\\asyncio\\tasks.py", line 507, in wait_for\n    return await fut\n           ^^^^^^^^^\n  File "C:\\Users\\rohka\\OneDrive\\Desktop\\ba-rfpapp\\venv\\Lib\\site-packages\\starlette\\websockets.py", line 120, in receive_text\n    self._raise_on_disconnect(message)\n    ~~~~~~~~~~~~~~~~~~~~~~~~~^^^^^^^^^\n  File "C:\\Users\\rohka\\OneDrive\\Desktop\\ba-rfpapp\\venv\\Lib\\site-packages\\starlette\\websockets.py", line 114, in _raise_on_disconnect\n    raise WebSocketDisconnect(message["code"], message.get("reason"))\nstarlette.websockets.WebSocketDisconnect: (1001, \'\')\n'}
2025-08-27 11:06:48,972 - httpx - INFO - HTTP Request: POST https://api.anthropic.com/v1/messages "HTTP/1.1 200 OK"
2025-08-27 11:06:59,899 - httpx - INFO - HTTP Request: POST https://api.anthropic.com/v1/messages "HTTP/1.1 200 OK"
2025-08-27 11:07:27,818 - httpx - INFO - HTTP Request: POST https://api.anthropic.com/v1/messages "HTTP/1.1 200 OK"
2025-08-27 11:12:00,806 - httpx - INFO - HTTP Request: POST https://api.anthropic.com/v1/messages "HTTP/1.1 200 OK"
2025-08-27 11:12:17,082 - httpx - INFO - HTTP Request: POST https://api.anthropic.com/v1/messages "HTTP/1.1 200 OK"
2025-08-27 11:12:55,203 - httpx - INFO - HTTP Request: POST https://api.anthropic.com/v1/messages "HTTP/1.1 200 OK"
2025-08-27 11:14:01,419 - BroadAxis - ERROR - Error occurred: {'error_type': 'WebSocketDisconnect', 'message': '(1012, None)', 'context': {'session_id': '1756311098066', 'operation': 'websocket_message_handling'}, 'traceback': 'Traceback (most recent call last):\n  File "C:\\Users\\rohka\\OneDrive\\Desktop\\ba-rfpapp\\backend\\websocket_api.py", line 61, in websocket_chat\n    data = await asyncio.wait_for(websocket.receive_text(), timeout=300.0)  # 5 min timeout\n           ^^^^^^^^^^^^^^^^^^^^^^^^^^^^^^^^^^^^^^^^^^^^^^^^^^^^^^^^^^^^^^^\n  File "C:\\Users\\rohka\\AppData\\Local\\Programs\\Python\\Python313\\Lib\\asyncio\\tasks.py", line 507, in wait_for\n    return await fut\n           ^^^^^^^^^\n  File "C:\\Users\\rohka\\OneDrive\\Desktop\\ba-rfpapp\\venv\\Lib\\site-packages\\starlette\\websockets.py", line 120, in receive_text\n    self._raise_on_disconnect(message)\n    ~~~~~~~~~~~~~~~~~~~~~~~~~^^^^^^^^^\n  File "C:\\Users\\rohka\\OneDrive\\Desktop\\ba-rfpapp\\venv\\Lib\\site-packages\\starlette\\websockets.py", line 114, in _raise_on_disconnect\n    raise WebSocketDisconnect(message["code"], message.get("reason"))\nstarlette.websockets.WebSocketDisconnect: (1012, None)\n'}
2025-08-27 11:14:02,023 - asyncio - ERROR - an error occurred during closing of asynchronous generator <async_generator object stdio_client at 0x000001FD57D52260>
asyncgen: <async_generator object stdio_client at 0x000001FD57D52260>
  + Exception Group Traceback (most recent call last):
  |   File "C:\Users\rohka\OneDrive\Desktop\ba-rfpapp\venv\Lib\site-packages\anyio\_backends\_asyncio.py", line 772, in __aexit__
  |     raise BaseExceptionGroup(
  |         "unhandled errors in a TaskGroup", self._exceptions
  |     ) from None
  | BaseExceptionGroup: unhandled errors in a TaskGroup (1 sub-exception)
  +-+---------------- 1 ----------------
    | Traceback (most recent call last):
    |   File "C:\Users\rohka\OneDrive\Desktop\ba-rfpapp\venv\Lib\site-packages\mcp\client\stdio\__init__.py", line 187, in stdio_client
    |     yield read_stream, write_stream
    | GeneratorExit
    +------------------------------------

During handling of the above exception, another exception occurred:

Traceback (most recent call last):
  File "C:\Users\rohka\AppData\Local\Programs\Python\Python313\Lib\asyncio\tasks.py", line 304, in __step_run_and_handle_result
    result = coro.send(None)
  File "C:\Users\rohka\OneDrive\Desktop\ba-rfpapp\venv\Lib\site-packages\mcp\client\stdio\__init__.py", line 181, in stdio_client
    anyio.create_task_group() as tg,
    ~~~~~~~~~~~~~~~~~~~~~~~^^
  File "C:\Users\rohka\OneDrive\Desktop\ba-rfpapp\venv\Lib\site-packages\anyio\_backends\_asyncio.py", line 778, in __aexit__
    if self.cancel_scope.__exit__(type(exc), exc, exc.__traceback__):
       ~~~~~~~~~~~~~~~~~~~~~~~~~~^^^^^^^^^^^^^^^^^^^^^^^^^^^^^^^^^^^
  File "C:\Users\rohka\OneDrive\Desktop\ba-rfpapp\venv\Lib\site-packages\anyio\_backends\_asyncio.py", line 457, in __exit__
    raise RuntimeError(
    ...<2 lines>...
    )
RuntimeError: Attempted to exit cancel scope in a different task than it was entered in
2025-08-27 11:14:11,143 - BroadAxis - ERROR - Error occurred: {'error_type': 'WebSocketDisconnect', 'message': '(1012, None)', 'context': {'session_id': None, 'operation': 'websocket_message_handling'}, 'traceback': 'Traceback (most recent call last):\n  File "C:\\Users\\rohka\\OneDrive\\Desktop\\ba-rfpapp\\backend\\websocket_api.py", line 61, in websocket_chat\n    data = await asyncio.wait_for(websocket.receive_text(), timeout=300.0)  # 5 min timeout\n           ^^^^^^^^^^^^^^^^^^^^^^^^^^^^^^^^^^^^^^^^^^^^^^^^^^^^^^^^^^^^^^^\n  File "C:\\Users\\rohka\\AppData\\Local\\Programs\\Python\\Python313\\Lib\\asyncio\\tasks.py", line 507, in wait_for\n    return await fut\n           ^^^^^^^^^\n  File "C:\\Users\\rohka\\OneDrive\\Desktop\\ba-rfpapp\\venv\\Lib\\site-packages\\starlette\\websockets.py", line 120, in receive_text\n    self._raise_on_disconnect(message)\n    ~~~~~~~~~~~~~~~~~~~~~~~~~^^^^^^^^^\n  File "C:\\Users\\rohka\\OneDrive\\Desktop\\ba-rfpapp\\venv\\Lib\\site-packages\\starlette\\websockets.py", line 114, in _raise_on_disconnect\n    raise WebSocketDisconnect(message["code"], message.get("reason"))\nstarlette.websockets.WebSocketDisconnect: (1012, None)\n'}
2025-08-27 11:14:41,874 - BroadAxis - ERROR - Error occurred: {'error_type': 'WebSocketDisconnect', 'message': '(1012, None)', 'context': {'session_id': None, 'operation': 'websocket_message_handling'}, 'traceback': 'Traceback (most recent call last):\n  File "C:\\Users\\rohka\\OneDrive\\Desktop\\ba-rfpapp\\backend\\websocket_api.py", line 61, in websocket_chat\n    data = await asyncio.wait_for(websocket.receive_text(), timeout=300.0)  # 5 min timeout\n           ^^^^^^^^^^^^^^^^^^^^^^^^^^^^^^^^^^^^^^^^^^^^^^^^^^^^^^^^^^^^^^^\n  File "C:\\Users\\rohka\\AppData\\Local\\Programs\\Python\\Python313\\Lib\\asyncio\\tasks.py", line 507, in wait_for\n    return await fut\n           ^^^^^^^^^\n  File "C:\\Users\\rohka\\OneDrive\\Desktop\\ba-rfpapp\\venv\\Lib\\site-packages\\starlette\\websockets.py", line 120, in receive_text\n    self._raise_on_disconnect(message)\n    ~~~~~~~~~~~~~~~~~~~~~~~~~^^^^^^^^^\n  File "C:\\Users\\rohka\\OneDrive\\Desktop\\ba-rfpapp\\venv\\Lib\\site-packages\\starlette\\websockets.py", line 114, in _raise_on_disconnect\n    raise WebSocketDisconnect(message["code"], message.get("reason"))\nstarlette.websockets.WebSocketDisconnect: (1012, None)\n'}
2025-08-27 11:14:55,105 - BroadAxis - ERROR - Error occurred: {'error_type': 'WebSocketDisconnect', 'message': "(1001, '')", 'context': {'session_id': None, 'operation': 'websocket_message_handling'}, 'traceback': 'Traceback (most recent call last):\n  File "C:\\Users\\rohka\\OneDrive\\Desktop\\ba-rfpapp\\backend\\websocket_api.py", line 61, in websocket_chat\n    data = await asyncio.wait_for(websocket.receive_text(), timeout=300.0)  # 5 min timeout\n           ^^^^^^^^^^^^^^^^^^^^^^^^^^^^^^^^^^^^^^^^^^^^^^^^^^^^^^^^^^^^^^^\n  File "C:\\Users\\rohka\\AppData\\Local\\Programs\\Python\\Python313\\Lib\\asyncio\\tasks.py", line 507, in wait_for\n    return await fut\n           ^^^^^^^^^\n  File "C:\\Users\\rohka\\OneDrive\\Desktop\\ba-rfpapp\\venv\\Lib\\site-packages\\starlette\\websockets.py", line 120, in receive_text\n    self._raise_on_disconnect(message)\n    ~~~~~~~~~~~~~~~~~~~~~~~~~^^^^^^^^^\n  File "C:\\Users\\rohka\\OneDrive\\Desktop\\ba-rfpapp\\venv\\Lib\\site-packages\\starlette\\websockets.py", line 114, in _raise_on_disconnect\n    raise WebSocketDisconnect(message["code"], message.get("reason"))\nstarlette.websockets.WebSocketDisconnect: (1001, \'\')\n'}
2025-08-27 11:15:27,500 - httpx - INFO - HTTP Request: POST https://api.anthropic.com/v1/messages "HTTP/1.1 200 OK"
2025-08-27 11:15:35,909 - httpx - INFO - HTTP Request: POST https://api.anthropic.com/v1/messages "HTTP/1.1 200 OK"
2025-08-27 11:15:55,502 - httpx - INFO - HTTP Request: POST https://api.anthropic.com/v1/messages "HTTP/1.1 200 OK"
2025-08-27 11:18:01,392 - BroadAxis - ERROR - Error occurred: {'error_type': 'WebSocketDisconnect', 'message': '(1012, None)', 'context': {'session_id': '1756311311507', 'operation': 'websocket_message_handling'}, 'traceback': 'Traceback (most recent call last):\n  File "C:\\Users\\rohka\\OneDrive\\Desktop\\ba-rfpapp\\backend\\websocket_api.py", line 61, in websocket_chat\n    data = await asyncio.wait_for(websocket.receive_text(), timeout=300.0)  # 5 min timeout\n           ^^^^^^^^^^^^^^^^^^^^^^^^^^^^^^^^^^^^^^^^^^^^^^^^^^^^^^^^^^^^^^^\n  File "C:\\Users\\rohka\\AppData\\Local\\Programs\\Python\\Python313\\Lib\\asyncio\\tasks.py", line 507, in wait_for\n    return await fut\n           ^^^^^^^^^\n  File "C:\\Users\\rohka\\OneDrive\\Desktop\\ba-rfpapp\\venv\\Lib\\site-packages\\starlette\\websockets.py", line 120, in receive_text\n    self._raise_on_disconnect(message)\n    ~~~~~~~~~~~~~~~~~~~~~~~~~^^^^^^^^^\n  File "C:\\Users\\rohka\\OneDrive\\Desktop\\ba-rfpapp\\venv\\Lib\\site-packages\\starlette\\websockets.py", line 114, in _raise_on_disconnect\n    raise WebSocketDisconnect(message["code"], message.get("reason"))\nstarlette.websockets.WebSocketDisconnect: (1012, None)\n'}
2025-08-27 11:18:02,091 - asyncio - ERROR - an error occurred during closing of asynchronous generator <async_generator object stdio_client at 0x00000265C0AAE260>
asyncgen: <async_generator object stdio_client at 0x00000265C0AAE260>
  + Exception Group Traceback (most recent call last):
  |   File "C:\Users\rohka\OneDrive\Desktop\ba-rfpapp\venv\Lib\site-packages\anyio\_backends\_asyncio.py", line 772, in __aexit__
  |     raise BaseExceptionGroup(
  |         "unhandled errors in a TaskGroup", self._exceptions
  |     ) from None
  | BaseExceptionGroup: unhandled errors in a TaskGroup (1 sub-exception)
  +-+---------------- 1 ----------------
    | Traceback (most recent call last):
    |   File "C:\Users\rohka\OneDrive\Desktop\ba-rfpapp\venv\Lib\site-packages\mcp\client\stdio\__init__.py", line 187, in stdio_client
    |     yield read_stream, write_stream
    | GeneratorExit
    +------------------------------------

During handling of the above exception, another exception occurred:

Traceback (most recent call last):
  File "C:\Users\rohka\AppData\Local\Programs\Python\Python313\Lib\asyncio\tasks.py", line 304, in __step_run_and_handle_result
    result = coro.send(None)
  File "C:\Users\rohka\OneDrive\Desktop\ba-rfpapp\venv\Lib\site-packages\mcp\client\stdio\__init__.py", line 181, in stdio_client
    anyio.create_task_group() as tg,
    ~~~~~~~~~~~~~~~~~~~~~~~^^
  File "C:\Users\rohka\OneDrive\Desktop\ba-rfpapp\venv\Lib\site-packages\anyio\_backends\_asyncio.py", line 778, in __aexit__
    if self.cancel_scope.__exit__(type(exc), exc, exc.__traceback__):
       ~~~~~~~~~~~~~~~~~~~~~~~~~~^^^^^^^^^^^^^^^^^^^^^^^^^^^^^^^^^^^
  File "C:\Users\rohka\OneDrive\Desktop\ba-rfpapp\venv\Lib\site-packages\anyio\_backends\_asyncio.py", line 457, in __exit__
    raise RuntimeError(
    ...<2 lines>...
    )
RuntimeError: Attempted to exit cancel scope in a different task than it was entered in
2025-08-27 11:18:18,147 - BroadAxis - ERROR - Error occurred: {'error_type': 'WebSocketDisconnect', 'message': '(1012, None)', 'context': {'session_id': None, 'operation': 'websocket_message_handling'}, 'traceback': 'Traceback (most recent call last):\n  File "C:\\Users\\rohka\\OneDrive\\Desktop\\ba-rfpapp\\backend\\websocket_api.py", line 61, in websocket_chat\n    data = await asyncio.wait_for(websocket.receive_text(), timeout=300.0)  # 5 min timeout\n           ^^^^^^^^^^^^^^^^^^^^^^^^^^^^^^^^^^^^^^^^^^^^^^^^^^^^^^^^^^^^^^^\n  File "C:\\Users\\rohka\\AppData\\Local\\Programs\\Python\\Python313\\Lib\\asyncio\\tasks.py", line 507, in wait_for\n    return await fut\n           ^^^^^^^^^\n  File "C:\\Users\\rohka\\OneDrive\\Desktop\\ba-rfpapp\\venv\\Lib\\site-packages\\starlette\\websockets.py", line 120, in receive_text\n    self._raise_on_disconnect(message)\n    ~~~~~~~~~~~~~~~~~~~~~~~~~^^^^^^^^^\n  File "C:\\Users\\rohka\\OneDrive\\Desktop\\ba-rfpapp\\venv\\Lib\\site-packages\\starlette\\websockets.py", line 114, in _raise_on_disconnect\n    raise WebSocketDisconnect(message["code"], message.get("reason"))\nstarlette.websockets.WebSocketDisconnect: (1012, None)\n'}
2025-08-27 11:18:26,727 - BroadAxis - ERROR - Error occurred: {'error_type': 'WebSocketDisconnect', 'message': '(1012, None)', 'context': {'session_id': None, 'operation': 'websocket_message_handling'}, 'traceback': 'Traceback (most recent call last):\n  File "C:\\Users\\rohka\\OneDrive\\Desktop\\ba-rfpapp\\backend\\websocket_api.py", line 61, in websocket_chat\n    data = await asyncio.wait_for(websocket.receive_text(), timeout=300.0)  # 5 min timeout\n           ^^^^^^^^^^^^^^^^^^^^^^^^^^^^^^^^^^^^^^^^^^^^^^^^^^^^^^^^^^^^^^^\n  File "C:\\Users\\rohka\\AppData\\Local\\Programs\\Python\\Python313\\Lib\\asyncio\\tasks.py", line 507, in wait_for\n    return await fut\n           ^^^^^^^^^\n  File "C:\\Users\\rohka\\OneDrive\\Desktop\\ba-rfpapp\\venv\\Lib\\site-packages\\starlette\\websockets.py", line 120, in receive_text\n    self._raise_on_disconnect(message)\n    ~~~~~~~~~~~~~~~~~~~~~~~~~^^^^^^^^^\n  File "C:\\Users\\rohka\\OneDrive\\Desktop\\ba-rfpapp\\venv\\Lib\\site-packages\\starlette\\websockets.py", line 114, in _raise_on_disconnect\n    raise WebSocketDisconnect(message["code"], message.get("reason"))\nstarlette.websockets.WebSocketDisconnect: (1012, None)\n'}
2025-08-27 11:20:33,574 - BroadAxis - ERROR - Error occurred: {'error_type': 'WebSocketDisconnect', 'message': "(1001, '')", 'context': {'session_id': None, 'operation': 'websocket_message_handling'}, 'traceback': 'Traceback (most recent call last):\n  File "C:\\Users\\rohka\\OneDrive\\Desktop\\ba-rfpapp\\backend\\websocket_api.py", line 61, in websocket_chat\n    data = await asyncio.wait_for(websocket.receive_text(), timeout=300.0)  # 5 min timeout\n           ^^^^^^^^^^^^^^^^^^^^^^^^^^^^^^^^^^^^^^^^^^^^^^^^^^^^^^^^^^^^^^^\n  File "C:\\Users\\rohka\\AppData\\Local\\Programs\\Python\\Python313\\Lib\\asyncio\\tasks.py", line 507, in wait_for\n    return await fut\n           ^^^^^^^^^\n  File "C:\\Users\\rohka\\OneDrive\\Desktop\\ba-rfpapp\\venv\\Lib\\site-packages\\starlette\\websockets.py", line 120, in receive_text\n    self._raise_on_disconnect(message)\n    ~~~~~~~~~~~~~~~~~~~~~~~~~^^^^^^^^^\n  File "C:\\Users\\rohka\\OneDrive\\Desktop\\ba-rfpapp\\venv\\Lib\\site-packages\\starlette\\websockets.py", line 114, in _raise_on_disconnect\n    raise WebSocketDisconnect(message["code"], message.get("reason"))\nstarlette.websockets.WebSocketDisconnect: (1001, \'\')\n'}
2025-08-27 11:29:49,484 - httpx - INFO - HTTP Request: POST https://api.anthropic.com/v1/messages "HTTP/1.1 200 OK"
2025-08-27 11:30:00,451 - httpx - INFO - HTTP Request: POST https://api.anthropic.com/v1/messages "HTTP/1.1 200 OK"
2025-08-27 11:30:24,208 - httpx - INFO - HTTP Request: POST https://api.anthropic.com/v1/messages "HTTP/1.1 200 OK"
2025-08-27 11:32:21,091 - BroadAxis - ERROR - Error occurred: {'error_type': 'WebSocketDisconnect', 'message': '(1012, None)', 'context': {'session_id': 'd658fa52-3fa2-4893-9fbe-2a2113e3bcd2', 'operation': 'websocket_message_handling'}, 'traceback': 'Traceback (most recent call last):\n  File "C:\\Users\\rohka\\OneDrive\\Desktop\\ba-rfpapp\\backend\\websocket_api.py", line 61, in websocket_chat\n    data = await asyncio.wait_for(websocket.receive_text(), timeout=300.0)  # 5 min timeout\n           ^^^^^^^^^^^^^^^^^^^^^^^^^^^^^^^^^^^^^^^^^^^^^^^^^^^^^^^^^^^^^^^\n  File "C:\\Users\\rohka\\AppData\\Local\\Programs\\Python\\Python313\\Lib\\asyncio\\tasks.py", line 507, in wait_for\n    return await fut\n           ^^^^^^^^^\n  File "C:\\Users\\rohka\\OneDrive\\Desktop\\ba-rfpapp\\venv\\Lib\\site-packages\\starlette\\websockets.py", line 120, in receive_text\n    self._raise_on_disconnect(message)\n    ~~~~~~~~~~~~~~~~~~~~~~~~~^^^^^^^^^\n  File "C:\\Users\\rohka\\OneDrive\\Desktop\\ba-rfpapp\\venv\\Lib\\site-packages\\starlette\\websockets.py", line 114, in _raise_on_disconnect\n    raise WebSocketDisconnect(message["code"], message.get("reason"))\nstarlette.websockets.WebSocketDisconnect: (1012, None)\n'}
2025-08-27 11:32:21,746 - asyncio - ERROR - an error occurred during closing of asynchronous generator <async_generator object stdio_client at 0x00000241CBD59A80>
asyncgen: <async_generator object stdio_client at 0x00000241CBD59A80>
  + Exception Group Traceback (most recent call last):
  |   File "C:\Users\rohka\OneDrive\Desktop\ba-rfpapp\venv\Lib\site-packages\anyio\_backends\_asyncio.py", line 772, in __aexit__
  |     raise BaseExceptionGroup(
  |         "unhandled errors in a TaskGroup", self._exceptions
  |     ) from None
  | BaseExceptionGroup: unhandled errors in a TaskGroup (1 sub-exception)
  +-+---------------- 1 ----------------
    | Traceback (most recent call last):
    |   File "C:\Users\rohka\OneDrive\Desktop\ba-rfpapp\venv\Lib\site-packages\mcp\client\stdio\__init__.py", line 187, in stdio_client
    |     yield read_stream, write_stream
    | GeneratorExit
    +------------------------------------

During handling of the above exception, another exception occurred:

Traceback (most recent call last):
  File "C:\Users\rohka\AppData\Local\Programs\Python\Python313\Lib\asyncio\tasks.py", line 304, in __step_run_and_handle_result
    result = coro.send(None)
  File "C:\Users\rohka\OneDrive\Desktop\ba-rfpapp\venv\Lib\site-packages\mcp\client\stdio\__init__.py", line 181, in stdio_client
    anyio.create_task_group() as tg,
    ~~~~~~~~~~~~~~~~~~~~~~~^^
  File "C:\Users\rohka\OneDrive\Desktop\ba-rfpapp\venv\Lib\site-packages\anyio\_backends\_asyncio.py", line 778, in __aexit__
    if self.cancel_scope.__exit__(type(exc), exc, exc.__traceback__):
       ~~~~~~~~~~~~~~~~~~~~~~~~~~^^^^^^^^^^^^^^^^^^^^^^^^^^^^^^^^^^^
  File "C:\Users\rohka\OneDrive\Desktop\ba-rfpapp\venv\Lib\site-packages\anyio\_backends\_asyncio.py", line 457, in __exit__
    raise RuntimeError(
    ...<2 lines>...
    )
RuntimeError: Attempted to exit cancel scope in a different task than it was entered in
2025-08-27 11:33:56,599 - httpx - INFO - HTTP Request: POST https://api.anthropic.com/v1/messages "HTTP/1.1 200 OK"
2025-08-27 11:34:10,176 - httpx - INFO - HTTP Request: POST https://api.anthropic.com/v1/messages "HTTP/1.1 200 OK"
2025-08-27 11:34:26,894 - httpx - INFO - HTTP Request: POST https://api.anthropic.com/v1/messages "HTTP/1.1 200 OK"
2025-08-27 11:35:08,088 - BroadAxis - ERROR - Error occurred: {'error_type': 'WebSocketDisconnect', 'message': '(1012, None)', 'context': {'session_id': 'e3173a18-22f2-4406-9246-3afc3ea850be', 'operation': 'websocket_message_handling'}, 'traceback': 'Traceback (most recent call last):\n  File "C:\\Users\\rohka\\OneDrive\\Desktop\\ba-rfpapp\\backend\\websocket_api.py", line 61, in websocket_chat\n    data = await asyncio.wait_for(websocket.receive_text(), timeout=300.0)  # 5 min timeout\n           ^^^^^^^^^^^^^^^^^^^^^^^^^^^^^^^^^^^^^^^^^^^^^^^^^^^^^^^^^^^^^^^\n  File "C:\\Users\\rohka\\AppData\\Local\\Programs\\Python\\Python313\\Lib\\asyncio\\tasks.py", line 507, in wait_for\n    return await fut\n           ^^^^^^^^^\n  File "C:\\Users\\rohka\\OneDrive\\Desktop\\ba-rfpapp\\venv\\Lib\\site-packages\\starlette\\websockets.py", line 120, in receive_text\n    self._raise_on_disconnect(message)\n    ~~~~~~~~~~~~~~~~~~~~~~~~~^^^^^^^^^\n  File "C:\\Users\\rohka\\OneDrive\\Desktop\\ba-rfpapp\\venv\\Lib\\site-packages\\starlette\\websockets.py", line 114, in _raise_on_disconnect\n    raise WebSocketDisconnect(message["code"], message.get("reason"))\nstarlette.websockets.WebSocketDisconnect: (1012, None)\n'}
2025-08-27 11:35:08,638 - asyncio - ERROR - an error occurred during closing of asynchronous generator <async_generator object stdio_client at 0x000002227B968190>
asyncgen: <async_generator object stdio_client at 0x000002227B968190>
  + Exception Group Traceback (most recent call last):
  |   File "C:\Users\rohka\OneDrive\Desktop\ba-rfpapp\venv\Lib\site-packages\anyio\_backends\_asyncio.py", line 772, in __aexit__
  |     raise BaseExceptionGroup(
  |         "unhandled errors in a TaskGroup", self._exceptions
  |     ) from None
  | BaseExceptionGroup: unhandled errors in a TaskGroup (1 sub-exception)
  +-+---------------- 1 ----------------
    | Traceback (most recent call last):
    |   File "C:\Users\rohka\OneDrive\Desktop\ba-rfpapp\venv\Lib\site-packages\mcp\client\stdio\__init__.py", line 187, in stdio_client
    |     yield read_stream, write_stream
    | GeneratorExit
    +------------------------------------

During handling of the above exception, another exception occurred:

Traceback (most recent call last):
  File "C:\Users\rohka\AppData\Local\Programs\Python\Python313\Lib\asyncio\tasks.py", line 304, in __step_run_and_handle_result
    result = coro.send(None)
  File "C:\Users\rohka\OneDrive\Desktop\ba-rfpapp\venv\Lib\site-packages\mcp\client\stdio\__init__.py", line 181, in stdio_client
    anyio.create_task_group() as tg,
    ~~~~~~~~~~~~~~~~~~~~~~~^^
  File "C:\Users\rohka\OneDrive\Desktop\ba-rfpapp\venv\Lib\site-packages\anyio\_backends\_asyncio.py", line 778, in __aexit__
    if self.cancel_scope.__exit__(type(exc), exc, exc.__traceback__):
       ~~~~~~~~~~~~~~~~~~~~~~~~~~^^^^^^^^^^^^^^^^^^^^^^^^^^^^^^^^^^^
  File "C:\Users\rohka\OneDrive\Desktop\ba-rfpapp\venv\Lib\site-packages\anyio\_backends\_asyncio.py", line 457, in __exit__
    raise RuntimeError(
    ...<2 lines>...
    )
RuntimeError: Attempted to exit cancel scope in a different task than it was entered in
2025-08-27 11:35:24,362 - BroadAxis - ERROR - Error occurred: {'error_type': 'WebSocketDisconnect', 'message': '(1012, None)', 'context': {'session_id': None, 'operation': 'websocket_message_handling'}, 'traceback': 'Traceback (most recent call last):\n  File "C:\\Users\\rohka\\OneDrive\\Desktop\\ba-rfpapp\\backend\\websocket_api.py", line 61, in websocket_chat\n    data = await asyncio.wait_for(websocket.receive_text(), timeout=300.0)  # 5 min timeout\n           ^^^^^^^^^^^^^^^^^^^^^^^^^^^^^^^^^^^^^^^^^^^^^^^^^^^^^^^^^^^^^^^\n  File "C:\\Users\\rohka\\AppData\\Local\\Programs\\Python\\Python313\\Lib\\asyncio\\tasks.py", line 507, in wait_for\n    return await fut\n           ^^^^^^^^^\n  File "C:\\Users\\rohka\\OneDrive\\Desktop\\ba-rfpapp\\venv\\Lib\\site-packages\\starlette\\websockets.py", line 120, in receive_text\n    self._raise_on_disconnect(message)\n    ~~~~~~~~~~~~~~~~~~~~~~~~~^^^^^^^^^\n  File "C:\\Users\\rohka\\OneDrive\\Desktop\\ba-rfpapp\\venv\\Lib\\site-packages\\starlette\\websockets.py", line 114, in _raise_on_disconnect\n    raise WebSocketDisconnect(message["code"], message.get("reason"))\nstarlette.websockets.WebSocketDisconnect: (1012, None)\n'}
2025-08-27 11:35:34,811 - BroadAxis - ERROR - Error occurred: {'error_type': 'WebSocketDisconnect', 'message': '(1012, None)', 'context': {'session_id': None, 'operation': 'websocket_message_handling'}, 'traceback': 'Traceback (most recent call last):\n  File "C:\\Users\\rohka\\OneDrive\\Desktop\\ba-rfpapp\\backend\\websocket_api.py", line 61, in websocket_chat\n    data = await asyncio.wait_for(websocket.receive_text(), timeout=300.0)  # 5 min timeout\n           ^^^^^^^^^^^^^^^^^^^^^^^^^^^^^^^^^^^^^^^^^^^^^^^^^^^^^^^^^^^^^^^\n  File "C:\\Users\\rohka\\AppData\\Local\\Programs\\Python\\Python313\\Lib\\asyncio\\tasks.py", line 507, in wait_for\n    return await fut\n           ^^^^^^^^^\n  File "C:\\Users\\rohka\\OneDrive\\Desktop\\ba-rfpapp\\venv\\Lib\\site-packages\\starlette\\websockets.py", line 120, in receive_text\n    self._raise_on_disconnect(message)\n    ~~~~~~~~~~~~~~~~~~~~~~~~~^^^^^^^^^\n  File "C:\\Users\\rohka\\OneDrive\\Desktop\\ba-rfpapp\\venv\\Lib\\site-packages\\starlette\\websockets.py", line 114, in _raise_on_disconnect\n    raise WebSocketDisconnect(message["code"], message.get("reason"))\nstarlette.websockets.WebSocketDisconnect: (1012, None)\n'}
2025-08-27 11:35:43,598 - BroadAxis - ERROR - Error occurred: {'error_type': 'WebSocketDisconnect', 'message': '(1012, None)', 'context': {'session_id': None, 'operation': 'websocket_message_handling'}, 'traceback': 'Traceback (most recent call last):\n  File "C:\\Users\\rohka\\OneDrive\\Desktop\\ba-rfpapp\\backend\\websocket_api.py", line 61, in websocket_chat\n    data = await asyncio.wait_for(websocket.receive_text(), timeout=300.0)  # 5 min timeout\n           ^^^^^^^^^^^^^^^^^^^^^^^^^^^^^^^^^^^^^^^^^^^^^^^^^^^^^^^^^^^^^^^\n  File "C:\\Users\\rohka\\AppData\\Local\\Programs\\Python\\Python313\\Lib\\asyncio\\tasks.py", line 507, in wait_for\n    return await fut\n           ^^^^^^^^^\n  File "C:\\Users\\rohka\\OneDrive\\Desktop\\ba-rfpapp\\venv\\Lib\\site-packages\\starlette\\websockets.py", line 120, in receive_text\n    self._raise_on_disconnect(message)\n    ~~~~~~~~~~~~~~~~~~~~~~~~~^^^^^^^^^\n  File "C:\\Users\\rohka\\OneDrive\\Desktop\\ba-rfpapp\\venv\\Lib\\site-packages\\starlette\\websockets.py", line 114, in _raise_on_disconnect\n    raise WebSocketDisconnect(message["code"], message.get("reason"))\nstarlette.websockets.WebSocketDisconnect: (1012, None)\n'}
2025-08-27 11:35:52,350 - BroadAxis - ERROR - Error occurred: {'error_type': 'WebSocketDisconnect', 'message': "(1001, '')", 'context': {'session_id': None, 'operation': 'websocket_message_handling'}, 'traceback': 'Traceback (most recent call last):\n  File "C:\\Users\\rohka\\OneDrive\\Desktop\\ba-rfpapp\\backend\\websocket_api.py", line 61, in websocket_chat\n    data = await asyncio.wait_for(websocket.receive_text(), timeout=300.0)  # 5 min timeout\n           ^^^^^^^^^^^^^^^^^^^^^^^^^^^^^^^^^^^^^^^^^^^^^^^^^^^^^^^^^^^^^^^\n  File "C:\\Users\\rohka\\AppData\\Local\\Programs\\Python\\Python313\\Lib\\asyncio\\tasks.py", line 507, in wait_for\n    return await fut\n           ^^^^^^^^^\n  File "C:\\Users\\rohka\\OneDrive\\Desktop\\ba-rfpapp\\venv\\Lib\\site-packages\\starlette\\websockets.py", line 120, in receive_text\n    self._raise_on_disconnect(message)\n    ~~~~~~~~~~~~~~~~~~~~~~~~~^^^^^^^^^\n  File "C:\\Users\\rohka\\OneDrive\\Desktop\\ba-rfpapp\\venv\\Lib\\site-packages\\starlette\\websockets.py", line 114, in _raise_on_disconnect\n    raise WebSocketDisconnect(message["code"], message.get("reason"))\nstarlette.websockets.WebSocketDisconnect: (1001, \'\')\n'}
2025-08-27 11:36:11,472 - httpx - INFO - HTTP Request: POST https://api.anthropic.com/v1/messages "HTTP/1.1 200 OK"
2025-08-27 11:36:21,475 - httpx - INFO - HTTP Request: POST https://api.anthropic.com/v1/messages "HTTP/1.1 200 OK"
2025-08-27 11:36:45,168 - httpx - INFO - HTTP Request: POST https://api.anthropic.com/v1/messages "HTTP/1.1 200 OK"
2025-08-27 11:38:55,404 - httpx - INFO - HTTP Request: POST https://api.anthropic.com/v1/messages "HTTP/1.1 200 OK"
2025-08-27 11:39:05,343 - httpx - INFO - HTTP Request: POST https://api.anthropic.com/v1/messages "HTTP/1.1 200 OK"
2025-08-27 11:39:27,984 - httpx - INFO - HTTP Request: POST https://api.anthropic.com/v1/messages "HTTP/1.1 200 OK"
2025-08-27 11:44:10,542 - httpx - INFO - HTTP Request: POST https://api.anthropic.com/v1/messages "HTTP/1.1 200 OK"
2025-08-27 11:44:14,375 - httpx - INFO - HTTP Request: POST https://api.anthropic.com/v1/messages "HTTP/1.1 200 OK"
2025-08-27 11:44:32,389 - httpx - INFO - HTTP Request: POST https://api.anthropic.com/v1/messages "HTTP/1.1 200 OK"
2025-08-27 11:44:48,649 - httpx - INFO - HTTP Request: POST https://api.anthropic.com/v1/messages "HTTP/1.1 200 OK"
2025-08-27 11:44:55,969 - httpx - INFO - HTTP Request: POST https://api.anthropic.com/v1/messages "HTTP/1.1 200 OK"
2025-08-27 11:45:01,346 - httpx - INFO - HTTP Request: POST https://api.anthropic.com/v1/messages "HTTP/1.1 200 OK"
2025-08-27 11:45:01,915 - httpx - INFO - HTTP Request: POST https://api.anthropic.com/v1/messages "HTTP/1.1 429 Too Many Requests"
2025-08-27 11:45:01,916 - anthropic._base_client - INFO - Retrying request to /v1/messages in 17.000000 seconds
2025-08-27 11:45:43,035 - httpx - INFO - HTTP Request: POST https://api.anthropic.com/v1/messages "HTTP/1.1 200 OK"
2025-08-27 11:46:01,737 - httpx - INFO - HTTP Request: POST https://api.anthropic.com/v1/messages "HTTP/1.1 200 OK"
2025-08-27 11:46:04,445 - httpx - INFO - HTTP Request: POST https://api.anthropic.com/v1/messages "HTTP/1.1 429 Too Many Requests"
2025-08-27 11:46:04,450 - anthropic._base_client - INFO - Retrying request to /v1/messages in 22.000000 seconds
2025-08-27 11:46:36,470 - httpx - INFO - HTTP Request: POST https://api.anthropic.com/v1/messages "HTTP/1.1 200 OK"
2025-08-27 11:54:11,635 - httpx - INFO - HTTP Request: POST https://api.anthropic.com/v1/messages "HTTP/1.1 200 OK"
2025-08-27 11:54:15,993 - httpx - INFO - HTTP Request: POST https://api.anthropic.com/v1/messages "HTTP/1.1 200 OK"
2025-08-27 11:54:31,699 - httpx - INFO - HTTP Request: POST https://api.anthropic.com/v1/messages "HTTP/1.1 200 OK"
2025-08-27 11:55:04,321 - httpx - INFO - HTTP Request: POST https://api.anthropic.com/v1/messages "HTTP/1.1 200 OK"
2025-08-27 11:55:07,896 - httpx - INFO - HTTP Request: POST https://api.anthropic.com/v1/messages "HTTP/1.1 200 OK"
2025-08-27 11:55:30,874 - httpx - INFO - HTTP Request: POST https://api.anthropic.com/v1/messages "HTTP/1.1 200 OK"
2025-08-27 11:55:42,397 - httpx - INFO - HTTP Request: POST https://api.anthropic.com/v1/messages "HTTP/1.1 429 Too Many Requests"
2025-08-27 11:55:42,399 - anthropic._base_client - INFO - Retrying request to /v1/messages in 28.000000 seconds
2025-08-27 11:56:13,233 - httpx - INFO - HTTP Request: POST https://api.anthropic.com/v1/messages "HTTP/1.1 200 OK"
2025-08-27 11:56:18,345 - httpx - INFO - HTTP Request: POST https://api.anthropic.com/v1/messages "HTTP/1.1 200 OK"
2025-08-27 11:56:19,919 - httpx - INFO - HTTP Request: POST https://api.anthropic.com/v1/messages "HTTP/1.1 429 Too Many Requests"
2025-08-27 11:56:19,922 - anthropic._base_client - INFO - Retrying request to /v1/messages in 20.000000 seconds
2025-08-27 11:56:45,045 - httpx - INFO - HTTP Request: POST https://api.anthropic.com/v1/messages "HTTP/1.1 200 OK"
2025-08-27 11:56:48,733 - httpx - INFO - HTTP Request: POST https://api.anthropic.com/v1/messages "HTTP/1.1 429 Too Many Requests"
2025-08-27 11:56:48,735 - anthropic._base_client - INFO - Retrying request to /v1/messages in 12.000000 seconds
2025-08-27 11:57:28,475 - httpx - INFO - HTTP Request: POST https://api.anthropic.com/v1/messages "HTTP/1.1 200 OK"
2025-08-27 11:57:45,361 - httpx - INFO - HTTP Request: POST https://api.anthropic.com/v1/messages "HTTP/1.1 200 OK"
2025-08-27 11:57:50,105 - httpx - INFO - HTTP Request: POST https://api.anthropic.com/v1/messages "HTTP/1.1 429 Too Many Requests"
2025-08-27 11:57:50,111 - anthropic._base_client - INFO - Retrying request to /v1/messages in 14.000000 seconds
2025-08-27 11:58:13,529 - httpx - INFO - HTTP Request: POST https://api.anthropic.com/v1/messages "HTTP/1.1 200 OK"
2025-08-27 12:03:43,553 - BroadAxis - ERROR - Error occurred: {'error_type': 'WebSocketDisconnect', 'message': "(1001, '')", 'context': {'session_id': '957a8e76-7d81-4267-912e-01ee2f1dcec8', 'operation': 'websocket_message_handling'}, 'traceback': 'Traceback (most recent call last):\n  File "C:\\Users\\rohka\\OneDrive\\Desktop\\ba-rfpapp\\backend\\websocket_api.py", line 61, in websocket_chat\n    data = await asyncio.wait_for(websocket.receive_text(), timeout=300.0)  # 5 min timeout\n           ^^^^^^^^^^^^^^^^^^^^^^^^^^^^^^^^^^^^^^^^^^^^^^^^^^^^^^^^^^^^^^^\n  File "C:\\Users\\rohka\\AppData\\Local\\Programs\\Python\\Python313\\Lib\\asyncio\\tasks.py", line 507, in wait_for\n    return await fut\n           ^^^^^^^^^\n  File "C:\\Users\\rohka\\OneDrive\\Desktop\\ba-rfpapp\\venv\\Lib\\site-packages\\starlette\\websockets.py", line 120, in receive_text\n    self._raise_on_disconnect(message)\n    ~~~~~~~~~~~~~~~~~~~~~~~~~^^^^^^^^^\n  File "C:\\Users\\rohka\\OneDrive\\Desktop\\ba-rfpapp\\venv\\Lib\\site-packages\\starlette\\websockets.py", line 114, in _raise_on_disconnect\n    raise WebSocketDisconnect(message["code"], message.get("reason"))\nstarlette.websockets.WebSocketDisconnect: (1001, \'\')\n'}
2025-08-27 12:04:10,671 - httpx - INFO - HTTP Request: POST https://api.anthropic.com/v1/messages "HTTP/1.1 200 OK"
2025-08-27 12:04:27,423 - httpx - INFO - HTTP Request: POST https://api.anthropic.com/v1/messages "HTTP/1.1 529 "
2025-08-27 12:04:27,437 - anthropic._base_client - INFO - Retrying request to /v1/messages in 0.451831 seconds
2025-08-27 12:04:32,490 - httpx - INFO - HTTP Request: POST https://api.anthropic.com/v1/messages "HTTP/1.1 200 OK"
2025-08-27 12:04:54,445 - httpx - INFO - HTTP Request: POST https://api.anthropic.com/v1/messages "HTTP/1.1 200 OK"
2025-08-27 12:05:07,501 - httpx - INFO - HTTP Request: POST https://api.anthropic.com/v1/messages "HTTP/1.1 200 OK"
2025-08-27 12:05:15,058 - httpx - INFO - HTTP Request: POST https://api.anthropic.com/v1/messages "HTTP/1.1 200 OK"
2025-08-27 12:05:15,971 - httpx - INFO - HTTP Request: POST https://api.anthropic.com/v1/messages "HTTP/1.1 429 Too Many Requests"
2025-08-27 12:05:15,972 - anthropic._base_client - INFO - Retrying request to /v1/messages in 11.000000 seconds
2025-08-27 12:05:31,569 - httpx - INFO - HTTP Request: POST https://api.anthropic.com/v1/messages "HTTP/1.1 200 OK"
2025-08-27 12:05:32,394 - httpx - INFO - HTTP Request: POST https://api.anthropic.com/v1/messages "HTTP/1.1 429 Too Many Requests"
2025-08-27 12:05:32,395 - anthropic._base_client - INFO - Retrying request to /v1/messages in 14.000000 seconds
2025-08-27 12:06:03,356 - httpx - INFO - HTTP Request: POST https://api.anthropic.com/v1/messages "HTTP/1.1 200 OK"
2025-08-27 12:10:54,845 - httpx - INFO - HTTP Request: POST https://api.anthropic.com/v1/messages "HTTP/1.1 200 OK"
2025-08-27 12:11:01,466 - httpx - INFO - HTTP Request: POST https://api.anthropic.com/v1/messages "HTTP/1.1 200 OK"
2025-08-27 12:11:20,039 - httpx - INFO - HTTP Request: POST https://api.anthropic.com/v1/messages "HTTP/1.1 200 OK"
2025-08-27 12:11:20,285 - BroadAxis - ERROR - Error occurred: {'error_type': 'WebSocketDisconnect', 'message': '', 'context': {'operation': 'websocket_send_message'}, 'traceback': 'Traceback (most recent call last):\n  File "C:\\Users\\rohka\\OneDrive\\Desktop\\ba-rfpapp\\venv\\Lib\\site-packages\\websockets\\legacy\\protocol.py", line 1279, in close_connection\n    await self.transfer_data_task\n  File "C:\\Users\\rohka\\AppData\\Local\\Programs\\Python\\Python313\\Lib\\asyncio\\futures.py", line 286, in __await__\n    yield self  # This tells Task to wait for completion.\n    ^^^^^^^^^^\n  File "C:\\Users\\rohka\\AppData\\Local\\Programs\\Python\\Python313\\Lib\\asyncio\\tasks.py", line 375, in __wakeup\n    future.result()\n    ~~~~~~~~~~~~~^^\n  File "C:\\Users\\rohka\\AppData\\Local\\Programs\\Python\\Python313\\Lib\\asyncio\\futures.py", line 194, in result\n    raise self._make_cancelled_error()\n  File "C:\\Users\\rohka\\AppData\\Local\\Programs\\Python\\Python313\\Lib\\asyncio\\tasks.py", line 306, in __step_run_and_handle_result\n    result = coro.throw(exc)\n  File "C:\\Users\\rohka\\OneDrive\\Desktop\\ba-rfpapp\\venv\\Lib\\site-packages\\websockets\\legacy\\protocol.py", line 945, in transfer_data\n    message = await self.read_message()\n              ^^^^^^^^^^^^^^^^^^^^^^^^^\n  File "C:\\Users\\rohka\\OneDrive\\Desktop\\ba-rfpapp\\venv\\Lib\\site-packages\\websockets\\legacy\\protocol.py", line 1015, in read_message\n    frame = await self.read_data_frame(max_size=self.max_size)\n            ^^^^^^^^^^^^^^^^^^^^^^^^^^^^^^^^^^^^^^^^^^^^^^^^^^\n  File "C:\\Users\\rohka\\OneDrive\\Desktop\\ba-rfpapp\\venv\\Lib\\site-packages\\websockets\\legacy\\protocol.py", line 1090, in read_data_frame\n    frame = await self.read_frame(max_size)\n            ^^^^^^^^^^^^^^^^^^^^^^^^^^^^^^^\n  File "C:\\Users\\rohka\\OneDrive\\Desktop\\ba-rfpapp\\venv\\Lib\\site-packages\\websockets\\legacy\\protocol.py", line 1147, in read_frame\n    frame = await Frame.read(\n            ^^^^^^^^^^^^^^^^^\n    ...<4 lines>...\n    )\n    ^\n  File "C:\\Users\\rohka\\OneDrive\\Desktop\\ba-rfpapp\\venv\\Lib\\site-packages\\websockets\\legacy\\framing.py", line 71, in read\n    data = await reader(2)\n           ^^^^^^^^^^^^^^^\n  File "C:\\Users\\rohka\\AppData\\Local\\Programs\\Python\\Python313\\Lib\\asyncio\\streams.py", line 769, in readexactly\n    await self._wait_for_data(\'readexactly\')\n  File "C:\\Users\\rohka\\AppData\\Local\\Programs\\Python\\Python313\\Lib\\asyncio\\streams.py", line 539, in _wait_for_data\n    await self._waiter\n  File "C:\\Users\\rohka\\AppData\\Local\\Programs\\Python\\Python313\\Lib\\asyncio\\futures.py", line 286, in __await__\n    yield self  # This tells Task to wait for completion.\n    ^^^^^^^^^^\n  File "C:\\Users\\rohka\\AppData\\Local\\Programs\\Python\\Python313\\Lib\\asyncio\\tasks.py", line 375, in __wakeup\n    future.result()\n    ~~~~~~~~~~~~~^^\n  File "C:\\Users\\rohka\\AppData\\Local\\Programs\\Python\\Python313\\Lib\\asyncio\\futures.py", line 194, in result\n    raise self._make_cancelled_error()\nasyncio.exceptions.CancelledError\n\nThe above exception was the direct cause of the following exception:\n\nTraceback (most recent call last):\n  File "C:\\Users\\rohka\\OneDrive\\Desktop\\ba-rfpapp\\venv\\Lib\\site-packages\\uvicorn\\protocols\\websockets\\websockets_impl.py", line 332, in asgi_send\n    await self.send(data)  # type: ignore[arg-type]\n    ^^^^^^^^^^^^^^^^^^^^^\n  File "C:\\Users\\rohka\\OneDrive\\Desktop\\ba-rfpapp\\venv\\Lib\\site-packages\\websockets\\legacy\\protocol.py", line 620, in send\n    await self.ensure_open()\n  File "C:\\Users\\rohka\\OneDrive\\Desktop\\ba-rfpapp\\venv\\Lib\\site-packages\\websockets\\legacy\\protocol.py", line 921, in ensure_open\n    raise self.connection_closed_exc()\nwebsockets.exceptions.ConnectionClosedError: sent 1012 (service restart); no close frame received\n\nThe above exception was the direct cause of the following exception:\n\nTraceback (most recent call last):\n  File "C:\\Users\\rohka\\OneDrive\\Desktop\\ba-rfpapp\\venv\\Lib\\site-packages\\starlette\\websockets.py", line 86, in send\n    await self._send(message)\n  File "C:\\Users\\rohka\\OneDrive\\Desktop\\ba-rfpapp\\venv\\Lib\\site-packages\\starlette\\_exception_handler.py", line 39, in sender\n    await send(message)\n  File "C:\\Users\\rohka\\OneDrive\\Desktop\\ba-rfpapp\\venv\\Lib\\site-packages\\uvicorn\\protocols\\websockets\\websockets_impl.py", line 345, in asgi_send\n    raise ClientDisconnected from exc\nuvicorn.protocols.utils.ClientDisconnected\n\nDuring handling of the above exception, another exception occurred:\n\nTraceback (most recent call last):\n  File "C:\\Users\\rohka\\OneDrive\\Desktop\\ba-rfpapp\\backend\\websocket_api.py", line 39, in send_personal_message\n    await websocket.send_text(message)\n  File "C:\\Users\\rohka\\OneDrive\\Desktop\\ba-rfpapp\\venv\\Lib\\site-packages\\starlette\\websockets.py", line 166, in send_text\n    await self.send({"type": "websocket.send", "text": data})\n  File "C:\\Users\\rohka\\OneDrive\\Desktop\\ba-rfpapp\\venv\\Lib\\site-packages\\starlette\\websockets.py", line 89, in send\n    raise WebSocketDisconnect(code=1006)\nstarlette.websockets.WebSocketDisconnect\n'}
2025-08-27 12:11:20,291 - BroadAxis - ERROR - Error occurred: {'error_type': 'WebSocketDisconnect', 'message': '', 'context': {'session_id': '0d5c9947-ecf1-454f-aab1-aafbfee4350b', 'query_length': 179}, 'traceback': 'Traceback (most recent call last):\n  File "C:\\Users\\rohka\\OneDrive\\Desktop\\ba-rfpapp\\venv\\Lib\\site-packages\\websockets\\legacy\\protocol.py", line 1279, in close_connection\n    await self.transfer_data_task\n  File "C:\\Users\\rohka\\AppData\\Local\\Programs\\Python\\Python313\\Lib\\asyncio\\futures.py", line 286, in __await__\n    yield self  # This tells Task to wait for completion.\n    ^^^^^^^^^^\n  File "C:\\Users\\rohka\\AppData\\Local\\Programs\\Python\\Python313\\Lib\\asyncio\\tasks.py", line 375, in __wakeup\n    future.result()\n    ~~~~~~~~~~~~~^^\n  File "C:\\Users\\rohka\\AppData\\Local\\Programs\\Python\\Python313\\Lib\\asyncio\\futures.py", line 194, in result\n    raise self._make_cancelled_error()\n  File "C:\\Users\\rohka\\AppData\\Local\\Programs\\Python\\Python313\\Lib\\asyncio\\tasks.py", line 306, in __step_run_and_handle_result\n    result = coro.throw(exc)\n  File "C:\\Users\\rohka\\OneDrive\\Desktop\\ba-rfpapp\\venv\\Lib\\site-packages\\websockets\\legacy\\protocol.py", line 945, in transfer_data\n    message = await self.read_message()\n              ^^^^^^^^^^^^^^^^^^^^^^^^^\n  File "C:\\Users\\rohka\\OneDrive\\Desktop\\ba-rfpapp\\venv\\Lib\\site-packages\\websockets\\legacy\\protocol.py", line 1015, in read_message\n    frame = await self.read_data_frame(max_size=self.max_size)\n            ^^^^^^^^^^^^^^^^^^^^^^^^^^^^^^^^^^^^^^^^^^^^^^^^^^\n  File "C:\\Users\\rohka\\OneDrive\\Desktop\\ba-rfpapp\\venv\\Lib\\site-packages\\websockets\\legacy\\protocol.py", line 1090, in read_data_frame\n    frame = await self.read_frame(max_size)\n            ^^^^^^^^^^^^^^^^^^^^^^^^^^^^^^^\n  File "C:\\Users\\rohka\\OneDrive\\Desktop\\ba-rfpapp\\venv\\Lib\\site-packages\\websockets\\legacy\\protocol.py", line 1147, in read_frame\n    frame = await Frame.read(\n            ^^^^^^^^^^^^^^^^^\n    ...<4 lines>...\n    )\n    ^\n  File "C:\\Users\\rohka\\OneDrive\\Desktop\\ba-rfpapp\\venv\\Lib\\site-packages\\websockets\\legacy\\framing.py", line 71, in read\n    data = await reader(2)\n           ^^^^^^^^^^^^^^^\n  File "C:\\Users\\rohka\\AppData\\Local\\Programs\\Python\\Python313\\Lib\\asyncio\\streams.py", line 769, in readexactly\n    await self._wait_for_data(\'readexactly\')\n  File "C:\\Users\\rohka\\AppData\\Local\\Programs\\Python\\Python313\\Lib\\asyncio\\streams.py", line 539, in _wait_for_data\n    await self._waiter\n  File "C:\\Users\\rohka\\AppData\\Local\\Programs\\Python\\Python313\\Lib\\asyncio\\futures.py", line 286, in __await__\n    yield self  # This tells Task to wait for completion.\n    ^^^^^^^^^^\n  File "C:\\Users\\rohka\\AppData\\Local\\Programs\\Python\\Python313\\Lib\\asyncio\\tasks.py", line 375, in __wakeup\n    future.result()\n    ~~~~~~~~~~~~~^^\n  File "C:\\Users\\rohka\\AppData\\Local\\Programs\\Python\\Python313\\Lib\\asyncio\\futures.py", line 194, in result\n    raise self._make_cancelled_error()\nasyncio.exceptions.CancelledError\n\nThe above exception was the direct cause of the following exception:\n\nTraceback (most recent call last):\n  File "C:\\Users\\rohka\\OneDrive\\Desktop\\ba-rfpapp\\venv\\Lib\\site-packages\\uvicorn\\protocols\\websockets\\websockets_impl.py", line 332, in asgi_send\n    await self.send(data)  # type: ignore[arg-type]\n    ^^^^^^^^^^^^^^^^^^^^^\n  File "C:\\Users\\rohka\\OneDrive\\Desktop\\ba-rfpapp\\venv\\Lib\\site-packages\\websockets\\legacy\\protocol.py", line 620, in send\n    await self.ensure_open()\n  File "C:\\Users\\rohka\\OneDrive\\Desktop\\ba-rfpapp\\venv\\Lib\\site-packages\\websockets\\legacy\\protocol.py", line 921, in ensure_open\n    raise self.connection_closed_exc()\nwebsockets.exceptions.ConnectionClosedError: sent 1012 (service restart); no close frame received\n\nThe above exception was the direct cause of the following exception:\n\nTraceback (most recent call last):\n  File "C:\\Users\\rohka\\OneDrive\\Desktop\\ba-rfpapp\\venv\\Lib\\site-packages\\starlette\\websockets.py", line 86, in send\n    await self._send(message)\n  File "C:\\Users\\rohka\\OneDrive\\Desktop\\ba-rfpapp\\venv\\Lib\\site-packages\\starlette\\_exception_handler.py", line 39, in sender\n    await send(message)\n  File "C:\\Users\\rohka\\OneDrive\\Desktop\\ba-rfpapp\\venv\\Lib\\site-packages\\uvicorn\\protocols\\websockets\\websockets_impl.py", line 345, in asgi_send\n    raise ClientDisconnected from exc\nuvicorn.protocols.utils.ClientDisconnected\n\nDuring handling of the above exception, another exception occurred:\n\nTraceback (most recent call last):\n  File "C:\\Users\\rohka\\OneDrive\\Desktop\\ba-rfpapp\\backend\\websocket_api.py", line 224, in websocket_chat\n    await manager.send_personal_message(\n    ...<8 lines>...\n    )\n  File "C:\\Users\\rohka\\OneDrive\\Desktop\\ba-rfpapp\\backend\\websocket_api.py", line 39, in send_personal_message\n    await websocket.send_text(message)\n  File "C:\\Users\\rohka\\OneDrive\\Desktop\\ba-rfpapp\\venv\\Lib\\site-packages\\starlette\\websockets.py", line 166, in send_text\n    await self.send({"type": "websocket.send", "text": data})\n  File "C:\\Users\\rohka\\OneDrive\\Desktop\\ba-rfpapp\\venv\\Lib\\site-packages\\starlette\\websockets.py", line 89, in send\n    raise WebSocketDisconnect(code=1006)\nstarlette.websockets.WebSocketDisconnect\n'}
2025-08-27 12:11:20,297 - BroadAxis - ERROR - Error occurred: {'error_type': 'RuntimeError', 'message': 'Cannot call "send" once a close message has been sent.', 'context': {'operation': 'websocket_send_message'}, 'traceback': 'Traceback (most recent call last):\n  File "C:\\Users\\rohka\\OneDrive\\Desktop\\ba-rfpapp\\venv\\Lib\\site-packages\\websockets\\legacy\\protocol.py", line 1279, in close_connection\n    await self.transfer_data_task\n  File "C:\\Users\\rohka\\AppData\\Local\\Programs\\Python\\Python313\\Lib\\asyncio\\futures.py", line 286, in __await__\n    yield self  # This tells Task to wait for completion.\n    ^^^^^^^^^^\n  File "C:\\Users\\rohka\\AppData\\Local\\Programs\\Python\\Python313\\Lib\\asyncio\\tasks.py", line 375, in __wakeup\n    future.result()\n    ~~~~~~~~~~~~~^^\n  File "C:\\Users\\rohka\\AppData\\Local\\Programs\\Python\\Python313\\Lib\\asyncio\\futures.py", line 194, in result\n    raise self._make_cancelled_error()\n  File "C:\\Users\\rohka\\AppData\\Local\\Programs\\Python\\Python313\\Lib\\asyncio\\tasks.py", line 306, in __step_run_and_handle_result\n    result = coro.throw(exc)\n  File "C:\\Users\\rohka\\OneDrive\\Desktop\\ba-rfpapp\\venv\\Lib\\site-packages\\websockets\\legacy\\protocol.py", line 945, in transfer_data\n    message = await self.read_message()\n              ^^^^^^^^^^^^^^^^^^^^^^^^^\n  File "C:\\Users\\rohka\\OneDrive\\Desktop\\ba-rfpapp\\venv\\Lib\\site-packages\\websockets\\legacy\\protocol.py", line 1015, in read_message\n    frame = await self.read_data_frame(max_size=self.max_size)\n            ^^^^^^^^^^^^^^^^^^^^^^^^^^^^^^^^^^^^^^^^^^^^^^^^^^\n  File "C:\\Users\\rohka\\OneDrive\\Desktop\\ba-rfpapp\\venv\\Lib\\site-packages\\websockets\\legacy\\protocol.py", line 1090, in read_data_frame\n    frame = await self.read_frame(max_size)\n            ^^^^^^^^^^^^^^^^^^^^^^^^^^^^^^^\n  File "C:\\Users\\rohka\\OneDrive\\Desktop\\ba-rfpapp\\venv\\Lib\\site-packages\\websockets\\legacy\\protocol.py", line 1147, in read_frame\n    frame = await Frame.read(\n            ^^^^^^^^^^^^^^^^^\n    ...<4 lines>...\n    )\n    ^\n  File "C:\\Users\\rohka\\OneDrive\\Desktop\\ba-rfpapp\\venv\\Lib\\site-packages\\websockets\\legacy\\framing.py", line 71, in read\n    data = await reader(2)\n           ^^^^^^^^^^^^^^^\n  File "C:\\Users\\rohka\\AppData\\Local\\Programs\\Python\\Python313\\Lib\\asyncio\\streams.py", line 769, in readexactly\n    await self._wait_for_data(\'readexactly\')\n  File "C:\\Users\\rohka\\AppData\\Local\\Programs\\Python\\Python313\\Lib\\asyncio\\streams.py", line 539, in _wait_for_data\n    await self._waiter\n  File "C:\\Users\\rohka\\AppData\\Local\\Programs\\Python\\Python313\\Lib\\asyncio\\futures.py", line 286, in __await__\n    yield self  # This tells Task to wait for completion.\n    ^^^^^^^^^^\n  File "C:\\Users\\rohka\\AppData\\Local\\Programs\\Python\\Python313\\Lib\\asyncio\\tasks.py", line 375, in __wakeup\n    future.result()\n    ~~~~~~~~~~~~~^^\n  File "C:\\Users\\rohka\\AppData\\Local\\Programs\\Python\\Python313\\Lib\\asyncio\\futures.py", line 194, in result\n    raise self._make_cancelled_error()\nasyncio.exceptions.CancelledError\n\nThe above exception was the direct cause of the following exception:\n\nTraceback (most recent call last):\n  File "C:\\Users\\rohka\\OneDrive\\Desktop\\ba-rfpapp\\venv\\Lib\\site-packages\\uvicorn\\protocols\\websockets\\websockets_impl.py", line 332, in asgi_send\n    await self.send(data)  # type: ignore[arg-type]\n    ^^^^^^^^^^^^^^^^^^^^^\n  File "C:\\Users\\rohka\\OneDrive\\Desktop\\ba-rfpapp\\venv\\Lib\\site-packages\\websockets\\legacy\\protocol.py", line 620, in send\n    await self.ensure_open()\n  File "C:\\Users\\rohka\\OneDrive\\Desktop\\ba-rfpapp\\venv\\Lib\\site-packages\\websockets\\legacy\\protocol.py", line 921, in ensure_open\n    raise self.connection_closed_exc()\nwebsockets.exceptions.ConnectionClosedError: sent 1012 (service restart); no close frame received\n\nThe above exception was the direct cause of the following exception:\n\nTraceback (most recent call last):\n  File "C:\\Users\\rohka\\OneDrive\\Desktop\\ba-rfpapp\\venv\\Lib\\site-packages\\starlette\\websockets.py", line 86, in send\n    await self._send(message)\n  File "C:\\Users\\rohka\\OneDrive\\Desktop\\ba-rfpapp\\venv\\Lib\\site-packages\\starlette\\_exception_handler.py", line 39, in sender\n    await send(message)\n  File "C:\\Users\\rohka\\OneDrive\\Desktop\\ba-rfpapp\\venv\\Lib\\site-packages\\uvicorn\\protocols\\websockets\\websockets_impl.py", line 345, in asgi_send\n    raise ClientDisconnected from exc\nuvicorn.protocols.utils.ClientDisconnected\n\nDuring handling of the above exception, another exception occurred:\n\nTraceback (most recent call last):\n  File "C:\\Users\\rohka\\OneDrive\\Desktop\\ba-rfpapp\\backend\\websocket_api.py", line 224, in websocket_chat\n    await manager.send_personal_message(\n    ...<8 lines>...\n    )\n  File "C:\\Users\\rohka\\OneDrive\\Desktop\\ba-rfpapp\\backend\\websocket_api.py", line 39, in send_personal_message\n    await websocket.send_text(message)\n  File "C:\\Users\\rohka\\OneDrive\\Desktop\\ba-rfpapp\\venv\\Lib\\site-packages\\starlette\\websockets.py", line 166, in send_text\n    await self.send({"type": "websocket.send", "text": data})\n  File "C:\\Users\\rohka\\OneDrive\\Desktop\\ba-rfpapp\\venv\\Lib\\site-packages\\starlette\\websockets.py", line 89, in send\n    raise WebSocketDisconnect(code=1006)\nstarlette.websockets.WebSocketDisconnect\n\nDuring handling of the above exception, another exception occurred:\n\nTraceback (most recent call last):\n  File "C:\\Users\\rohka\\OneDrive\\Desktop\\ba-rfpapp\\backend\\websocket_api.py", line 39, in send_personal_message\n    await websocket.send_text(message)\n  File "C:\\Users\\rohka\\OneDrive\\Desktop\\ba-rfpapp\\venv\\Lib\\site-packages\\starlette\\websockets.py", line 166, in send_text\n    await self.send({"type": "websocket.send", "text": data})\n  File "C:\\Users\\rohka\\OneDrive\\Desktop\\ba-rfpapp\\venv\\Lib\\site-packages\\starlette\\websockets.py", line 98, in send\n    raise RuntimeError(\'Cannot call "send" once a close message has been sent.\')\nRuntimeError: Cannot call "send" once a close message has been sent.\n'}
2025-08-27 12:11:20,302 - BroadAxis - ERROR - Error occurred: {'error_type': 'RuntimeError', 'message': 'Cannot call "send" once a close message has been sent.', 'context': {'session_id': '0d5c9947-ecf1-454f-aab1-aafbfee4350b', 'operation': 'websocket_message_handling'}, 'traceback': 'Traceback (most recent call last):\n  File "C:\\Users\\rohka\\OneDrive\\Desktop\\ba-rfpapp\\venv\\Lib\\site-packages\\websockets\\legacy\\protocol.py", line 1279, in close_connection\n    await self.transfer_data_task\n  File "C:\\Users\\rohka\\AppData\\Local\\Programs\\Python\\Python313\\Lib\\asyncio\\futures.py", line 286, in __await__\n    yield self  # This tells Task to wait for completion.\n    ^^^^^^^^^^\n  File "C:\\Users\\rohka\\AppData\\Local\\Programs\\Python\\Python313\\Lib\\asyncio\\tasks.py", line 375, in __wakeup\n    future.result()\n    ~~~~~~~~~~~~~^^\n  File "C:\\Users\\rohka\\AppData\\Local\\Programs\\Python\\Python313\\Lib\\asyncio\\futures.py", line 194, in result\n    raise self._make_cancelled_error()\n  File "C:\\Users\\rohka\\AppData\\Local\\Programs\\Python\\Python313\\Lib\\asyncio\\tasks.py", line 306, in __step_run_and_handle_result\n    result = coro.throw(exc)\n  File "C:\\Users\\rohka\\OneDrive\\Desktop\\ba-rfpapp\\venv\\Lib\\site-packages\\websockets\\legacy\\protocol.py", line 945, in transfer_data\n    message = await self.read_message()\n              ^^^^^^^^^^^^^^^^^^^^^^^^^\n  File "C:\\Users\\rohka\\OneDrive\\Desktop\\ba-rfpapp\\venv\\Lib\\site-packages\\websockets\\legacy\\protocol.py", line 1015, in read_message\n    frame = await self.read_data_frame(max_size=self.max_size)\n            ^^^^^^^^^^^^^^^^^^^^^^^^^^^^^^^^^^^^^^^^^^^^^^^^^^\n  File "C:\\Users\\rohka\\OneDrive\\Desktop\\ba-rfpapp\\venv\\Lib\\site-packages\\websockets\\legacy\\protocol.py", line 1090, in read_data_frame\n    frame = await self.read_frame(max_size)\n            ^^^^^^^^^^^^^^^^^^^^^^^^^^^^^^^\n  File "C:\\Users\\rohka\\OneDrive\\Desktop\\ba-rfpapp\\venv\\Lib\\site-packages\\websockets\\legacy\\protocol.py", line 1147, in read_frame\n    frame = await Frame.read(\n            ^^^^^^^^^^^^^^^^^\n    ...<4 lines>...\n    )\n    ^\n  File "C:\\Users\\rohka\\OneDrive\\Desktop\\ba-rfpapp\\venv\\Lib\\site-packages\\websockets\\legacy\\framing.py", line 71, in read\n    data = await reader(2)\n           ^^^^^^^^^^^^^^^\n  File "C:\\Users\\rohka\\AppData\\Local\\Programs\\Python\\Python313\\Lib\\asyncio\\streams.py", line 769, in readexactly\n    await self._wait_for_data(\'readexactly\')\n  File "C:\\Users\\rohka\\AppData\\Local\\Programs\\Python\\Python313\\Lib\\asyncio\\streams.py", line 539, in _wait_for_data\n    await self._waiter\n  File "C:\\Users\\rohka\\AppData\\Local\\Programs\\Python\\Python313\\Lib\\asyncio\\futures.py", line 286, in __await__\n    yield self  # This tells Task to wait for completion.\n    ^^^^^^^^^^\n  File "C:\\Users\\rohka\\AppData\\Local\\Programs\\Python\\Python313\\Lib\\asyncio\\tasks.py", line 375, in __wakeup\n    future.result()\n    ~~~~~~~~~~~~~^^\n  File "C:\\Users\\rohka\\AppData\\Local\\Programs\\Python\\Python313\\Lib\\asyncio\\futures.py", line 194, in result\n    raise self._make_cancelled_error()\nasyncio.exceptions.CancelledError\n\nThe above exception was the direct cause of the following exception:\n\nTraceback (most recent call last):\n  File "C:\\Users\\rohka\\OneDrive\\Desktop\\ba-rfpapp\\venv\\Lib\\site-packages\\uvicorn\\protocols\\websockets\\websockets_impl.py", line 332, in asgi_send\n    await self.send(data)  # type: ignore[arg-type]\n    ^^^^^^^^^^^^^^^^^^^^^\n  File "C:\\Users\\rohka\\OneDrive\\Desktop\\ba-rfpapp\\venv\\Lib\\site-packages\\websockets\\legacy\\protocol.py", line 620, in send\n    await self.ensure_open()\n  File "C:\\Users\\rohka\\OneDrive\\Desktop\\ba-rfpapp\\venv\\Lib\\site-packages\\websockets\\legacy\\protocol.py", line 921, in ensure_open\n    raise self.connection_closed_exc()\nwebsockets.exceptions.ConnectionClosedError: sent 1012 (service restart); no close frame received\n\nThe above exception was the direct cause of the following exception:\n\nTraceback (most recent call last):\n  File "C:\\Users\\rohka\\OneDrive\\Desktop\\ba-rfpapp\\venv\\Lib\\site-packages\\starlette\\websockets.py", line 86, in send\n    await self._send(message)\n  File "C:\\Users\\rohka\\OneDrive\\Desktop\\ba-rfpapp\\venv\\Lib\\site-packages\\starlette\\_exception_handler.py", line 39, in sender\n    await send(message)\n  File "C:\\Users\\rohka\\OneDrive\\Desktop\\ba-rfpapp\\venv\\Lib\\site-packages\\uvicorn\\protocols\\websockets\\websockets_impl.py", line 345, in asgi_send\n    raise ClientDisconnected from exc\nuvicorn.protocols.utils.ClientDisconnected\n\nDuring handling of the above exception, another exception occurred:\n\nTraceback (most recent call last):\n  File "C:\\Users\\rohka\\OneDrive\\Desktop\\ba-rfpapp\\backend\\websocket_api.py", line 224, in websocket_chat\n    await manager.send_personal_message(\n    ...<8 lines>...\n    )\n  File "C:\\Users\\rohka\\OneDrive\\Desktop\\ba-rfpapp\\backend\\websocket_api.py", line 39, in send_personal_message\n    await websocket.send_text(message)\n  File "C:\\Users\\rohka\\OneDrive\\Desktop\\ba-rfpapp\\venv\\Lib\\site-packages\\starlette\\websockets.py", line 166, in send_text\n    await self.send({"type": "websocket.send", "text": data})\n  File "C:\\Users\\rohka\\OneDrive\\Desktop\\ba-rfpapp\\venv\\Lib\\site-packages\\starlette\\websockets.py", line 89, in send\n    raise WebSocketDisconnect(code=1006)\nstarlette.websockets.WebSocketDisconnect\n\nDuring handling of the above exception, another exception occurred:\n\nTraceback (most recent call last):\n  File "C:\\Users\\rohka\\OneDrive\\Desktop\\ba-rfpapp\\backend\\websocket_api.py", line 259, in websocket_chat\n    await manager.send_personal_message(\n    ...<6 lines>...\n    )\n  File "C:\\Users\\rohka\\OneDrive\\Desktop\\ba-rfpapp\\backend\\websocket_api.py", line 39, in send_personal_message\n    await websocket.send_text(message)\n  File "C:\\Users\\rohka\\OneDrive\\Desktop\\ba-rfpapp\\venv\\Lib\\site-packages\\starlette\\websockets.py", line 166, in send_text\n    await self.send({"type": "websocket.send", "text": data})\n  File "C:\\Users\\rohka\\OneDrive\\Desktop\\ba-rfpapp\\venv\\Lib\\site-packages\\starlette\\websockets.py", line 98, in send\n    raise RuntimeError(\'Cannot call "send" once a close message has been sent.\')\nRuntimeError: Cannot call "send" once a close message has been sent.\n'}
2025-08-27 12:11:21,355 - asyncio - ERROR - an error occurred during closing of asynchronous generator <async_generator object stdio_client at 0x0000016C79999A80>
asyncgen: <async_generator object stdio_client at 0x0000016C79999A80>
  + Exception Group Traceback (most recent call last):
  |   File "C:\Users\rohka\OneDrive\Desktop\ba-rfpapp\venv\Lib\site-packages\anyio\_backends\_asyncio.py", line 772, in __aexit__
  |     raise BaseExceptionGroup(
  |         "unhandled errors in a TaskGroup", self._exceptions
  |     ) from None
  | BaseExceptionGroup: unhandled errors in a TaskGroup (1 sub-exception)
  +-+---------------- 1 ----------------
    | Traceback (most recent call last):
    |   File "C:\Users\rohka\OneDrive\Desktop\ba-rfpapp\venv\Lib\site-packages\mcp\client\stdio\__init__.py", line 187, in stdio_client
    |     yield read_stream, write_stream
    | GeneratorExit
    +------------------------------------

During handling of the above exception, another exception occurred:

Traceback (most recent call last):
  File "C:\Users\rohka\AppData\Local\Programs\Python\Python313\Lib\asyncio\tasks.py", line 304, in __step_run_and_handle_result
    result = coro.send(None)
  File "C:\Users\rohka\OneDrive\Desktop\ba-rfpapp\venv\Lib\site-packages\mcp\client\stdio\__init__.py", line 181, in stdio_client
    anyio.create_task_group() as tg,
    ~~~~~~~~~~~~~~~~~~~~~~~^^
  File "C:\Users\rohka\OneDrive\Desktop\ba-rfpapp\venv\Lib\site-packages\anyio\_backends\_asyncio.py", line 778, in __aexit__
    if self.cancel_scope.__exit__(type(exc), exc, exc.__traceback__):
       ~~~~~~~~~~~~~~~~~~~~~~~~~~^^^^^^^^^^^^^^^^^^^^^^^^^^^^^^^^^^^
  File "C:\Users\rohka\OneDrive\Desktop\ba-rfpapp\venv\Lib\site-packages\anyio\_backends\_asyncio.py", line 457, in __exit__
    raise RuntimeError(
    ...<2 lines>...
    )
RuntimeError: Attempted to exit cancel scope in a different task than it was entered in
2025-08-27 12:18:18,979 - httpx - INFO - HTTP Request: POST https://api.anthropic.com/v1/messages "HTTP/1.1 200 OK"
2025-08-27 12:18:23,453 - httpx - INFO - HTTP Request: POST https://api.anthropic.com/v1/messages "HTTP/1.1 200 OK"
2025-08-27 12:18:44,492 - httpx - INFO - HTTP Request: POST https://api.anthropic.com/v1/messages "HTTP/1.1 200 OK"
2025-08-27 12:18:52,271 - httpx - INFO - HTTP Request: POST https://api.anthropic.com/v1/messages "HTTP/1.1 429 Too Many Requests"
2025-08-27 12:18:52,275 - anthropic._base_client - INFO - Retrying request to /v1/messages in 9.000000 seconds
2025-08-27 12:19:29,750 - httpx - INFO - HTTP Request: POST https://api.anthropic.com/v1/messages "HTTP/1.1 529 "
2025-08-27 12:19:29,751 - anthropic._base_client - INFO - Retrying request to /v1/messages in 0.942404 seconds
2025-08-27 12:19:32,973 - httpx - INFO - HTTP Request: POST https://api.anthropic.com/v1/messages "HTTP/1.1 200 OK"
2025-08-27 12:19:36,064 - httpx - INFO - HTTP Request: POST https://api.anthropic.com/v1/messages "HTTP/1.1 200 OK"
2025-08-27 12:19:56,897 - httpx - INFO - HTTP Request: POST https://api.anthropic.com/v1/messages "HTTP/1.1 200 OK"
2025-08-27 12:20:12,136 - httpx - INFO - HTTP Request: POST https://api.anthropic.com/v1/messages "HTTP/1.1 429 Too Many Requests"
2025-08-27 12:20:12,137 - anthropic._base_client - INFO - Retrying request to /v1/messages in 30.000000 seconds
2025-08-27 12:20:47,437 - httpx - INFO - HTTP Request: POST https://api.anthropic.com/v1/messages "HTTP/1.1 200 OK"
2025-08-27 12:20:51,842 - httpx - INFO - HTTP Request: POST https://api.anthropic.com/v1/messages "HTTP/1.1 200 OK"
2025-08-27 12:20:52,868 - httpx - INFO - HTTP Request: POST https://api.anthropic.com/v1/messages "HTTP/1.1 429 Too Many Requests"
2025-08-27 12:20:52,869 - anthropic._base_client - INFO - Retrying request to /v1/messages in 13.000000 seconds
2025-08-27 12:21:07,874 - httpx - INFO - HTTP Request: POST https://api.anthropic.com/v1/messages "HTTP/1.1 200 OK"
2025-08-27 12:21:09,036 - httpx - INFO - HTTP Request: POST https://api.anthropic.com/v1/messages "HTTP/1.1 429 Too Many Requests"
2025-08-27 12:21:09,039 - anthropic._base_client - INFO - Retrying request to /v1/messages in 11.000000 seconds
2025-08-27 12:21:24,023 - httpx - INFO - HTTP Request: POST https://api.anthropic.com/v1/messages "HTTP/1.1 200 OK"
2025-08-27 12:21:26,712 - httpx - INFO - HTTP Request: POST https://api.anthropic.com/v1/messages "HTTP/1.1 429 Too Many Requests"
2025-08-27 12:21:26,715 - anthropic._base_client - INFO - Retrying request to /v1/messages in 10.000000 seconds
2025-08-27 12:21:41,634 - httpx - INFO - HTTP Request: POST https://api.anthropic.com/v1/messages "HTTP/1.1 200 OK"
2025-08-27 12:21:43,749 - httpx - INFO - HTTP Request: POST https://api.anthropic.com/v1/messages "HTTP/1.1 429 Too Many Requests"
2025-08-27 12:21:43,750 - anthropic._base_client - INFO - Retrying request to /v1/messages in 0.482300 seconds
2025-08-27 12:21:44,444 - httpx - INFO - HTTP Request: POST https://api.anthropic.com/v1/messages "HTTP/1.1 429 Too Many Requests"
2025-08-27 12:21:44,445 - anthropic._base_client - INFO - Retrying request to /v1/messages in 0.993946 seconds
2025-08-27 12:21:45,633 - httpx - INFO - HTTP Request: POST https://api.anthropic.com/v1/messages "HTTP/1.1 429 Too Many Requests"
2025-08-27 12:26:43,042 - BroadAxis - ERROR - Error occurred: {'error_type': 'WebSocketDisconnect', 'message': '(1012, None)', 'context': {'session_id': '56c54731-f9d0-486d-ae0f-366eee073882', 'operation': 'websocket_message_handling'}, 'traceback': 'Traceback (most recent call last):\n  File "C:\\Users\\rohka\\OneDrive\\Desktop\\ba-rfpapp\\backend\\websocket_api.py", line 61, in websocket_chat\n    data = await asyncio.wait_for(websocket.receive_text(), timeout=300.0)  # 5 min timeout\n           ^^^^^^^^^^^^^^^^^^^^^^^^^^^^^^^^^^^^^^^^^^^^^^^^^^^^^^^^^^^^^^^\n  File "C:\\Users\\rohka\\AppData\\Local\\Programs\\Python\\Python313\\Lib\\asyncio\\tasks.py", line 507, in wait_for\n    return await fut\n           ^^^^^^^^^\n  File "C:\\Users\\rohka\\OneDrive\\Desktop\\ba-rfpapp\\venv\\Lib\\site-packages\\starlette\\websockets.py", line 120, in receive_text\n    self._raise_on_disconnect(message)\n    ~~~~~~~~~~~~~~~~~~~~~~~~~^^^^^^^^^\n  File "C:\\Users\\rohka\\OneDrive\\Desktop\\ba-rfpapp\\venv\\Lib\\site-packages\\starlette\\websockets.py", line 114, in _raise_on_disconnect\n    raise WebSocketDisconnect(message["code"], message.get("reason"))\nstarlette.websockets.WebSocketDisconnect: (1012, None)\n'}
2025-08-27 12:26:44,004 - asyncio - ERROR - an error occurred during closing of asynchronous generator <async_generator object stdio_client at 0x00000233DBB29A80>
asyncgen: <async_generator object stdio_client at 0x00000233DBB29A80>
  + Exception Group Traceback (most recent call last):
  |   File "C:\Users\rohka\OneDrive\Desktop\ba-rfpapp\venv\Lib\site-packages\anyio\_backends\_asyncio.py", line 772, in __aexit__
  |     raise BaseExceptionGroup(
  |         "unhandled errors in a TaskGroup", self._exceptions
  |     ) from None
  | BaseExceptionGroup: unhandled errors in a TaskGroup (1 sub-exception)
  +-+---------------- 1 ----------------
    | Traceback (most recent call last):
    |   File "C:\Users\rohka\OneDrive\Desktop\ba-rfpapp\venv\Lib\site-packages\mcp\client\stdio\__init__.py", line 187, in stdio_client
    |     yield read_stream, write_stream
    | GeneratorExit
    +------------------------------------

During handling of the above exception, another exception occurred:

Traceback (most recent call last):
  File "C:\Users\rohka\AppData\Local\Programs\Python\Python313\Lib\asyncio\tasks.py", line 304, in __step_run_and_handle_result
    result = coro.send(None)
  File "C:\Users\rohka\OneDrive\Desktop\ba-rfpapp\venv\Lib\site-packages\mcp\client\stdio\__init__.py", line 181, in stdio_client
    anyio.create_task_group() as tg,
    ~~~~~~~~~~~~~~~~~~~~~~~^^
  File "C:\Users\rohka\OneDrive\Desktop\ba-rfpapp\venv\Lib\site-packages\anyio\_backends\_asyncio.py", line 778, in __aexit__
    if self.cancel_scope.__exit__(type(exc), exc, exc.__traceback__):
       ~~~~~~~~~~~~~~~~~~~~~~~~~~^^^^^^^^^^^^^^^^^^^^^^^^^^^^^^^^^^^
  File "C:\Users\rohka\OneDrive\Desktop\ba-rfpapp\venv\Lib\site-packages\anyio\_backends\_asyncio.py", line 457, in __exit__
    raise RuntimeError(
    ...<2 lines>...
    )
RuntimeError: Attempted to exit cancel scope in a different task than it was entered in
2025-08-27 12:28:05,757 - httpx - INFO - HTTP Request: POST https://api.anthropic.com/v1/messages "HTTP/1.1 200 OK"
2025-08-27 12:28:10,567 - httpx - INFO - HTTP Request: POST https://api.anthropic.com/v1/messages "HTTP/1.1 200 OK"
2025-08-27 12:28:34,028 - httpx - INFO - HTTP Request: POST https://api.anthropic.com/v1/messages "HTTP/1.1 200 OK"
2025-08-27 12:28:39,877 - httpx - INFO - HTTP Request: POST https://api.anthropic.com/v1/messages "HTTP/1.1 429 Too Many Requests"
2025-08-27 12:28:39,881 - anthropic._base_client - INFO - Retrying request to /v1/messages in 9.000000 seconds
2025-08-27 12:28:53,318 - httpx - INFO - HTTP Request: POST https://api.anthropic.com/v1/messages "HTTP/1.1 200 OK"
2025-08-27 12:28:56,599 - httpx - INFO - HTTP Request: POST https://api.anthropic.com/v1/messages "HTTP/1.1 200 OK"
2025-08-27 12:28:57,621 - httpx - INFO - HTTP Request: POST https://api.anthropic.com/v1/messages "HTTP/1.1 429 Too Many Requests"
2025-08-27 12:28:57,622 - anthropic._base_client - INFO - Retrying request to /v1/messages in 13.000000 seconds
2025-08-27 12:29:14,127 - httpx - INFO - HTTP Request: POST https://api.anthropic.com/v1/messages "HTTP/1.1 200 OK"
2025-08-27 12:29:16,942 - httpx - INFO - HTTP Request: POST https://api.anthropic.com/v1/messages "HTTP/1.1 429 Too Many Requests"
2025-08-27 12:29:16,945 - anthropic._base_client - INFO - Retrying request to /v1/messages in 8.000000 seconds
2025-08-27 12:29:29,147 - httpx - INFO - HTTP Request: POST https://api.anthropic.com/v1/messages "HTTP/1.1 200 OK"
2025-08-27 12:29:31,688 - httpx - INFO - HTTP Request: POST https://api.anthropic.com/v1/messages "HTTP/1.1 429 Too Many Requests"
2025-08-27 12:29:31,690 - anthropic._base_client - INFO - Retrying request to /v1/messages in 0.415570 seconds
2025-08-27 12:29:32,307 - httpx - INFO - HTTP Request: POST https://api.anthropic.com/v1/messages "HTTP/1.1 429 Too Many Requests"
2025-08-27 12:29:32,310 - anthropic._base_client - INFO - Retrying request to /v1/messages in 0.797820 seconds
2025-08-27 12:29:33,324 - httpx - INFO - HTTP Request: POST https://api.anthropic.com/v1/messages "HTTP/1.1 429 Too Many Requests"
2025-08-27 12:35:46,644 - httpx - INFO - HTTP Request: POST https://api.anthropic.com/v1/messages "HTTP/1.1 200 OK"
2025-08-27 12:35:50,464 - httpx - INFO - HTTP Request: POST https://api.anthropic.com/v1/messages "HTTP/1.1 200 OK"
2025-08-27 12:38:55,095 - BroadAxis - ERROR - Error occurred: {'error_type': 'WebSocketDisconnect', 'message': "(1001, '')", 'context': {'session_id': None, 'operation': 'websocket_message_handling'}, 'traceback': 'Traceback (most recent call last):\n  File "C:\\Users\\rohka\\OneDrive\\Desktop\\ba-rfpapp\\backend\\websocket_api.py", line 61, in websocket_chat\n    data = await asyncio.wait_for(websocket.receive_text(), timeout=300.0)  # 5 min timeout\n           ^^^^^^^^^^^^^^^^^^^^^^^^^^^^^^^^^^^^^^^^^^^^^^^^^^^^^^^^^^^^^^^\n  File "C:\\Users\\rohka\\AppData\\Local\\Programs\\Python\\Python313\\Lib\\asyncio\\tasks.py", line 507, in wait_for\n    return await fut\n           ^^^^^^^^^\n  File "C:\\Users\\rohka\\OneDrive\\Desktop\\ba-rfpapp\\venv\\Lib\\site-packages\\starlette\\websockets.py", line 120, in receive_text\n    self._raise_on_disconnect(message)\n    ~~~~~~~~~~~~~~~~~~~~~~~~~^^^^^^^^^\n  File "C:\\Users\\rohka\\OneDrive\\Desktop\\ba-rfpapp\\venv\\Lib\\site-packages\\starlette\\websockets.py", line 114, in _raise_on_disconnect\n    raise WebSocketDisconnect(message["code"], message.get("reason"))\nstarlette.websockets.WebSocketDisconnect: (1001, \'\')\n'}
2025-08-27 12:38:55,099 - BroadAxis - ERROR - Error occurred: {'error_type': 'WebSocketDisconnect', 'message': "(1001, '')", 'context': {'session_id': '9b58a0e8-b40b-488c-ba95-ac5e81989ef7', 'operation': 'websocket_message_handling'}, 'traceback': 'Traceback (most recent call last):\n  File "C:\\Users\\rohka\\OneDrive\\Desktop\\ba-rfpapp\\backend\\websocket_api.py", line 61, in websocket_chat\n    data = await asyncio.wait_for(websocket.receive_text(), timeout=300.0)  # 5 min timeout\n           ^^^^^^^^^^^^^^^^^^^^^^^^^^^^^^^^^^^^^^^^^^^^^^^^^^^^^^^^^^^^^^^\n  File "C:\\Users\\rohka\\AppData\\Local\\Programs\\Python\\Python313\\Lib\\asyncio\\tasks.py", line 507, in wait_for\n    return await fut\n           ^^^^^^^^^\n  File "C:\\Users\\rohka\\OneDrive\\Desktop\\ba-rfpapp\\venv\\Lib\\site-packages\\starlette\\websockets.py", line 120, in receive_text\n    self._raise_on_disconnect(message)\n    ~~~~~~~~~~~~~~~~~~~~~~~~~^^^^^^^^^\n  File "C:\\Users\\rohka\\OneDrive\\Desktop\\ba-rfpapp\\venv\\Lib\\site-packages\\starlette\\websockets.py", line 114, in _raise_on_disconnect\n    raise WebSocketDisconnect(message["code"], message.get("reason"))\nstarlette.websockets.WebSocketDisconnect: (1001, \'\')\n'}
2025-08-27 12:40:42,781 - httpx - INFO - HTTP Request: POST https://api.anthropic.com/v1/messages "HTTP/1.1 200 OK"
2025-08-27 12:40:46,464 - httpx - INFO - HTTP Request: POST https://api.anthropic.com/v1/messages "HTTP/1.1 200 OK"
2025-08-27 12:41:07,341 - httpx - INFO - HTTP Request: POST https://api.anthropic.com/v1/messages "HTTP/1.1 200 OK"
2025-08-27 13:00:26,063 - httpx - INFO - HTTP Request: POST https://api.anthropic.com/v1/messages "HTTP/1.1 200 OK"
2025-08-27 13:00:33,713 - httpx - INFO - HTTP Request: POST https://api.anthropic.com/v1/messages "HTTP/1.1 200 OK"
2025-08-27 13:00:56,469 - httpx - INFO - HTTP Request: POST https://api.anthropic.com/v1/messages "HTTP/1.1 200 OK"
2025-08-27 13:19:25,919 - BroadAxis - ERROR - Error occurred: {'error_type': 'WebSocketDisconnect', 'message': "(<CloseCode.ABNORMAL_CLOSURE: 1006>, '')", 'context': {'session_id': None, 'operation': 'websocket_message_handling'}, 'traceback': 'Traceback (most recent call last):\n  File "C:\\Users\\rohka\\OneDrive\\Desktop\\ba-rfpapp\\backend\\websocket_api.py", line 61, in websocket_chat\n    data = await asyncio.wait_for(websocket.receive_text(), timeout=300.0)  # 5 min timeout\n           ^^^^^^^^^^^^^^^^^^^^^^^^^^^^^^^^^^^^^^^^^^^^^^^^^^^^^^^^^^^^^^^\n  File "C:\\Users\\rohka\\AppData\\Local\\Programs\\Python\\Python313\\Lib\\asyncio\\tasks.py", line 507, in wait_for\n    return await fut\n           ^^^^^^^^^\n  File "C:\\Users\\rohka\\OneDrive\\Desktop\\ba-rfpapp\\venv\\Lib\\site-packages\\starlette\\websockets.py", line 120, in receive_text\n    self._raise_on_disconnect(message)\n    ~~~~~~~~~~~~~~~~~~~~~~~~~^^^^^^^^^\n  File "C:\\Users\\rohka\\OneDrive\\Desktop\\ba-rfpapp\\venv\\Lib\\site-packages\\starlette\\websockets.py", line 114, in _raise_on_disconnect\n    raise WebSocketDisconnect(message["code"], message.get("reason"))\nstarlette.websockets.WebSocketDisconnect: (<CloseCode.ABNORMAL_CLOSURE: 1006>, \'\')\n'}
2025-08-27 13:26:26,919 - BroadAxis - ERROR - Error occurred: {'error_type': 'WebSocketDisconnect', 'message': "(1001, '')", 'context': {'session_id': None, 'operation': 'websocket_message_handling'}, 'traceback': 'Traceback (most recent call last):\n  File "C:\\Users\\rohka\\OneDrive\\Desktop\\ba-rfpapp\\backend\\websocket_api.py", line 61, in websocket_chat\n    data = await asyncio.wait_for(websocket.receive_text(), timeout=300.0)  # 5 min timeout\n           ^^^^^^^^^^^^^^^^^^^^^^^^^^^^^^^^^^^^^^^^^^^^^^^^^^^^^^^^^^^^^^^\n  File "C:\\Users\\rohka\\AppData\\Local\\Programs\\Python\\Python313\\Lib\\asyncio\\tasks.py", line 507, in wait_for\n    return await fut\n           ^^^^^^^^^\n  File "C:\\Users\\rohka\\OneDrive\\Desktop\\ba-rfpapp\\venv\\Lib\\site-packages\\starlette\\websockets.py", line 120, in receive_text\n    self._raise_on_disconnect(message)\n    ~~~~~~~~~~~~~~~~~~~~~~~~~^^^^^^^^^\n  File "C:\\Users\\rohka\\OneDrive\\Desktop\\ba-rfpapp\\venv\\Lib\\site-packages\\starlette\\websockets.py", line 114, in _raise_on_disconnect\n    raise WebSocketDisconnect(message["code"], message.get("reason"))\nstarlette.websockets.WebSocketDisconnect: (1001, \'\')\n'}
2025-08-27 15:22:56,332 - BroadAxis - ERROR - Error occurred: {'error_type': 'WebSocketDisconnect', 'message': "(1001, '')", 'context': {'session_id': None, 'operation': 'websocket_message_handling'}, 'traceback': 'Traceback (most recent call last):\n  File "C:\\Users\\rohka\\OneDrive\\Desktop\\ba-rfpapp\\backend\\websocket_api.py", line 61, in websocket_chat\n    data = await asyncio.wait_for(websocket.receive_text(), timeout=300.0)  # 5 min timeout\n           ^^^^^^^^^^^^^^^^^^^^^^^^^^^^^^^^^^^^^^^^^^^^^^^^^^^^^^^^^^^^^^^\n  File "C:\\Users\\rohka\\AppData\\Local\\Programs\\Python\\Python313\\Lib\\asyncio\\tasks.py", line 507, in wait_for\n    return await fut\n           ^^^^^^^^^\n  File "C:\\Users\\rohka\\OneDrive\\Desktop\\ba-rfpapp\\venv\\Lib\\site-packages\\starlette\\websockets.py", line 120, in receive_text\n    self._raise_on_disconnect(message)\n    ~~~~~~~~~~~~~~~~~~~~~~~~~^^^^^^^^^\n  File "C:\\Users\\rohka\\OneDrive\\Desktop\\ba-rfpapp\\venv\\Lib\\site-packages\\starlette\\websockets.py", line 114, in _raise_on_disconnect\n    raise WebSocketDisconnect(message["code"], message.get("reason"))\nstarlette.websockets.WebSocketDisconnect: (1001, \'\')\n'}
2025-08-29 14:34:53,098 - BroadAxis - ERROR - Error occurred: {'error_type': 'WebSocketDisconnect', 'message': '(1012, None)', 'context': {'session_id': None, 'operation': 'websocket_message_handling'}, 'traceback': 'Traceback (most recent call last):\n  File "E:\\broadaxis\\StandardsAI\\Broadaxis-frontend-backend-3_fixingmcp\\backend\\websocket_api.py", line 61, in websocket_chat\n    data = await asyncio.wait_for(websocket.receive_text(), timeout=300.0)  # 5 min timeout\n           ^^^^^^^^^^^^^^^^^^^^^^^^^^^^^^^^^^^^^^^^^^^^^^^^^^^^^^^^^^^^^^^\n  File "C:\\Python313\\Lib\\asyncio\\tasks.py", line 507, in wait_for\n    return await fut\n           ^^^^^^^^^\n  File "E:\\broadaxis\\StandardsAI\\Broadaxis-frontend-backend-3_fixingmcp\\.venv\\Lib\\site-packages\\starlette\\websockets.py", line 120, in receive_text\n    self._raise_on_disconnect(message)\n    ~~~~~~~~~~~~~~~~~~~~~~~~~^^^^^^^^^\n  File "E:\\broadaxis\\StandardsAI\\Broadaxis-frontend-backend-3_fixingmcp\\.venv\\Lib\\site-packages\\starlette\\websockets.py", line 114, in _raise_on_disconnect\n    raise WebSocketDisconnect(message["code"], message.get("reason"))\nstarlette.websockets.WebSocketDisconnect: (1012, None)\n'}
2025-08-29 14:34:53,574 - asyncio - ERROR - an error occurred during closing of asynchronous generator <async_generator object stdio_client at 0x000001FD9A754970>
asyncgen: <async_generator object stdio_client at 0x000001FD9A754970>
  + Exception Group Traceback (most recent call last):
  |   File "E:\broadaxis\StandardsAI\Broadaxis-frontend-backend-3_fixingmcp\.venv\Lib\site-packages\anyio\_backends\_asyncio.py", line 772, in __aexit__
  |     raise BaseExceptionGroup(
  |         "unhandled errors in a TaskGroup", self._exceptions
  |     ) from None
  | BaseExceptionGroup: unhandled errors in a TaskGroup (1 sub-exception)
  +-+---------------- 1 ----------------
    | Traceback (most recent call last):
    |   File "E:\broadaxis\StandardsAI\Broadaxis-frontend-backend-3_fixingmcp\.venv\Lib\site-packages\mcp\client\stdio\__init__.py", line 187, in stdio_client
    |     yield read_stream, write_stream
    | GeneratorExit
    +------------------------------------

During handling of the above exception, another exception occurred:

Traceback (most recent call last):
  File "C:\Python313\Lib\asyncio\tasks.py", line 304, in __step_run_and_handle_result
    result = coro.send(None)
  File "E:\broadaxis\StandardsAI\Broadaxis-frontend-backend-3_fixingmcp\.venv\Lib\site-packages\mcp\client\stdio\__init__.py", line 181, in stdio_client
    anyio.create_task_group() as tg,
    ~~~~~~~~~~~~~~~~~~~~~~~^^
  File "E:\broadaxis\StandardsAI\Broadaxis-frontend-backend-3_fixingmcp\.venv\Lib\site-packages\anyio\_backends\_asyncio.py", line 778, in __aexit__
    if self.cancel_scope.__exit__(type(exc), exc, exc.__traceback__):
       ~~~~~~~~~~~~~~~~~~~~~~~~~~^^^^^^^^^^^^^^^^^^^^^^^^^^^^^^^^^^^
  File "E:\broadaxis\StandardsAI\Broadaxis-frontend-backend-3_fixingmcp\.venv\Lib\site-packages\anyio\_backends\_asyncio.py", line 457, in __exit__
    raise RuntimeError(
    ...<2 lines>...
    )
RuntimeError: Attempted to exit cancel scope in a different task than it was entered in
