2025-08-26 16:34:02,261 - httpx - INFO - HTTP Request: POST https://api.anthropic.com/v1/messages "HTTP/1.1 200 OK"
2025-08-26 16:34:07,320 - httpx - INFO - HTTP Request: POST https://api.anthropic.com/v1/messages "HTTP/1.1 200 OK"
2025-08-26 16:34:17,578 - httpx - INFO - HTTP Request: POST https://api.anthropic.com/v1/messages "HTTP/1.1 200 OK"
2025-08-26 16:38:24,397 - httpx - INFO - HTTP Request: POST https://api.anthropic.com/v1/messages "HTTP/1.1 200 OK"
2025-08-26 19:17:45,885 - BroadAxis - ERROR - Error occurred: {'error_type': 'WebSocketDisconnect', 'message': "(1001, '')", 'context': {'session_id': 'ws_1778749663104_1756246085', 'operation': 'websocket_message_handling'}, 'traceback': 'Traceback (most recent call last):\n  File "C:\\Users\\rohka\\OneDrive\\Desktop\\ba-rfpapp\\backend\\websocket_api.py", line 52, in websocket_chat\n    data = await asyncio.wait_for(websocket.receive_text(), timeout=300.0)  # 5 min timeout\n           ^^^^^^^^^^^^^^^^^^^^^^^^^^^^^^^^^^^^^^^^^^^^^^^^^^^^^^^^^^^^^^^\n  File "C:\\Users\\rohka\\AppData\\Local\\Programs\\Python\\Python313\\Lib\\asyncio\\tasks.py", line 507, in wait_for\n    return await fut\n           ^^^^^^^^^\n  File "C:\\Users\\rohka\\OneDrive\\Desktop\\ba-rfpapp\\venv\\Lib\\site-packages\\starlette\\websockets.py", line 120, in receive_text\n    self._raise_on_disconnect(message)\n    ~~~~~~~~~~~~~~~~~~~~~~~~~^^^^^^^^^\n  File "C:\\Users\\rohka\\OneDrive\\Desktop\\ba-rfpapp\\venv\\Lib\\site-packages\\starlette\\websockets.py", line 114, in _raise_on_disconnect\n    raise WebSocketDisconnect(message["code"], message.get("reason"))\nstarlette.websockets.WebSocketDisconnect: (1001, \'\')\n'}
2025-08-26 19:18:01,898 - httpx - INFO - HTTP Request: POST https://api.anthropic.com/v1/messages "HTTP/1.1 200 OK"
2025-08-26 19:18:03,910 - BroadAxis - ERROR - Error occurred: {'error_type': 'WebSocketDisconnect', 'message': '', 'context': {'operation': 'websocket_send_message'}, 'traceback': 'Traceback (most recent call last):\n  File "C:\\Users\\rohka\\OneDrive\\Desktop\\ba-rfpapp\\venv\\Lib\\site-packages\\websockets\\legacy\\protocol.py", line 1279, in close_connection\n    await self.transfer_data_task\n  File "C:\\Users\\rohka\\AppData\\Local\\Programs\\Python\\Python313\\Lib\\asyncio\\futures.py", line 286, in __await__\n    yield self  # This tells Task to wait for completion.\n    ^^^^^^^^^^\n  File "C:\\Users\\rohka\\AppData\\Local\\Programs\\Python\\Python313\\Lib\\asyncio\\tasks.py", line 375, in __wakeup\n    future.result()\n    ~~~~~~~~~~~~~^^\n  File "C:\\Users\\rohka\\AppData\\Local\\Programs\\Python\\Python313\\Lib\\asyncio\\futures.py", line 194, in result\n    raise self._make_cancelled_error()\n  File "C:\\Users\\rohka\\AppData\\Local\\Programs\\Python\\Python313\\Lib\\asyncio\\tasks.py", line 306, in __step_run_and_handle_result\n    result = coro.throw(exc)\n  File "C:\\Users\\rohka\\OneDrive\\Desktop\\ba-rfpapp\\venv\\Lib\\site-packages\\websockets\\legacy\\protocol.py", line 956, in transfer_data\n    await asyncio.shield(self._put_message_waiter)\n  File "C:\\Users\\rohka\\AppData\\Local\\Programs\\Python\\Python313\\Lib\\asyncio\\futures.py", line 286, in __await__\n    yield self  # This tells Task to wait for completion.\n    ^^^^^^^^^^\n  File "C:\\Users\\rohka\\AppData\\Local\\Programs\\Python\\Python313\\Lib\\asyncio\\tasks.py", line 375, in __wakeup\n    future.result()\n    ~~~~~~~~~~~~~^^\n  File "C:\\Users\\rohka\\AppData\\Local\\Programs\\Python\\Python313\\Lib\\asyncio\\futures.py", line 194, in result\n    raise self._make_cancelled_error()\nasyncio.exceptions.CancelledError\n\nThe above exception was the direct cause of the following exception:\n\nTraceback (most recent call last):\n  File "C:\\Users\\rohka\\OneDrive\\Desktop\\ba-rfpapp\\venv\\Lib\\site-packages\\uvicorn\\protocols\\websockets\\websockets_impl.py", line 332, in asgi_send\n    await self.send(data)  # type: ignore[arg-type]\n    ^^^^^^^^^^^^^^^^^^^^^\n  File "C:\\Users\\rohka\\OneDrive\\Desktop\\ba-rfpapp\\venv\\Lib\\site-packages\\websockets\\legacy\\protocol.py", line 620, in send\n    await self.ensure_open()\n  File "C:\\Users\\rohka\\OneDrive\\Desktop\\ba-rfpapp\\venv\\Lib\\site-packages\\websockets\\legacy\\protocol.py", line 921, in ensure_open\n    raise self.connection_closed_exc()\nwebsockets.exceptions.ConnectionClosedError: sent 1011 (internal error) keepalive ping timeout; no close frame received\n\nThe above exception was the direct cause of the following exception:\n\nTraceback (most recent call last):\n  File "C:\\Users\\rohka\\OneDrive\\Desktop\\ba-rfpapp\\venv\\Lib\\site-packages\\starlette\\websockets.py", line 86, in send\n    await self._send(message)\n  File "C:\\Users\\rohka\\OneDrive\\Desktop\\ba-rfpapp\\venv\\Lib\\site-packages\\starlette\\_exception_handler.py", line 39, in sender\n    await send(message)\n  File "C:\\Users\\rohka\\OneDrive\\Desktop\\ba-rfpapp\\venv\\Lib\\site-packages\\uvicorn\\protocols\\websockets\\websockets_impl.py", line 345, in asgi_send\n    raise ClientDisconnected from exc\nuvicorn.protocols.utils.ClientDisconnected\n\nDuring handling of the above exception, another exception occurred:\n\nTraceback (most recent call last):\n  File "C:\\Users\\rohka\\OneDrive\\Desktop\\ba-rfpapp\\backend\\websocket_api.py", line 30, in send_personal_message\n    await websocket.send_text(message)\n  File "C:\\Users\\rohka\\OneDrive\\Desktop\\ba-rfpapp\\venv\\Lib\\site-packages\\starlette\\websockets.py", line 166, in send_text\n    await self.send({"type": "websocket.send", "text": data})\n  File "C:\\Users\\rohka\\OneDrive\\Desktop\\ba-rfpapp\\venv\\Lib\\site-packages\\starlette\\websockets.py", line 89, in send\n    raise WebSocketDisconnect(code=1006)\nstarlette.websockets.WebSocketDisconnect\n'}
2025-08-26 19:18:03,917 - BroadAxis - ERROR - Error occurred: {'error_type': 'WebSocketDisconnect', 'message': '', 'context': {'operation': 'websocket_progress_update'}, 'traceback': 'Traceback (most recent call last):\n  File "C:\\Users\\rohka\\OneDrive\\Desktop\\ba-rfpapp\\venv\\Lib\\site-packages\\websockets\\legacy\\protocol.py", line 1279, in close_connection\n    await self.transfer_data_task\n  File "C:\\Users\\rohka\\AppData\\Local\\Programs\\Python\\Python313\\Lib\\asyncio\\futures.py", line 286, in __await__\n    yield self  # This tells Task to wait for completion.\n    ^^^^^^^^^^\n  File "C:\\Users\\rohka\\AppData\\Local\\Programs\\Python\\Python313\\Lib\\asyncio\\tasks.py", line 375, in __wakeup\n    future.result()\n    ~~~~~~~~~~~~~^^\n  File "C:\\Users\\rohka\\AppData\\Local\\Programs\\Python\\Python313\\Lib\\asyncio\\futures.py", line 194, in result\n    raise self._make_cancelled_error()\n  File "C:\\Users\\rohka\\AppData\\Local\\Programs\\Python\\Python313\\Lib\\asyncio\\tasks.py", line 306, in __step_run_and_handle_result\n    result = coro.throw(exc)\n  File "C:\\Users\\rohka\\OneDrive\\Desktop\\ba-rfpapp\\venv\\Lib\\site-packages\\websockets\\legacy\\protocol.py", line 956, in transfer_data\n    await asyncio.shield(self._put_message_waiter)\n  File "C:\\Users\\rohka\\AppData\\Local\\Programs\\Python\\Python313\\Lib\\asyncio\\futures.py", line 286, in __await__\n    yield self  # This tells Task to wait for completion.\n    ^^^^^^^^^^\n  File "C:\\Users\\rohka\\AppData\\Local\\Programs\\Python\\Python313\\Lib\\asyncio\\tasks.py", line 375, in __wakeup\n    future.result()\n    ~~~~~~~~~~~~~^^\n  File "C:\\Users\\rohka\\AppData\\Local\\Programs\\Python\\Python313\\Lib\\asyncio\\futures.py", line 194, in result\n    raise self._make_cancelled_error()\nasyncio.exceptions.CancelledError\n\nThe above exception was the direct cause of the following exception:\n\nTraceback (most recent call last):\n  File "C:\\Users\\rohka\\OneDrive\\Desktop\\ba-rfpapp\\venv\\Lib\\site-packages\\uvicorn\\protocols\\websockets\\websockets_impl.py", line 332, in asgi_send\n    await self.send(data)  # type: ignore[arg-type]\n    ^^^^^^^^^^^^^^^^^^^^^\n  File "C:\\Users\\rohka\\OneDrive\\Desktop\\ba-rfpapp\\venv\\Lib\\site-packages\\websockets\\legacy\\protocol.py", line 620, in send\n    await self.ensure_open()\n  File "C:\\Users\\rohka\\OneDrive\\Desktop\\ba-rfpapp\\venv\\Lib\\site-packages\\websockets\\legacy\\protocol.py", line 921, in ensure_open\n    raise self.connection_closed_exc()\nwebsockets.exceptions.ConnectionClosedError: sent 1011 (internal error) keepalive ping timeout; no close frame received\n\nThe above exception was the direct cause of the following exception:\n\nTraceback (most recent call last):\n  File "C:\\Users\\rohka\\OneDrive\\Desktop\\ba-rfpapp\\venv\\Lib\\site-packages\\starlette\\websockets.py", line 86, in send\n    await self._send(message)\n  File "C:\\Users\\rohka\\OneDrive\\Desktop\\ba-rfpapp\\venv\\Lib\\site-packages\\starlette\\_exception_handler.py", line 39, in sender\n    await send(message)\n  File "C:\\Users\\rohka\\OneDrive\\Desktop\\ba-rfpapp\\venv\\Lib\\site-packages\\uvicorn\\protocols\\websockets\\websockets_impl.py", line 345, in asgi_send\n    raise ClientDisconnected from exc\nuvicorn.protocols.utils.ClientDisconnected\n\nDuring handling of the above exception, another exception occurred:\n\nTraceback (most recent call last):\n  File "C:\\Users\\rohka\\OneDrive\\Desktop\\ba-rfpapp\\backend\\mcp_interface.py", line 285, in execute_tool_with_progress\n    await send_message_callback(\n    ...<9 lines>...\n    )\n  File "C:\\Users\\rohka\\OneDrive\\Desktop\\ba-rfpapp\\backend\\websocket_api.py", line 30, in send_personal_message\n    await websocket.send_text(message)\n  File "C:\\Users\\rohka\\OneDrive\\Desktop\\ba-rfpapp\\venv\\Lib\\site-packages\\starlette\\websockets.py", line 166, in send_text\n    await self.send({"type": "websocket.send", "text": data})\n  File "C:\\Users\\rohka\\OneDrive\\Desktop\\ba-rfpapp\\venv\\Lib\\site-packages\\starlette\\websockets.py", line 89, in send\n    raise WebSocketDisconnect(code=1006)\nstarlette.websockets.WebSocketDisconnect\n'}
2025-08-26 19:18:03,919 - BroadAxis - ERROR - Error occurred: {'error_type': 'RuntimeError', 'message': 'Cannot call "send" once a close message has been sent.', 'context': {'operation': 'websocket_send_message'}, 'traceback': 'Traceback (most recent call last):\n  File "C:\\Users\\rohka\\OneDrive\\Desktop\\ba-rfpapp\\backend\\websocket_api.py", line 30, in send_personal_message\n    await websocket.send_text(message)\n  File "C:\\Users\\rohka\\OneDrive\\Desktop\\ba-rfpapp\\venv\\Lib\\site-packages\\starlette\\websockets.py", line 166, in send_text\n    await self.send({"type": "websocket.send", "text": data})\n  File "C:\\Users\\rohka\\OneDrive\\Desktop\\ba-rfpapp\\venv\\Lib\\site-packages\\starlette\\websockets.py", line 98, in send\n    raise RuntimeError(\'Cannot call "send" once a close message has been sent.\')\nRuntimeError: Cannot call "send" once a close message has been sent.\n'}
2025-08-26 19:18:03,921 - BroadAxis - ERROR - Error occurred: {'error_type': 'RuntimeError', 'message': 'Cannot call "send" once a close message has been sent.', 'context': {'operation': 'websocket_generation_update'}, 'traceback': 'Traceback (most recent call last):\n  File "C:\\Users\\rohka\\OneDrive\\Desktop\\ba-rfpapp\\backend\\mcp_interface.py", line 320, in process_query_with_anthropic\n    await send_message_callback(\n    ...<9 lines>...\n    )\n  File "C:\\Users\\rohka\\OneDrive\\Desktop\\ba-rfpapp\\backend\\websocket_api.py", line 30, in send_personal_message\n    await websocket.send_text(message)\n  File "C:\\Users\\rohka\\OneDrive\\Desktop\\ba-rfpapp\\venv\\Lib\\site-packages\\starlette\\websockets.py", line 166, in send_text\n    await self.send({"type": "websocket.send", "text": data})\n  File "C:\\Users\\rohka\\OneDrive\\Desktop\\ba-rfpapp\\venv\\Lib\\site-packages\\starlette\\websockets.py", line 98, in send\n    raise RuntimeError(\'Cannot call "send" once a close message has been sent.\')\nRuntimeError: Cannot call "send" once a close message has been sent.\n'}
2025-08-26 19:18:11,436 - httpx - INFO - HTTP Request: POST https://api.anthropic.com/v1/messages "HTTP/1.1 200 OK"
2025-08-26 19:18:11,439 - BroadAxis - ERROR - Error occurred: {'error_type': 'RuntimeError', 'message': 'Cannot call "send" once a close message has been sent.', 'context': {'operation': 'websocket_send_message'}, 'traceback': 'Traceback (most recent call last):\n  File "C:\\Users\\rohka\\OneDrive\\Desktop\\ba-rfpapp\\backend\\websocket_api.py", line 30, in send_personal_message\n    await websocket.send_text(message)\n  File "C:\\Users\\rohka\\OneDrive\\Desktop\\ba-rfpapp\\venv\\Lib\\site-packages\\starlette\\websockets.py", line 166, in send_text\n    await self.send({"type": "websocket.send", "text": data})\n  File "C:\\Users\\rohka\\OneDrive\\Desktop\\ba-rfpapp\\venv\\Lib\\site-packages\\starlette\\websockets.py", line 98, in send\n    raise RuntimeError(\'Cannot call "send" once a close message has been sent.\')\nRuntimeError: Cannot call "send" once a close message has been sent.\n'}
2025-08-26 19:18:11,441 - BroadAxis - ERROR - Error occurred: {'error_type': 'RuntimeError', 'message': 'Cannot call "send" once a close message has been sent.', 'context': {'session_id': 'ws_1778749769040_1756244282', 'query_length': 23}, 'traceback': 'Traceback (most recent call last):\n  File "C:\\Users\\rohka\\OneDrive\\Desktop\\ba-rfpapp\\backend\\websocket_api.py", line 161, in websocket_chat\n    await manager.send_personal_message(\n    ...<7 lines>...\n    )\n  File "C:\\Users\\rohka\\OneDrive\\Desktop\\ba-rfpapp\\backend\\websocket_api.py", line 30, in send_personal_message\n    await websocket.send_text(message)\n  File "C:\\Users\\rohka\\OneDrive\\Desktop\\ba-rfpapp\\venv\\Lib\\site-packages\\starlette\\websockets.py", line 166, in send_text\n    await self.send({"type": "websocket.send", "text": data})\n  File "C:\\Users\\rohka\\OneDrive\\Desktop\\ba-rfpapp\\venv\\Lib\\site-packages\\starlette\\websockets.py", line 98, in send\n    raise RuntimeError(\'Cannot call "send" once a close message has been sent.\')\nRuntimeError: Cannot call "send" once a close message has been sent.\n'}
2025-08-26 19:18:11,442 - BroadAxis - ERROR - Error occurred: {'error_type': 'RuntimeError', 'message': 'Cannot call "send" once a close message has been sent.', 'context': {'operation': 'websocket_send_message'}, 'traceback': 'Traceback (most recent call last):\n  File "C:\\Users\\rohka\\OneDrive\\Desktop\\ba-rfpapp\\backend\\websocket_api.py", line 161, in websocket_chat\n    await manager.send_personal_message(\n    ...<7 lines>...\n    )\n  File "C:\\Users\\rohka\\OneDrive\\Desktop\\ba-rfpapp\\backend\\websocket_api.py", line 30, in send_personal_message\n    await websocket.send_text(message)\n  File "C:\\Users\\rohka\\OneDrive\\Desktop\\ba-rfpapp\\venv\\Lib\\site-packages\\starlette\\websockets.py", line 166, in send_text\n    await self.send({"type": "websocket.send", "text": data})\n  File "C:\\Users\\rohka\\OneDrive\\Desktop\\ba-rfpapp\\venv\\Lib\\site-packages\\starlette\\websockets.py", line 98, in send\n    raise RuntimeError(\'Cannot call "send" once a close message has been sent.\')\nRuntimeError: Cannot call "send" once a close message has been sent.\n\nDuring handling of the above exception, another exception occurred:\n\nTraceback (most recent call last):\n  File "C:\\Users\\rohka\\OneDrive\\Desktop\\ba-rfpapp\\backend\\websocket_api.py", line 30, in send_personal_message\n    await websocket.send_text(message)\n  File "C:\\Users\\rohka\\OneDrive\\Desktop\\ba-rfpapp\\venv\\Lib\\site-packages\\starlette\\websockets.py", line 166, in send_text\n    await self.send({"type": "websocket.send", "text": data})\n  File "C:\\Users\\rohka\\OneDrive\\Desktop\\ba-rfpapp\\venv\\Lib\\site-packages\\starlette\\websockets.py", line 98, in send\n    raise RuntimeError(\'Cannot call "send" once a close message has been sent.\')\nRuntimeError: Cannot call "send" once a close message has been sent.\n'}
2025-08-26 19:18:11,444 - BroadAxis - ERROR - Error occurred: {'error_type': 'RuntimeError', 'message': 'Cannot call "send" once a close message has been sent.', 'context': {'session_id': 'ws_1778749769040_1756244282', 'operation': 'websocket_message_handling'}, 'traceback': 'Traceback (most recent call last):\n  File "C:\\Users\\rohka\\OneDrive\\Desktop\\ba-rfpapp\\backend\\websocket_api.py", line 161, in websocket_chat\n    await manager.send_personal_message(\n    ...<7 lines>...\n    )\n  File "C:\\Users\\rohka\\OneDrive\\Desktop\\ba-rfpapp\\backend\\websocket_api.py", line 30, in send_personal_message\n    await websocket.send_text(message)\n  File "C:\\Users\\rohka\\OneDrive\\Desktop\\ba-rfpapp\\venv\\Lib\\site-packages\\starlette\\websockets.py", line 166, in send_text\n    await self.send({"type": "websocket.send", "text": data})\n  File "C:\\Users\\rohka\\OneDrive\\Desktop\\ba-rfpapp\\venv\\Lib\\site-packages\\starlette\\websockets.py", line 98, in send\n    raise RuntimeError(\'Cannot call "send" once a close message has been sent.\')\nRuntimeError: Cannot call "send" once a close message has been sent.\n\nDuring handling of the above exception, another exception occurred:\n\nTraceback (most recent call last):\n  File "C:\\Users\\rohka\\OneDrive\\Desktop\\ba-rfpapp\\backend\\websocket_api.py", line 195, in websocket_chat\n    await manager.send_personal_message(\n    ...<6 lines>...\n    )\n  File "C:\\Users\\rohka\\OneDrive\\Desktop\\ba-rfpapp\\backend\\websocket_api.py", line 30, in send_personal_message\n    await websocket.send_text(message)\n  File "C:\\Users\\rohka\\OneDrive\\Desktop\\ba-rfpapp\\venv\\Lib\\site-packages\\starlette\\websockets.py", line 166, in send_text\n    await self.send({"type": "websocket.send", "text": data})\n  File "C:\\Users\\rohka\\OneDrive\\Desktop\\ba-rfpapp\\venv\\Lib\\site-packages\\starlette\\websockets.py", line 98, in send\n    raise RuntimeError(\'Cannot call "send" once a close message has been sent.\')\nRuntimeError: Cannot call "send" once a close message has been sent.\n'}
2025-08-26 19:18:11,819 - httpx - INFO - HTTP Request: POST https://api.anthropic.com/v1/messages "HTTP/1.1 200 OK"
2025-08-26 19:18:33,287 - httpx - INFO - HTTP Request: POST https://api.anthropic.com/v1/messages "HTTP/1.1 200 OK"
2025-08-26 19:18:36,816 - httpx - INFO - HTTP Request: POST https://api.anthropic.com/v1/messages "HTTP/1.1 200 OK"
2025-08-26 19:20:02,700 - BroadAxis - ERROR - Error occurred: {'error_type': 'WebSocketDisconnect', 'message': '(1012, None)', 'context': {'session_id': 'ws_1778750529776_1756253866', 'operation': 'websocket_message_handling'}, 'traceback': 'Traceback (most recent call last):\n  File "C:\\Users\\rohka\\OneDrive\\Desktop\\ba-rfpapp\\backend\\websocket_api.py", line 52, in websocket_chat\n    data = await asyncio.wait_for(websocket.receive_text(), timeout=300.0)  # 5 min timeout\n           ^^^^^^^^^^^^^^^^^^^^^^^^^^^^^^^^^^^^^^^^^^^^^^^^^^^^^^^^^^^^^^^\n  File "C:\\Users\\rohka\\AppData\\Local\\Programs\\Python\\Python313\\Lib\\asyncio\\tasks.py", line 507, in wait_for\n    return await fut\n           ^^^^^^^^^\n  File "C:\\Users\\rohka\\OneDrive\\Desktop\\ba-rfpapp\\venv\\Lib\\site-packages\\starlette\\websockets.py", line 120, in receive_text\n    self._raise_on_disconnect(message)\n    ~~~~~~~~~~~~~~~~~~~~~~~~~^^^^^^^^^\n  File "C:\\Users\\rohka\\OneDrive\\Desktop\\ba-rfpapp\\venv\\Lib\\site-packages\\starlette\\websockets.py", line 114, in _raise_on_disconnect\n    raise WebSocketDisconnect(message["code"], message.get("reason"))\nstarlette.websockets.WebSocketDisconnect: (1012, None)\n'}
2025-08-26 19:20:03,340 - asyncio - ERROR - an error occurred during closing of asynchronous generator <async_generator object stdio_client at 0x0000019E25B230D0>
asyncgen: <async_generator object stdio_client at 0x0000019E25B230D0>
  + Exception Group Traceback (most recent call last):
  |   File "C:\Users\rohka\OneDrive\Desktop\ba-rfpapp\venv\Lib\site-packages\anyio\_backends\_asyncio.py", line 772, in __aexit__
  |     raise BaseExceptionGroup(
  |         "unhandled errors in a TaskGroup", self._exceptions
  |     ) from None
  | BaseExceptionGroup: unhandled errors in a TaskGroup (1 sub-exception)
  +-+---------------- 1 ----------------
    | Traceback (most recent call last):
    |   File "C:\Users\rohka\OneDrive\Desktop\ba-rfpapp\venv\Lib\site-packages\mcp\client\stdio\__init__.py", line 187, in stdio_client
    |     yield read_stream, write_stream
    | GeneratorExit
    +------------------------------------

During handling of the above exception, another exception occurred:

Traceback (most recent call last):
  File "C:\Users\rohka\AppData\Local\Programs\Python\Python313\Lib\asyncio\tasks.py", line 304, in __step_run_and_handle_result
    result = coro.send(None)
  File "C:\Users\rohka\OneDrive\Desktop\ba-rfpapp\venv\Lib\site-packages\mcp\client\stdio\__init__.py", line 181, in stdio_client
    anyio.create_task_group() as tg,
    ~~~~~~~~~~~~~~~~~~~~~~~^^
  File "C:\Users\rohka\OneDrive\Desktop\ba-rfpapp\venv\Lib\site-packages\anyio\_backends\_asyncio.py", line 778, in __aexit__
    if self.cancel_scope.__exit__(type(exc), exc, exc.__traceback__):
       ~~~~~~~~~~~~~~~~~~~~~~~~~~^^^^^^^^^^^^^^^^^^^^^^^^^^^^^^^^^^^
  File "C:\Users\rohka\OneDrive\Desktop\ba-rfpapp\venv\Lib\site-packages\anyio\_backends\_asyncio.py", line 457, in __exit__
    raise RuntimeError(
    ...<2 lines>...
    )
RuntimeError: Attempted to exit cancel scope in a different task than it was entered in
2025-08-26 19:22:09,969 - httpx - INFO - HTTP Request: POST https://api.anthropic.com/v1/messages "HTTP/1.1 200 OK"
2025-08-26 19:29:46,852 - httpx - INFO - HTTP Request: POST https://api.anthropic.com/v1/messages "HTTP/1.1 200 OK"
2025-08-26 19:37:09,747 - BroadAxis - INFO - WebSocket disconnected gracefully: ws_2556640719760_1756255029
2025-08-26 19:37:47,550 - BroadAxis - INFO - WebSocket disconnected gracefully: ws_2556639624720_1756255067
2025-08-26 19:38:26,125 - httpx - INFO - HTTP Request: POST https://api.anthropic.com/v1/messages "HTTP/1.1 200 OK"
2025-08-26 19:38:26,165 - BroadAxis - INFO - WebSocket disconnected during message send
2025-08-26 19:38:26,165 - BroadAxis - WARNING - Attempted to send message to disconnected WebSocket
2025-08-26 20:26:50,275 - httpx - INFO - HTTP Request: POST https://api.anthropic.com/v1/messages "HTTP/1.1 200 OK"
2025-08-26 20:33:05,239 - httpx - INFO - HTTP Request: POST https://api.anthropic.com/v1/messages "HTTP/1.1 200 OK"
2025-08-26 20:35:11,982 - asyncio - ERROR - an error occurred during closing of asynchronous generator <async_generator object stdio_client at 0x000001EEFA27D690>
asyncgen: <async_generator object stdio_client at 0x000001EEFA27D690>
  + Exception Group Traceback (most recent call last):
  |   File "C:\Users\rohka\AppData\Local\Programs\Python\Python313\Lib\site-packages\anyio\_backends\_asyncio.py", line 772, in __aexit__
  |     raise BaseExceptionGroup(
  |         "unhandled errors in a TaskGroup", self._exceptions
  |     ) from None
  | BaseExceptionGroup: unhandled errors in a TaskGroup (1 sub-exception)
  +-+---------------- 1 ----------------
    | Traceback (most recent call last):
    |   File "C:\Users\rohka\AppData\Local\Programs\Python\Python313\Lib\site-packages\mcp\client\stdio\__init__.py", line 187, in stdio_client
    |     yield read_stream, write_stream
    | GeneratorExit
    +------------------------------------

During handling of the above exception, another exception occurred:

Traceback (most recent call last):
  File "C:\Users\rohka\AppData\Local\Programs\Python\Python313\Lib\site-packages\mcp\client\stdio\__init__.py", line 181, in stdio_client
    anyio.create_task_group() as tg,
    ~~~~~~~~~~~~~~~~~~~~~~~^^
  File "C:\Users\rohka\AppData\Local\Programs\Python\Python313\Lib\site-packages\anyio\_backends\_asyncio.py", line 778, in __aexit__
    if self.cancel_scope.__exit__(type(exc), exc, exc.__traceback__):
       ~~~~~~~~~~~~~~~~~~~~~~~~~~^^^^^^^^^^^^^^^^^^^^^^^^^^^^^^^^^^^
  File "C:\Users\rohka\AppData\Local\Programs\Python\Python313\Lib\site-packages\anyio\_backends\_asyncio.py", line 457, in __exit__
    raise RuntimeError(
    ...<2 lines>...
    )
RuntimeError: Attempted to exit cancel scope in a different task than it was entered in
2025-08-26 20:36:01,630 - httpx - INFO - HTTP Request: POST https://api.anthropic.com/v1/messages "HTTP/1.1 200 OK"
2025-08-26 20:36:03,989 - httpx - INFO - HTTP Request: POST https://api.anthropic.com/v1/messages "HTTP/1.1 200 OK"
2025-08-26 20:49:13,766 - asyncio - ERROR - an error occurred during closing of asynchronous generator <async_generator object stdio_client at 0x0000017E965D57E0>
asyncgen: <async_generator object stdio_client at 0x0000017E965D57E0>
  + Exception Group Traceback (most recent call last):
  |   File "C:\Users\rohka\AppData\Local\Programs\Python\Python313\Lib\site-packages\anyio\_backends\_asyncio.py", line 772, in __aexit__
  |     raise BaseExceptionGroup(
  |         "unhandled errors in a TaskGroup", self._exceptions
  |     ) from None
  | BaseExceptionGroup: unhandled errors in a TaskGroup (1 sub-exception)
  +-+---------------- 1 ----------------
    | Traceback (most recent call last):
    |   File "C:\Users\rohka\AppData\Local\Programs\Python\Python313\Lib\site-packages\mcp\client\stdio\__init__.py", line 187, in stdio_client
    |     yield read_stream, write_stream
    | GeneratorExit
    +------------------------------------

During handling of the above exception, another exception occurred:

Traceback (most recent call last):
  File "C:\Users\rohka\AppData\Local\Programs\Python\Python313\Lib\site-packages\mcp\client\stdio\__init__.py", line 181, in stdio_client
    anyio.create_task_group() as tg,
    ~~~~~~~~~~~~~~~~~~~~~~~^^
  File "C:\Users\rohka\AppData\Local\Programs\Python\Python313\Lib\site-packages\anyio\_backends\_asyncio.py", line 778, in __aexit__
    if self.cancel_scope.__exit__(type(exc), exc, exc.__traceback__):
       ~~~~~~~~~~~~~~~~~~~~~~~~~~^^^^^^^^^^^^^^^^^^^^^^^^^^^^^^^^^^^
  File "C:\Users\rohka\AppData\Local\Programs\Python\Python313\Lib\site-packages\anyio\_backends\_asyncio.py", line 457, in __exit__
    raise RuntimeError(
    ...<2 lines>...
    )
RuntimeError: Attempted to exit cancel scope in a different task than it was entered in
2025-08-26 20:51:43,894 - asyncio - ERROR - an error occurred during closing of asynchronous generator <async_generator object stdio_client at 0x00000201761E57E0>
asyncgen: <async_generator object stdio_client at 0x00000201761E57E0>
  + Exception Group Traceback (most recent call last):
  |   File "C:\Users\rohka\AppData\Local\Programs\Python\Python313\Lib\site-packages\anyio\_backends\_asyncio.py", line 772, in __aexit__
  |     raise BaseExceptionGroup(
  |         "unhandled errors in a TaskGroup", self._exceptions
  |     ) from None
  | BaseExceptionGroup: unhandled errors in a TaskGroup (1 sub-exception)
  +-+---------------- 1 ----------------
    | Traceback (most recent call last):
    |   File "C:\Users\rohka\AppData\Local\Programs\Python\Python313\Lib\site-packages\mcp\client\stdio\__init__.py", line 187, in stdio_client
    |     yield read_stream, write_stream
    | GeneratorExit
    +------------------------------------

During handling of the above exception, another exception occurred:

Traceback (most recent call last):
  File "C:\Users\rohka\AppData\Local\Programs\Python\Python313\Lib\site-packages\mcp\client\stdio\__init__.py", line 181, in stdio_client
    anyio.create_task_group() as tg,
    ~~~~~~~~~~~~~~~~~~~~~~~^^
  File "C:\Users\rohka\AppData\Local\Programs\Python\Python313\Lib\site-packages\anyio\_backends\_asyncio.py", line 778, in __aexit__
    if self.cancel_scope.__exit__(type(exc), exc, exc.__traceback__):
       ~~~~~~~~~~~~~~~~~~~~~~~~~~^^^^^^^^^^^^^^^^^^^^^^^^^^^^^^^^^^^
  File "C:\Users\rohka\AppData\Local\Programs\Python\Python313\Lib\site-packages\anyio\_backends\_asyncio.py", line 457, in __exit__
    raise RuntimeError(
    ...<2 lines>...
    )
RuntimeError: Attempted to exit cancel scope in a different task than it was entered in
2025-08-26 20:59:09,498 - asyncio - ERROR - an error occurred during closing of asynchronous generator <async_generator object stdio_client at 0x000002690E651690>
asyncgen: <async_generator object stdio_client at 0x000002690E651690>
  + Exception Group Traceback (most recent call last):
  |   File "C:\Users\rohka\AppData\Local\Programs\Python\Python313\Lib\site-packages\anyio\_backends\_asyncio.py", line 772, in __aexit__
  |     raise BaseExceptionGroup(
  |         "unhandled errors in a TaskGroup", self._exceptions
  |     ) from None
  | BaseExceptionGroup: unhandled errors in a TaskGroup (1 sub-exception)
  +-+---------------- 1 ----------------
    | Traceback (most recent call last):
    |   File "C:\Users\rohka\AppData\Local\Programs\Python\Python313\Lib\site-packages\mcp\client\stdio\__init__.py", line 187, in stdio_client
    |     yield read_stream, write_stream
    | GeneratorExit
    +------------------------------------

During handling of the above exception, another exception occurred:

Traceback (most recent call last):
  File "C:\Users\rohka\AppData\Local\Programs\Python\Python313\Lib\site-packages\mcp\client\stdio\__init__.py", line 181, in stdio_client
    anyio.create_task_group() as tg,
    ~~~~~~~~~~~~~~~~~~~~~~~^^
  File "C:\Users\rohka\AppData\Local\Programs\Python\Python313\Lib\site-packages\anyio\_backends\_asyncio.py", line 778, in __aexit__
    if self.cancel_scope.__exit__(type(exc), exc, exc.__traceback__):
       ~~~~~~~~~~~~~~~~~~~~~~~~~~^^^^^^^^^^^^^^^^^^^^^^^^^^^^^^^^^^^
  File "C:\Users\rohka\AppData\Local\Programs\Python\Python313\Lib\site-packages\anyio\_backends\_asyncio.py", line 457, in __exit__
    raise RuntimeError(
    ...<2 lines>...
    )
RuntimeError: Attempted to exit cancel scope in a different task than it was entered in
2025-08-26 20:59:33,135 - asyncio - ERROR - an error occurred during closing of asynchronous generator <async_generator object stdio_client at 0x0000024EE23D30D0>
asyncgen: <async_generator object stdio_client at 0x0000024EE23D30D0>
  + Exception Group Traceback (most recent call last):
  |   File "C:\Users\rohka\OneDrive\Desktop\ba-rfpapp\venv\Lib\site-packages\anyio\_backends\_asyncio.py", line 772, in __aexit__
  |     raise BaseExceptionGroup(
  |         "unhandled errors in a TaskGroup", self._exceptions
  |     ) from None
  | BaseExceptionGroup: unhandled errors in a TaskGroup (1 sub-exception)
  +-+---------------- 1 ----------------
    | Traceback (most recent call last):
    |   File "C:\Users\rohka\OneDrive\Desktop\ba-rfpapp\venv\Lib\site-packages\mcp\client\stdio\__init__.py", line 187, in stdio_client
    |     yield read_stream, write_stream
    | GeneratorExit
    +------------------------------------

During handling of the above exception, another exception occurred:

Traceback (most recent call last):
  File "C:\Users\rohka\AppData\Local\Programs\Python\Python313\Lib\asyncio\tasks.py", line 304, in __step_run_and_handle_result
    result = coro.send(None)
  File "C:\Users\rohka\OneDrive\Desktop\ba-rfpapp\venv\Lib\site-packages\mcp\client\stdio\__init__.py", line 181, in stdio_client
    anyio.create_task_group() as tg,
    ~~~~~~~~~~~~~~~~~~~~~~~^^
  File "C:\Users\rohka\OneDrive\Desktop\ba-rfpapp\venv\Lib\site-packages\anyio\_backends\_asyncio.py", line 778, in __aexit__
    if self.cancel_scope.__exit__(type(exc), exc, exc.__traceback__):
       ~~~~~~~~~~~~~~~~~~~~~~~~~~^^^^^^^^^^^^^^^^^^^^^^^^^^^^^^^^^^^
  File "C:\Users\rohka\OneDrive\Desktop\ba-rfpapp\venv\Lib\site-packages\anyio\_backends\_asyncio.py", line 457, in __exit__
    raise RuntimeError(
    ...<2 lines>...
    )
RuntimeError: Attempted to exit cancel scope in a different task than it was entered in
2025-08-26 21:00:18,037 - httpx - INFO - HTTP Request: POST https://api.anthropic.com/v1/messages "HTTP/1.1 200 OK"
2025-08-26 21:11:48,013 - BroadAxis - ERROR - Error occurred: {'error_type': 'WebSocketDisconnect', 'message': "(1001, '')", 'context': {'session_id': 'ws_2282835347008_1756260703', 'operation': 'websocket_message_handling'}, 'traceback': 'Traceback (most recent call last):\n  File "C:\\Users\\rohka\\OneDrive\\Desktop\\ba-rfpapp\\backend\\websocket_api.py", line 52, in websocket_chat\n    data = await asyncio.wait_for(websocket.receive_text(), timeout=300.0)  # 5 min timeout\n           ^^^^^^^^^^^^^^^^^^^^^^^^^^^^^^^^^^^^^^^^^^^^^^^^^^^^^^^^^^^^^^^\n  File "C:\\Users\\rohka\\AppData\\Local\\Programs\\Python\\Python313\\Lib\\asyncio\\tasks.py", line 507, in wait_for\n    return await fut\n           ^^^^^^^^^\n  File "C:\\Users\\rohka\\OneDrive\\Desktop\\ba-rfpapp\\venv\\Lib\\site-packages\\starlette\\websockets.py", line 120, in receive_text\n    self._raise_on_disconnect(message)\n    ~~~~~~~~~~~~~~~~~~~~~~~~~^^^^^^^^^\n  File "C:\\Users\\rohka\\OneDrive\\Desktop\\ba-rfpapp\\venv\\Lib\\site-packages\\starlette\\websockets.py", line 114, in _raise_on_disconnect\n    raise WebSocketDisconnect(message["code"], message.get("reason"))\nstarlette.websockets.WebSocketDisconnect: (1001, \'\')\n'}
2025-08-26 21:12:09,863 - httpx - INFO - HTTP Request: POST https://api.anthropic.com/v1/messages "HTTP/1.1 200 OK"
2025-08-26 21:12:17,777 - httpx - INFO - HTTP Request: POST https://api.anthropic.com/v1/messages "HTTP/1.1 200 OK"
2025-08-26 21:12:36,204 - httpx - INFO - HTTP Request: POST https://api.anthropic.com/v1/messages "HTTP/1.1 200 OK"
2025-08-26 21:12:46,003 - httpx - INFO - HTTP Request: POST https://api.anthropic.com/v1/messages "HTTP/1.1 200 OK"
2025-08-26 21:13:09,069 - httpx - INFO - HTTP Request: POST https://api.anthropic.com/v1/messages "HTTP/1.1 200 OK"
2025-08-26 21:13:17,768 - httpx - INFO - HTTP Request: POST https://api.anthropic.com/v1/messages "HTTP/1.1 200 OK"
2025-08-26 21:13:43,041 - httpx - INFO - HTTP Request: POST https://api.anthropic.com/v1/messages "HTTP/1.1 200 OK"
2025-08-26 21:13:49,628 - httpx - INFO - HTTP Request: POST https://api.anthropic.com/v1/messages "HTTP/1.1 200 OK"
2025-08-26 21:15:22,249 - httpx - INFO - HTTP Request: POST https://api.anthropic.com/v1/messages "HTTP/1.1 200 OK"
2025-08-26 21:15:26,312 - httpx - INFO - HTTP Request: POST https://api.anthropic.com/v1/messages "HTTP/1.1 200 OK"
2025-08-26 21:22:47,655 - BroadAxis - ERROR - Error occurred: {'error_type': 'WebSocketDisconnect', 'message': "(1001, '')", 'context': {'session_id': 'ws_2282834920784_1756260703', 'operation': 'websocket_message_handling'}, 'traceback': 'Traceback (most recent call last):\n  File "C:\\Users\\rohka\\OneDrive\\Desktop\\ba-rfpapp\\backend\\websocket_api.py", line 52, in websocket_chat\n    data = await asyncio.wait_for(websocket.receive_text(), timeout=300.0)  # 5 min timeout\n           ^^^^^^^^^^^^^^^^^^^^^^^^^^^^^^^^^^^^^^^^^^^^^^^^^^^^^^^^^^^^^^^\n  File "C:\\Users\\rohka\\AppData\\Local\\Programs\\Python\\Python313\\Lib\\asyncio\\tasks.py", line 507, in wait_for\n    return await fut\n           ^^^^^^^^^\n  File "C:\\Users\\rohka\\OneDrive\\Desktop\\ba-rfpapp\\venv\\Lib\\site-packages\\starlette\\websockets.py", line 120, in receive_text\n    self._raise_on_disconnect(message)\n    ~~~~~~~~~~~~~~~~~~~~~~~~~^^^^^^^^^\n  File "C:\\Users\\rohka\\OneDrive\\Desktop\\ba-rfpapp\\venv\\Lib\\site-packages\\starlette\\websockets.py", line 114, in _raise_on_disconnect\n    raise WebSocketDisconnect(message["code"], message.get("reason"))\nstarlette.websockets.WebSocketDisconnect: (1001, \'\')\n'}
2025-08-26 21:22:55,820 - BroadAxis - ERROR - Error occurred: {'error_type': 'WebSocketDisconnect', 'message': "(1001, '')", 'context': {'session_id': 'ws_2282835097744_1756261368', 'operation': 'websocket_message_handling'}, 'traceback': 'Traceback (most recent call last):\n  File "C:\\Users\\rohka\\OneDrive\\Desktop\\ba-rfpapp\\backend\\websocket_api.py", line 52, in websocket_chat\n    data = await asyncio.wait_for(websocket.receive_text(), timeout=300.0)  # 5 min timeout\n           ^^^^^^^^^^^^^^^^^^^^^^^^^^^^^^^^^^^^^^^^^^^^^^^^^^^^^^^^^^^^^^^\n  File "C:\\Users\\rohka\\AppData\\Local\\Programs\\Python\\Python313\\Lib\\asyncio\\tasks.py", line 507, in wait_for\n    return await fut\n           ^^^^^^^^^\n  File "C:\\Users\\rohka\\OneDrive\\Desktop\\ba-rfpapp\\venv\\Lib\\site-packages\\starlette\\websockets.py", line 120, in receive_text\n    self._raise_on_disconnect(message)\n    ~~~~~~~~~~~~~~~~~~~~~~~~~^^^^^^^^^\n  File "C:\\Users\\rohka\\OneDrive\\Desktop\\ba-rfpapp\\venv\\Lib\\site-packages\\starlette\\websockets.py", line 114, in _raise_on_disconnect\n    raise WebSocketDisconnect(message["code"], message.get("reason"))\nstarlette.websockets.WebSocketDisconnect: (1001, \'\')\n'}
2025-08-26 21:23:16,598 - httpx - INFO - HTTP Request: POST https://api.anthropic.com/v1/messages "HTTP/1.1 200 OK"
2025-08-26 21:23:26,236 - httpx - INFO - HTTP Request: POST https://api.anthropic.com/v1/messages "HTTP/1.1 200 OK"
2025-08-26 21:23:40,733 - httpx - INFO - HTTP Request: POST https://api.anthropic.com/v1/messages "HTTP/1.1 200 OK"
2025-08-26 21:23:43,783 - httpx - INFO - HTTP Request: POST https://api.anthropic.com/v1/messages "HTTP/1.1 200 OK"
2025-08-26 21:23:47,299 - httpx - INFO - HTTP Request: POST https://api.anthropic.com/v1/messages "HTTP/1.1 200 OK"
2025-08-26 21:23:53,024 - httpx - INFO - HTTP Request: POST https://api.anthropic.com/v1/messages "HTTP/1.1 200 OK"
2025-08-26 21:23:58,135 - httpx - INFO - HTTP Request: POST https://api.anthropic.com/v1/messages "HTTP/1.1 200 OK"
2025-08-26 21:24:05,102 - httpx - INFO - HTTP Request: POST https://api.anthropic.com/v1/messages "HTTP/1.1 200 OK"
2025-08-26 21:24:06,293 - httpx - INFO - HTTP Request: POST https://api.anthropic.com/v1/messages "HTTP/1.1 429 Too Many Requests"
2025-08-26 21:24:06,294 - anthropic._base_client - INFO - Retrying request to /v1/messages in 6.000000 seconds
2025-08-26 21:24:14,636 - httpx - INFO - HTTP Request: POST https://api.anthropic.com/v1/messages "HTTP/1.1 200 OK"
2025-08-26 21:24:15,547 - httpx - INFO - HTTP Request: POST https://api.anthropic.com/v1/messages "HTTP/1.1 429 Too Many Requests"
2025-08-26 21:24:15,549 - anthropic._base_client - INFO - Retrying request to /v1/messages in 18.000000 seconds
2025-08-26 21:24:29,333 - asyncio - ERROR - an error occurred during closing of asynchronous generator <async_generator object stdio_client at 0x00000213838E1BD0>
asyncgen: <async_generator object stdio_client at 0x00000213838E1BD0>
  + Exception Group Traceback (most recent call last):
  |   File "C:\Users\rohka\OneDrive\Desktop\ba-rfpapp\venv\Lib\site-packages\anyio\_backends\_asyncio.py", line 772, in __aexit__
  |     raise BaseExceptionGroup(
  |         "unhandled errors in a TaskGroup", self._exceptions
  |     ) from None
  | BaseExceptionGroup: unhandled errors in a TaskGroup (1 sub-exception)
  +-+---------------- 1 ----------------
    | Traceback (most recent call last):
    |   File "C:\Users\rohka\OneDrive\Desktop\ba-rfpapp\venv\Lib\site-packages\mcp\client\stdio\__init__.py", line 187, in stdio_client
    |     yield read_stream, write_stream
    | GeneratorExit
    +------------------------------------

During handling of the above exception, another exception occurred:

Traceback (most recent call last):
  File "C:\Users\rohka\AppData\Local\Programs\Python\Python313\Lib\asyncio\tasks.py", line 304, in __step_run_and_handle_result
    result = coro.send(None)
  File "C:\Users\rohka\OneDrive\Desktop\ba-rfpapp\venv\Lib\site-packages\mcp\client\stdio\__init__.py", line 181, in stdio_client
    anyio.create_task_group() as tg,
    ~~~~~~~~~~~~~~~~~~~~~~~^^
  File "C:\Users\rohka\OneDrive\Desktop\ba-rfpapp\venv\Lib\site-packages\anyio\_backends\_asyncio.py", line 778, in __aexit__
    if self.cancel_scope.__exit__(type(exc), exc, exc.__traceback__):
       ~~~~~~~~~~~~~~~~~~~~~~~~~~^^^^^^^^^^^^^^^^^^^^^^^^^^^^^^^^^^^
  File "C:\Users\rohka\OneDrive\Desktop\ba-rfpapp\venv\Lib\site-packages\anyio\_backends\_asyncio.py", line 457, in __exit__
    raise RuntimeError(
    ...<2 lines>...
    )
RuntimeError: Attempted to exit cancel scope in a different task than it was entered in
2025-08-26 21:29:48,635 - BroadAxis - ERROR - Error occurred: {'error_type': 'WebSocketDisconnect', 'message': "(1001, '')", 'context': {'session_id': 'ws_2660106976656_1756261474', 'operation': 'websocket_message_handling'}, 'traceback': 'Traceback (most recent call last):\n  File "C:\\Users\\rohka\\OneDrive\\Desktop\\ba-rfpapp\\backend\\websocket_api.py", line 52, in websocket_chat\n    data = await asyncio.wait_for(websocket.receive_text(), timeout=300.0)  # 5 min timeout\n           ^^^^^^^^^^^^^^^^^^^^^^^^^^^^^^^^^^^^^^^^^^^^^^^^^^^^^^^^^^^^^^^\n  File "C:\\Users\\rohka\\AppData\\Local\\Programs\\Python\\Python313\\Lib\\asyncio\\tasks.py", line 507, in wait_for\n    return await fut\n           ^^^^^^^^^\n  File "C:\\Users\\rohka\\OneDrive\\Desktop\\ba-rfpapp\\venv\\Lib\\site-packages\\starlette\\websockets.py", line 120, in receive_text\n    self._raise_on_disconnect(message)\n    ~~~~~~~~~~~~~~~~~~~~~~~~~^^^^^^^^^\n  File "C:\\Users\\rohka\\OneDrive\\Desktop\\ba-rfpapp\\venv\\Lib\\site-packages\\starlette\\websockets.py", line 114, in _raise_on_disconnect\n    raise WebSocketDisconnect(message["code"], message.get("reason"))\nstarlette.websockets.WebSocketDisconnect: (1001, \'\')\n'}
2025-08-26 21:30:23,489 - httpx - INFO - HTTP Request: POST https://api.anthropic.com/v1/messages "HTTP/1.1 200 OK"
2025-08-26 21:30:26,788 - httpx - INFO - HTTP Request: POST https://api.anthropic.com/v1/messages "HTTP/1.1 200 OK"
2025-08-26 21:30:29,541 - httpx - INFO - HTTP Request: POST https://api.anthropic.com/v1/messages "HTTP/1.1 400 Bad Request"
2025-08-26 21:37:29,590 - BroadAxis - ERROR - Error occurred: {'error_type': 'WebSocketDisconnect', 'message': "(1001, '')", 'context': {'session_id': 'ws_2660106448240_1756261790', 'operation': 'websocket_message_handling'}, 'traceback': 'Traceback (most recent call last):\n  File "C:\\Users\\rohka\\OneDrive\\Desktop\\ba-rfpapp\\backend\\websocket_api.py", line 52, in websocket_chat\n    data = await asyncio.wait_for(websocket.receive_text(), timeout=300.0)  # 5 min timeout\n           ^^^^^^^^^^^^^^^^^^^^^^^^^^^^^^^^^^^^^^^^^^^^^^^^^^^^^^^^^^^^^^^\n  File "C:\\Users\\rohka\\AppData\\Local\\Programs\\Python\\Python313\\Lib\\asyncio\\tasks.py", line 507, in wait_for\n    return await fut\n           ^^^^^^^^^\n  File "C:\\Users\\rohka\\OneDrive\\Desktop\\ba-rfpapp\\venv\\Lib\\site-packages\\starlette\\websockets.py", line 120, in receive_text\n    self._raise_on_disconnect(message)\n    ~~~~~~~~~~~~~~~~~~~~~~~~~^^^^^^^^^\n  File "C:\\Users\\rohka\\OneDrive\\Desktop\\ba-rfpapp\\venv\\Lib\\site-packages\\starlette\\websockets.py", line 114, in _raise_on_disconnect\n    raise WebSocketDisconnect(message["code"], message.get("reason"))\nstarlette.websockets.WebSocketDisconnect: (1001, \'\')\n'}
2025-08-26 21:37:48,732 - httpx - INFO - HTTP Request: POST https://api.anthropic.com/v1/messages "HTTP/1.1 200 OK"
2025-08-26 21:37:51,417 - httpx - INFO - HTTP Request: POST https://api.anthropic.com/v1/messages "HTTP/1.1 200 OK"
2025-08-26 21:37:55,973 - httpx - INFO - HTTP Request: POST https://api.anthropic.com/v1/messages "HTTP/1.1 200 OK"
2025-08-26 21:37:57,886 - httpx - INFO - HTTP Request: POST https://api.anthropic.com/v1/messages "HTTP/1.1 200 OK"
2025-08-26 21:38:00,321 - httpx - INFO - HTTP Request: POST https://api.anthropic.com/v1/messages "HTTP/1.1 200 OK"
2025-08-26 21:38:01,385 - httpx - INFO - HTTP Request: POST https://api.anthropic.com/v1/messages "HTTP/1.1 429 Too Many Requests"
2025-08-26 21:38:01,387 - anthropic._base_client - INFO - Retrying request to /v1/messages in 13.000000 seconds
2025-08-26 21:38:16,231 - httpx - INFO - HTTP Request: POST https://api.anthropic.com/v1/messages "HTTP/1.1 200 OK"
2025-08-26 21:38:17,268 - httpx - INFO - HTTP Request: POST https://api.anthropic.com/v1/messages "HTTP/1.1 429 Too Many Requests"
2025-08-26 21:38:17,269 - anthropic._base_client - INFO - Retrying request to /v1/messages in 21.000000 seconds
2025-08-26 21:38:40,225 - httpx - INFO - HTTP Request: POST https://api.anthropic.com/v1/messages "HTTP/1.1 200 OK"
2025-08-26 21:38:41,125 - httpx - INFO - HTTP Request: POST https://api.anthropic.com/v1/messages "HTTP/1.1 429 Too Many Requests"
2025-08-26 21:38:41,128 - anthropic._base_client - INFO - Retrying request to /v1/messages in 21.000000 seconds
2025-08-26 21:39:05,186 - httpx - INFO - HTTP Request: POST https://api.anthropic.com/v1/messages "HTTP/1.1 200 OK"
2025-08-26 21:39:07,323 - httpx - INFO - HTTP Request: POST https://api.anthropic.com/v1/messages "HTTP/1.1 429 Too Many Requests"
2025-08-26 21:39:07,325 - anthropic._base_client - INFO - Retrying request to /v1/messages in 22.000000 seconds
2025-08-26 21:39:40,334 - httpx - INFO - HTTP Request: POST https://api.anthropic.com/v1/messages "HTTP/1.1 200 OK"
2025-08-26 21:45:35,534 - BroadAxis - ERROR - Error occurred: {'error_type': 'WebSocketDisconnect', 'message': "(1001, '')", 'context': {'session_id': 'ws_2660106665520_1756262250', 'operation': 'websocket_message_handling'}, 'traceback': 'Traceback (most recent call last):\n  File "C:\\Users\\rohka\\OneDrive\\Desktop\\ba-rfpapp\\backend\\websocket_api.py", line 52, in websocket_chat\n    data = await asyncio.wait_for(websocket.receive_text(), timeout=300.0)  # 5 min timeout\n           ^^^^^^^^^^^^^^^^^^^^^^^^^^^^^^^^^^^^^^^^^^^^^^^^^^^^^^^^^^^^^^^\n  File "C:\\Users\\rohka\\AppData\\Local\\Programs\\Python\\Python313\\Lib\\asyncio\\tasks.py", line 507, in wait_for\n    return await fut\n           ^^^^^^^^^\n  File "C:\\Users\\rohka\\OneDrive\\Desktop\\ba-rfpapp\\venv\\Lib\\site-packages\\starlette\\websockets.py", line 120, in receive_text\n    self._raise_on_disconnect(message)\n    ~~~~~~~~~~~~~~~~~~~~~~~~~^^^^^^^^^\n  File "C:\\Users\\rohka\\OneDrive\\Desktop\\ba-rfpapp\\venv\\Lib\\site-packages\\starlette\\websockets.py", line 114, in _raise_on_disconnect\n    raise WebSocketDisconnect(message["code"], message.get("reason"))\nstarlette.websockets.WebSocketDisconnect: (1001, \'\')\n'}
2025-08-26 21:46:00,660 - httpx - INFO - HTTP Request: POST https://api.anthropic.com/v1/messages "HTTP/1.1 200 OK"
2025-08-26 21:46:09,292 - httpx - INFO - HTTP Request: POST https://api.anthropic.com/v1/messages "HTTP/1.1 200 OK"
2025-08-26 21:46:37,955 - httpx - INFO - HTTP Request: POST https://api.anthropic.com/v1/messages "HTTP/1.1 200 OK"
2025-08-26 21:46:48,671 - httpx - INFO - HTTP Request: POST https://api.anthropic.com/v1/messages "HTTP/1.1 200 OK"
2025-08-27 09:42:12,464 - BroadAxis - ERROR - Error occurred: {'error_type': 'WebSocketDisconnect', 'message': "(1001, '')", 'context': {'session_id': 'ws_2824775283600_1756305717', 'operation': 'websocket_message_handling'}, 'traceback': 'Traceback (most recent call last):\n  File "C:\\Users\\rohka\\OneDrive\\Desktop\\ba-rfpapp\\backend\\websocket_api.py", line 52, in websocket_chat\n    data = await asyncio.wait_for(websocket.receive_text(), timeout=300.0)  # 5 min timeout\n           ^^^^^^^^^^^^^^^^^^^^^^^^^^^^^^^^^^^^^^^^^^^^^^^^^^^^^^^^^^^^^^^\n  File "C:\\Users\\rohka\\AppData\\Local\\Programs\\Python\\Python313\\Lib\\asyncio\\tasks.py", line 507, in wait_for\n    return await fut\n           ^^^^^^^^^\n  File "C:\\Users\\rohka\\OneDrive\\Desktop\\ba-rfpapp\\venv\\Lib\\site-packages\\starlette\\websockets.py", line 120, in receive_text\n    self._raise_on_disconnect(message)\n    ~~~~~~~~~~~~~~~~~~~~~~~~~^^^^^^^^^\n  File "C:\\Users\\rohka\\OneDrive\\Desktop\\ba-rfpapp\\venv\\Lib\\site-packages\\starlette\\websockets.py", line 114, in _raise_on_disconnect\n    raise WebSocketDisconnect(message["code"], message.get("reason"))\nstarlette.websockets.WebSocketDisconnect: (1001, \'\')\n'}
